Workbook

Sheet Synergies
F2: P&L | G2: P&L @ 70% retention
B3: Annualized adjusted P&L | F3: ='26 EBITDA ADJ (2)'!Y23 -> 767548.18 | G3: =F3+F4 -> 1430073.9 | J3: =-'26 EBITDA ADJ (2)'!E6*2 -> 9390375.3 | K3: =-'26 EBITDA ADJ (2)'!E6*0.7*2 -> 6573262.7 | L3: =J3-K3 -> 2817112.6
B4: Synergies | F4: =-H15 -> 662525.69 | G4: =-L4 -> -845133.77 | H4: 30% of sls drop | L4: =L3*0.3 -> 845133.77
B5: Depreciation new co 12yrs (300,000 equip)(20x15k) | F5: =-300000/12 -> -25000 | G5: =F5 -> -25000
B6: 4% Sales (Full Sales) | F6: =-J3*0.04 -> -375615.01 | G6: =-K3*0.04 -> -262930.51
B7: $500k Upfront (paid over 5 years) 6.6% | F7: =-9806*12 -> -117672 | G7: =F7 -> -117672
B8: $1M Inv Carry Cost @7% | F8: =-1000000*0.07 -> -70000 | G8: =-1000000*0.07 -> -70000
B9: Extra Profit to Wise (Yrly) | F9: =SUM(F3:F8) -> 841786.86 | G9: =SUM(G3:G8) -> 109337.59
B12: HCF Acquistion | E12: 2026 HY1 | G12: After
B13: SYNERGIES | E13: Before | F13: 2026 Est | G13: Acqusition | H13: Adjusmt
B15: TOTAL SYNERGIES | H15: =H16+H24+H44+H45+H46 -> -662525.69 | J15: Supporting Calculations
B16: RENT | F16: =SUM(F17:F22) -> 294253.68 | G16: =SUM(G17:G22) -> 192414 | H16: =G16-F16 -> -101839.68 | J16: Sqft | K16: Price NNN | L16: New Calc | M16: NNN?
B17: Rent | C17: Hillsboro | E17: 0 | G17: =L17 -> 151914 | H17: =G17-F17 -> 151914 | J17: 75957 | K17: 2 | L17: =J17*K17 -> 151914
B18: Rent | C18: Angola | E18: ='SORTED B VS P'!N102 -> 48000 | F18: =E18*2 -> 96000 | G18: 0 | H18: =G18-F18 -> -96000
B19: Rent | C19: Fordyce | E19: ='SORTED B VS P'!N103 -> 15000 | F19: =E19*2 -> 30000 | G19: =L19 -> 40500 | H19: =G19-F19 -> 10500 | J19: 15000 | K19: 2.7 | L19: =J19*K19 -> 40500
B20: Utilities | C20: Angola | E20: ='SORTED B VS P'!M206 -> 61340.06 | F20: =E20*2 -> 122680.12 | G20: 0 | H20: =G20-F20 -> -122680.12 | J20: Verified-"Nothing from corporate in Angola Utilities - they should all go away with the building" | R20: Only things coded are NIPSCO - electric provide and City of Angola which is water and sewer.
B21: Caretaking | C21: Angola | E21: ='SORTED B VS P'!M100+'SORTED B VS P'!M214+'SORTED B VS P'!N226 -> 10647.46 | F21: =E21*2 -> 21294.92 | G21: 0 | H21: =G21-F21 -> -21294.92
B22: General Insurance | C22: Angola | E22: ='SORTED B VS P'!N224 -> 12139.32 | F22: =E22*2 -> 24278.64 | G22: 0 | H22: =G22-F22 -> -24278.64 | J22: We allocate the premiums based on previous years sales percentages to each location. The annual premium will go down once we remove the building from the policy. Not sure how much $.
B24: PEOPLE | F24: =SUM(F25:F43) -> 952694 | G24: =SUM(G25:G43) -> 635486 | H24: =SUM(H25:H43) -> -317208
B25: Owner 1 | F25: 100000 | G25: =F25 -> 100000 | H25: =G25-F25 -> 0
B26: Owner 2 | C26: Corp | F26: 100000 | G26: 0 | H26: =G26-F26 -> -100000 | J26: 1 less owner, keeping one
B27: Rhonda - CFO to GM | C27: Corp | F27: 71000 | G27: =F27*1.2 -> 85200 | H27: =G27-F27 -> 14200 | J27: 20% Incr for more repons
B28: Brooke - Accting/Inv | C28: Corp | F28: 68000 | G28: =F28*1.1 -> 74800 | H28: =G28-F28 -> 6800 | J28: 10% Incr for more repons
B29: COMP (remote) | C29: Corp | D29: Jeff Hensley | F29: 45240 | G29: 0 | H29: =G29-F29 -> -45240 | J29: 1961 closer to retire but doesn't think wants to
B30: COMP (remote) | C30: Corp | D30: Darin Murtle | F30: 49608 | G30: 0 | H30: =G30-F30 -> -49608 | J30: May need one but rehire in FTW
B31: Cust Sls | C31: Corp | D31: Keth Dick | F31: 51854 | G31: =F31 -> 51854 | H31: =G31-F31 -> 0 | J31: Cust Serv, truck driver, jack all trades,ship,, mat hand, scheuling
B32: Cust Sls (remote) | C32: Corp | D32: Carmen Martin | F32: 45032 | G32: =F32 -> 45032 | H32: =G32-F32 -> 0 | J32: orders intergrated paper, does all integ estimates
B33: Cust Sls | C33: Corp | D33: Mary Wills | F33: 44720 | G33: =F33 -> 44720 | H33: =G33-F33 -> 0 | J33: Work with Terri on govt stuff (maybe could train on paperwork or sales side??)
B34: Outside Sls | C34: Corp | D34: Terri | F34: 79000 | G34: =F34 -> 79000 | H34: =G34-F34 -> 0 | J34: Need for State work
B35: Outside Sls | C35: Corp | D35: Noah | F35: 56080 | G35: =F35 -> 56080 | H35: =G35-F35 -> 0 | J35: Have him develop sales
H36: =G36-F36 -> 0
B37: Plant Super | C37: Angola | D37: Tim Mcconah | F37: 61200 | H37: =G37-F37 -> -61200
B38: Scheduling/OfficeMgr | C38: Angola | D38: Melody Maguire | F38: 44720 | G38: =F38 -> 44720 | H38: =G38-F38 -> 0 | J38: Lives with Hamilton Martinez (Press)
B39: Scheduling | C39: Angola | D39: Dena Melchi | F39: 40560 | H39: =G39-F39 -> -40560 | J39: No need job jackets, runs reports for Rob, bindery when needed, used to burn plates before operators trained to burn own plates ANGOLA only; use 3rd party for flexo
B40: Shipping | C40: Angola | D40: Benji Hawkins | F40: 41600 | G40: 0 | H40: =G40-F40 -> -41600 | J40: No need for position
B42: Cust Sls | C42: Hillsboro | D42: Jason Miller | F42: 54080 | G42: =F42 -> 54080 | J42: Keep - cust service - all stock orders, sales HCF.com; lots logistics, complaints, frt schuling big jobs (VERY VALUABLE, knows computer system)
B44: PAPER | F44: =SUM(F45:F58) -> 0 | G44: =SUM(G45:G58) -> 0 | H44: =-'[1]Summary Savings'!$E$3 -> -243478.01
B45: Heatlhcare
B46: IT Synergies

Sheet Pixlle
D4: TYPE | E4: IS
D5: HCF FINANCIALS HY1 2026
D6: Sum of NET_CHANGE | E6: Column Labels
D7: Row Labels | E7: Pixelle | F7: Grand Total
D8: 1. Sales | E8: -962160.67 | F8: -962160.67
D9: 2. Variable cost Labor | E9: 315753.08 | F9: 315753.08
D10: 3. Mfg IDL | E10: 12414.36 | F10: 12414.36
D11: 4. Mfg OVHD | E11: 82744.57 | F11: 82744.57
D12: Grand Total | E12: -551248.66 | F12: -551248.66
R13: WITHOUT 6days
I14: Forecast | K14: =I14 -> Forecast | T14: Should be
E15: Jan-Dec2025 | G15: Jan-Jun2026 | I15: Jul-Dec2026 | K15: FY 2026 Est | M15: Est 2027 | N15: Assumption | Q15: Valuation | R15: =G15 -> Jan-Jun2026 | S15: =I15 -> Jul-Dec2026 | T15: Valatuion
D16: SALES | E16: =-[2]Pivot!$D$5 -> 870156.16 | F16: % Sales | G16: =-'26 EBITDA ADJ'!D6 -> 962160.67 | H16: % Sales | I16: =450000*2 -> 900000 | J16: % Sales | K16: =G16+I16 -> 1862160.7 | L16: % Sales | M16: =450000*4 -> 1800000 | N16: $450k x 4 | P16: =Q16 -> 1924321.3 | Q16: =G16*2 -> 1924321.3 | R16: =551308/6*5+410852+41000 -> 911275.33 | S16: =I16 -> 900000 | T16: =R16+S16 -> 1811275.3
A17: VARLAB | B17: 60700 | C17: 50 | D17: PRODUCTION WAGES | E17: 169152.01 | F17: =E17/E$16 -> 0.19439271 | G17: 192924.91 | H17: =G17/G$16 -> 0.20051216 | I17: =H17*I$16 -> 180460.94 | J17: =I17/I$16 -> 0.20051216 | K17: =G17+I17 -> 373385.85 | L17: =K17/K$16 -> 0.20051216 | M17: =N17*M$16 -> 360921.88 | N17: =L17 -> 0.20051216 | Q17: =G17*2 -> 385849.82 | R17: =I17 -> 180460.94 | S17: =I17 -> 180460.94 | T17: =R17+S17 -> 360921.88
A18: VARLAB | B18: 60710 | C18: 50 | D18: PRODUCTION OVERTIME | E18: 11359.5 | F18: =E18/E$16 -> 0.013054553 | G18: 16086.61 | H18: =G18/G$16 -> 0.016719255 | I18: =F18*I16 -> 11749.098 | J18: =I18/I$16 -> 0.013054553 | K18: =G18+I18 -> 27835.708 | L18: =K18/K$16 -> 0.01494807 | M18: =N18*M$16 -> 23498.196 | N18: =J18 -> 0.013054553 | O18: Assum reduces to 1.3% | Q18: =G18*2 -> 32173.22 | R18: =I18 -> 11749.098 | S18: =I18 -> 11749.098 | T18: =R18+S18 -> 23498.196
A19: VARLAB | B19: 60720 | C19: 50 | D19: PRODUCTION VACATION | E19: 10905.8 | F19: =E19/E$16 -> 0.012533153 | G19: 3777.6 | H19: =G19/G$16 -> 0.0039261634 | I19: =H19*I$16 -> 3533.5471 | J19: =I19/I$16 -> 0.0039261634 | K19: =G19+I19 -> 7311.1471 | L19: =K19/K$16 -> 0.0039261634 | M19: =N19*M$16 -> 7067.0941 | N19: =J19 -> 0.0039261634 | Q19: =G19*2 -> 7555.2 | R19: =I19 -> 3533.5471 | S19: =I19 -> 3533.5471 | T19: =R19+S19 -> 7067.0941
A20: VARLAB | B20: 60730 | C20: 50 | D20: PRODUCTION HOLIDAY | E20: 6821.6 | F20: =E20/E$16 -> 0.0078395124 | G20: 3916.4 | H20: =G20/G$16 -> 0.004070422 | I20: =H20*I$16 -> 3663.3798 | J20: =I20/I$16 -> 0.004070422 | K20: =G20+I20 -> 7579.7798 | L20: =K20/K$16 -> 0.004070422 | M20: =N20*M$16 -> 7326.7597 | N20: =J20 -> 0.004070422 | Q20: =G20*2 -> 7832.8 | R20: =I20 -> 3663.3798 | S20: =I20 -> 3663.3798 | T20: =R20+S20 -> 7326.7597
A21: VARLAB | B21: 60750 | C21: 50 | D21: MAINT. WAGES | E21: -11914.34 | F21: =E21/E$16 -> -0.013692186 | G21: -8500.32 | H21: =G21/G$16 -> -0.0088346159 | I21: =H21*I$16 -> -7951.1544 | J21: =I21/I$16 -> -0.0088346159 | K21: =G21+I21 -> -16451.474 | L21: =K21/K$16 -> -0.0088346159 | M21: =N21*M$16 -> -15902.309 | N21: =J21 -> -0.0088346159 | Q21: =G21*2 -> -17000.64 | R21: =I21 -> -7951.1544 | S21: =I21 -> -7951.1544 | T21: =R21+S21 -> -15902.309
A22: VARLAB | B22: 60751 | C22: 50 | D22: MAINT. O.T. WAGES | E22: 619.41 | F22: =E22/E$16 -> 0.00071183775 | G22: 30 | H22: =G22/G$16 -> 3.1179824e-05 | I22: =H22*I$16 -> 28.061841 | J22: =I22/I$16 -> 3.1179824e-05 | K22: =G22+I22 -> 58.061841 | L22: =K22/K$16 -> 3.1179824e-05 | M22: =N22*M$16 -> 56.123683 | N22: =J22 -> 3.1179824e-05 | Q22: =G22*2 -> 60 | R22: =I22 -> 28.061841 | S22: =I22 -> 28.061841 | T22: =R22+S22 -> 56.123683
A23: VARLAB | B23: 60752 | C23: 50 | D23: MAINT. VAC. WAGES | E23: 3400.2 | F23: =E23/E$16 -> 0.0039075745 | G23: 800 | H23: =G23/G$16 -> 0.00083146196 | I23: =H23*I$16 -> 748.31577 | J23: =I23/I$16 -> 0.00083146196 | K23: =G23+I23 -> 1548.3158 | L23: =K23/K$16 -> 0.00083146196 | M23: =N23*M$16 -> 1496.6315 | N23: =J23 -> 0.00083146196 | Q23: =G23*2 -> 1600 | R23: =I23 -> 748.31577 | S23: =I23 -> 748.31577 | T23: =R23+S23 -> 1496.6315
A24: VARLAB | B24: 60753 | C24: 50 | D24: MAINT. HOLIDAY WAGES | E24: 1257.6 | F24: =E24/E$16 -> 0.0014452578 | G24: 480 | H24: =G24/G$16 -> 0.00049887718 | I24: =H24*I$16 -> 448.98946 | J24: =I24/I$16 -> 0.00049887718 | K24: =G24+I24 -> 928.98946 | L24: =K24/K$16 -> 0.00049887718 | M24: =N24*M$16 -> 897.97892 | N24: =J24 -> 0.00049887718 | Q24: =G24*2 -> 960 | R24: =I24 -> 448.98946 | S24: =I24 -> 448.98946 | T24: =R24+S24 -> 897.97892
A25: IDL | B25: 60770 | C25: 50 | D25: PLANT SUPERVISION | E25: 56669.65 | F25: =E25/E$16 -> 0.065125839 | G25: 28614.88 | H25: =G25/G$16 -> 0.02974023 | I25: =H25*I$16 -> 26766.207 | J25: =I25/I$16 -> 0.02974023 | K25: =G25+I25 -> 55381.087 | L25: =K25/K$16 -> 0.02974023 | M25: =N25*M$16 -> 53532.415 | N25: =J25 -> 0.02974023 | Q25: =G25*2 -> 57229.76 | R25: =I25 -> 26766.207 | S25: =I25 -> 26766.207 | T25: =R25+S25 -> 53532.415
A26: IDL | B26: 60840 | C26: 50 | D26: SHIPPING WAGES | E26: 40683.75 | F26: =E26/E$16 -> 0.046754539 | G26: 22463.2 | H26: =G26/G$16 -> 0.02334662 | I26: =H26*I$16 -> 21011.958 | J26: =I26/I$16 -> 0.02334662 | K26: =G26+I26 -> 43475.158 | L26: =K26/K$16 -> 0.02334662 | M26: =N26*M$16 -> 42023.917 | N26: =J26 -> 0.02334662 | Q26: =G26*2 -> 44926.4 | R26: =I26 -> 21011.958 | S26: =I26 -> 21011.958 | T26: =R26+S26 -> 42023.917
A27: IDL | B27: 60841 | C27: 50 | D27: SHIPPING O.T. WAGES | E27: 87.33 | F27: =E27/E$16 -> 0.0001003613 | G27: 0 | H27: =G27/G$16 -> 0 | I27: =H27*I$16 -> 0 | J27: =I27/I$16 -> 0 | K27: =G27+I27 -> 0 | L27: =K27/K$16 -> 0 | M27: =N27*M$16 -> 0 | N27: =J27 -> 0 | Q27: =G27*2 -> 0 | R27: =I27 -> 0 | S27: =I27 -> 0 | T27: =R27+S27 -> 0
A28: IDL | B28: 60842 | C28: 50 | D28: SHIPPING VAC. WAGES | E28: 1498.5 | F28: =E28/E$16 -> 0.0017221047 | G28: 2422 | H28: =G28/G$16 -> 0.0025172511 | I28: =H28*I$16 -> 2265.526 | J28: =I28/I$16 -> 0.0025172511 | K28: =G28+I28 -> 4687.526 | L28: =K28/K$16 -> 0.0025172511 | M28: =N28*M$16 -> 4531.052 | N28: =J28 -> 0.0025172511 | Q28: =G28*2 -> 4844 | R28: =I28 -> 2265.526 | S28: =I28 -> 2265.526 | T28: =R28+S28 -> 4531.052
A29: IDL | B29: 60843 | C29: 50 | D29: SHIPPING HOLIDAY WAGES | E29: 810 | F29: =E29/E$16 -> 0.0009308674 | G29: 0 | H29: =G29/G$16 -> 0 | I29: =H29*I$16 -> 0 | J29: =I29/I$16 -> 0 | K29: =G29+I29 -> 0 | L29: =K29/K$16 -> 0 | M29: =N29*M$16 -> 0 | N29: =J29 -> 0 | Q29: =G29*2 -> 0 | R29: =I29 -> 0 | S29: =I29 -> 0 | T29: =R29+S29 -> 0
D30: Misc Incom 12k Premium Saturdays | G30: -12000 | I30: =H30*I$16 -> 0 | K30: =G30+I30 -> -12000 | L30: =K30/K$16 -> -0.0064441271 | M30: =N30*M$16 -> 0 | N30: =J30 -> 0 | O30: Assume doesn't repeat | Q30: =G30*2 -> -24000 | S30: =I30 -> 0 | T30: =R30+S30 -> 0
D31: Labor Cost | E31: =SUM(E17:E30) -> 291351.01 | F31: =E31/E$16 -> 0.33482612 | G31: =SUM(G17:G30) -> 251015.28 | H31: =G31/G$16 -> 0.26088707 | J31: =I31/I$16 -> 0 | K31: =SUM(K17:K30) -> 493740.15 | L31: =K31/K$16 -> 0.26514369 | M31: =SUM(M17:M30) -> 485449.74 | N31: =M31/M$16 -> 0.2696943 | Q31: =G34*2 -> -82171.44 | R31: 0 | S31: =I31 -> 0 | T31: =R31+S31 -> 0
E32: =E16-E31 -> 578805.15 | F32: =E32/E$16 -> 0.66517388 | G32: =G16-G31 -> 711145.39 | I32: =I16-I31 -> 900000 | K32: =K16-K31 -> 1368420.5 | M32: =M16-M31 -> 1314550.3 | P32: =Q32 -> 1504462.2 | Q32: =Q16-SUM(Q17:Q31) -> 1504462.2 | R32: =R16-SUM(R17:R31) -> 668550.46 | S32: =S16-SUM(S17:S31) -> 657275.13 | T32: =T16-SUM(T17:T31) -> 1325825.6
G33: $12,000 is for a premium we paid employees to work Saturdays | P33: =G32-G34 -> 752231.11 | Q33: =Q32/2 -> 752231.11 | T33: =Q32-T32 -> 178636.63
B34: 60850 | C34: 50 | D34: SUPERVISORY SALARIES | E34: -118069.05 | G34: -41085.72 | K34: 0 | M34: ??? | P34: =P33-Q33 -> 0 | T34: =T33*3.5 -> 625228.19
B35: Is there normally a cost in supervisor salary in Fordyce facility?
B36: or is it zero and you are just running the credit through this account?
D38: Rest Labor FICA | G38: ='SORTED B VS P'!M172+'SORTED B VS P'!M176+'SORTED B VS P'!M180+'SORTED B VS P'!M184+'SORTED B VS P'!M188+'SORTED B VS P'!M192 -> 106237.88 | I38: =G38 -> 106237.88 | K38: =G38+I38 -> 212475.76 | M38: =SUM(G17:G29)*2 -> 526030.56 | N38: =SUM(M17:M30) -> 485449.74 | P38: =-G38*2 -> -212475.76 | Q38: =-G38*2 -> -212475.76 | R38: =-G38 -> -106237.88 | S38: =-I38 -> -106237.88 | T38: =R38+S38 -> -212475.76
G39: =SUM(G17:G29)+G38+G34+G30 -> 316167.44 | I39: =SUM(I17:I29)+I38+I34 -> 348962.75 | K39: =SUM(K17:K29)+K38+K34 -> 718215.91 | N39: =N38-M38 -> -40580.821 | P39: =P32+P38 -> 1291986.5 | Q39: =Q32+Q38 -> 1291986.5 | R39: =R32+R38 -> 562312.58 | S39: =S32+S38 -> 551037.25 | T39: =R39+S39 -> 1113349.8
T40: =T39-Q39 -> -178636.63
D41: Var & IDL | G41: ='26 EBITDA ADJ'!D7+'26 EBITDA ADJ'!D12-12000 -> 316167.44 | I41: =G41*2 -> 632334.88 | K41: =G41+I41 -> 948502.32 | T41: =T40*3.5 -> -625228.19
D42: Sales - VARL&IDL | G42: =G16-G41 -> 645993.23
G43: =Pivot!D7+Pivot!D12+Pivot!D14+Pivot!D15+Pivot!D18 -> 103410.32 | Q43: =-G43 -> -103410.32 | R43: =Q43 -> -103410.32 | S43: =R43 -> -103410.32
G44: =G42-G43 -> 542582.91 | Q44: =Q39+Q43 -> 1188576.1 | R44: =R39+R43 -> 458902.26 | S44: =S39+S43 -> 447626.93
...

Sheet 26 EBITDA ADJ (2)
V1: Pixelle Sales | X1: =(551308+410852)*2 -> 1924320 | Y1: =(410852+444994)*2 -> 1711692 | Z1: =Y1-X1 -> -212628
A2: TYPE | B2: IS
A3: HCF FINANCIALS HY1 2026 | L3: Adjustment Calcs | N3: Pixelle | O3: =N3 -> Pixelle | Q3: 2026 6Months | AC3: 2026 12Months
A4: Sum of NET_CHANGE | B4: Column Labels | N4: Adjustment | O4: Adj 2026 HY1 | S4: Adjusted | T4: 2026 Adj 5Days | V4: Adjusted EBITDA | W4: 2026 6Mo | X4: Orignal | Y4: Adjusted | Z4: Diff | AA4: Diff 3.5x | AB4: Explanation of new EBITDA Adjustments | AE4: Adjusted | AF4: 2026 Adj 5Days
A5: Row Labels | B5: Angola | C5: Hillsboro | D5: Pixelle | E5: Grand Total | F5: Original | G5: =B5 -> Angola | H5: =C5 -> Hillsboro | I5: =D5 -> Pixelle | J5: Total | L5: Adjust 6days vs 5 days | N5: Avg/Day | O5: 5Days Sls | Q5: =B5 -> Angola | R5: =C5 -> Hillsboro | S5: =D5 -> Pixelle | T5: =E5 -> Grand Total | W5: Original | X5: Annualized | Y5: Annualized | AA5: Valuation | AC5: =M5 -> 0 | AD5: =N5 -> Avg/Day | AE5: =O5 -> 5Days Sls | AF5: =P5 -> 0
A6: 1. Sales | B6: -1500193.9 | C6: -2232833 | D6: -962160.67 | E6: -4695187.6 | G6: % of Sales Totals | L6: Sales if 5Days | N6: =D6+O6 -> -91884.67 | O6: =435138*2 -> 870276 | Q6: =B6 -> -1500193.9 | R6: =C6 -> -2232833 | S6: =-O6 -> -870276 | T6: =SUM(Q6:S6) -> -4603303 | U6: =T6*2 -> -9206605.9 | V6: Sales | W6: =-E6 -> 4695187.6 | X6: =W6*2 -> 9390375.3 | Y6: =((410852+444994)/2)*4-B6*2-C6*2 -> 9177745.9 | Z6: =Y6-X6 -> -212629.34 | AB6: Pixelle Q1 overinflated working 6 days, use average of Q2&Q3 | AC6: =Q6*2 -> -3000387.9 | AD6: =R6*2 -> -4465666.1 | AE6: 1800000 | AF6: =SUM(AC6:AE6) -> -5666053.9
A7: 2. Variable cost Labor | B7: 343188.12 | C7: 498256.51 | D7: 315753.08 | E7: 1157197.7 | G7: =-B7/B$6 -> 0.2287625 | H7: =-C7/C$6 -> 0.22314992 | I7: =-D7/D$6 -> 0.32817084 | J7: =-E7/E$6 -> 0.24646464 | N7: =5/6 -> 0.83333333 | O7: =N7*551308 -> 459423.33 | Q7: =B7 -> 343188.12 | R7: =C7 -> 498256.51 | S7: =D7 -> 315753.08 | T7: =SUM(Q7:S7) -> 1157197.7 | U7: =T7*2 -> 2314395.4 | V7: Net Profit | W7: =F22 -> 467828 | X7: =W7*2 -> 935656 | AC7: =Q7*2 -> 686376.24 | AD7: =R7*2 -> 996513.02 | AE7: =O7 -> 459423.33 | AF7: =SUM(AC7:AE7) -> 2142312.6
A8: 2. Variable cost Mat | B8: 855851.1 | C8: 1143410.8 | D8: 22188.07 | E8: 2021450 | G8: =-B8/B$6 -> 0.57049364 | H8: =-C8/C$6 -> 0.5120897 | I8: =-D8/D$6 -> 0.02306067 | J8: =-E8/E$6 -> 0.43053657 | O8: 410852 | Q8: =B8 -> 855851.1 | R8: =C8 -> 1143410.8 | S8: =D8 -> 22188.07 | T8: =SUM(Q8:S8) -> 2021450 | U8: =T8*2 -> 4042899.9 | V8: Deduct Debt Forgiveness | W8: =-'[3]2-T5Y IS (Cont.)'!$D$66 -> -133786 | X8: =W8*2 -> -267572 | AC8: =Q8*2 -> 1711702.2 | AD8: =R8*2 -> 2286821.6 | AE8: =O8 -> 410852 | AF8: =SUM(AC8:AE8) -> 4409375.8
A9: 2a. Variable cost Mat | C9: -19607.13 | E9: -19607.13 | G9: =-B9/B$6 -> 0 | H9: =-C9/C$6 -> -0.0087812791 | I9: =-D9/D$6 -> 0 | J9: =-E9/E$6 -> -0.0041760056 | O9: =AVERAGE(O7:O9) -> 0 | Q9: =B9 -> 0 | R9: =C9 -> -19607.13 | S9: =D9 -> 0 | T9: =SUM(Q9:S9) -> -19607.13 | U9: =T9*2 -> -39214.26 | V9: Net Profit after Debt Adj | W9: =W7+W8 -> 334042 | X9: =W9*2 -> 668084 | Y9: =X9 -> 668084 | Z9: =Y9-X9 -> 0 | AC9: =Q9*2 -> 0 | AD9: =R9*2 -> -39214.26 | AE9: =O9 -> 0 | AF9: =SUM(AC9:AE9) -> -19607.13
A10: 2a. Variable cost Mat Out/Env | C10: 11708.17 | E10: 11708.17 | G10: =-B10/B$6 -> 0 | H10: =-C10/C$6 -> 0.0052436388 | I10: =-D10/D$6 -> 0 | J10: =-E10/E$6 -> 0.0024936533 | Q10: =B10 -> 0 | R10: =C10 -> 11708.17 | S10: =D10 -> 0 | T10: =SUM(Q10:S10) -> 11708.17 | U10: =T10*2 -> 23416.34 | V10: Add back Interest Expense | W10: ='SORTED B VS P'!N288+'SORTED B VS P'!M292 -> 1784.75 | X10: =W10*2 -> 3569.5 | Y10: =X10 -> 3569.5 | Z10: =Y10-X10 -> 0 | AC10: =Q10*2 -> 0 | AD10: =R10*2 -> 23416.34 | AE10: =O10 -> 0 | AF10: =SUM(AC10:AE10) -> 23416.34
A11: 8c. Frt Exp | B11: 5732.8 | C11: 7801.63 | E11: 13534.43 | G11: =-B11/B$6 -> 0.0038213726 | H11: =-C11/C$6 -> 0.0034940499 | I11: =-D11/D$6 -> 0 | J11: =-E11/E$6 -> 0.0028826175 | Q11: =B11 -> 5732.8 | R11: =C11 -> 7801.63 | S11: =D11 -> 0 | T11: =SUM(Q11:S11) -> 13534.43 | U11: =T11*2 -> 27068.86 | V11: Add back Depreciation | W11: =('SORTED B VS P'!N195+'SORTED B VS P'!N196+'SORTED B VS P'!N197+'SORTED B VS P'!N198+'SORTED B VS P'!N199+'SORTED B VS P'!N200+'SORTED B VS P'!N201+'SORTED B VS P'!N202++'SORTED B VS P'!N203+'SORTED B VS P'!N204) -> 106590.78 | X11: =W11*2 -> 213181.56 | Y11: =X11 -> 213181.56 | Z11: =Y11-X11 -> 0 | AC11: =Q11*2 -> 11465.6 | AD11: =R11*2 -> 15603.26 | AE11: =O11 -> 0 | AF11: =SUM(AC11:AE11) -> 27068.86
A12: 3. Mfg IDL | B12: 87123.01 | C12: 115278.5 | D12: 12414.36 | E12: 214815.87 | G12: =-B12/B$6 -> 0.058074498 | H12: =-C12/C$6 -> 0.051628805 | I12: =-D12/D$6 -> 0.012902585 | J12: =-E12/E$6 -> 0.04575235 | L12: CREDIT PIXELLE | N12: -41085 | O12: =D12-N12 -> 53499.36 | Q12: =B12 -> 87123.01 | R12: =C12 -> 115278.5 | S12: =D12 -> 12414.36 | T12: =SUM(Q12:S12) -> 214815.87 | U12: =T12*2 -> 429631.74 | V12: Add back Bank Charges② | W12: ='SORTED B VS P'!N212 -> 17884.74 | X12: =W12*2 -> 35769.48 | Y12: =X12 -> 35769.48 | Z12: =Y12-X12 -> 0 | AC12: =Q12*2 -> 174246.02 | AD12: =R12*2 -> 230557 | AF12: =SUM(AC12:AE12) -> 404803.02
A13: 4. Mfg OVHD | B13: 186209.89 | C13: 202999.64 | D13: 82744.57 | E13: 471954.1 | G13: =-B13/B$6 -> 0.12412388 | H13: =-C13/C$6 -> 0.090915728 | I13: =-D13/D$6 -> 0.085998703 | J13: =-E13/E$6 -> 0.10051869 | Q13: =B13 -> 186209.89 | R13: =C13 -> 202999.64 | S13: =D13 -> 82744.57 | T13: =SUM(Q13:S13) -> 471954.1 | U13: =T13*2 -> 943908.2 | V13: Estimated Fair Market Rent | W13: 0 | X13: =W13*2 -> 0 | Y13: =-AB33 -> -66414 | Z13: =Y13-X13 -> -66414 | AA13: =Z13*3.5 -> -232449 | AC13: =Q13*2 -> 372419.78 | AD13: =R13*2 -> 405999.28 | AE13: =O13 -> 0 | AF13: =SUM(AC13:AE13) -> 778419.06
A14: 7. Selling | B14: 36556.54 | C14: 177818.79 | E14: 214375.33 | G14: =-B14/B$6 -> 0.024367876 | H14: =-C14/C$6 -> 0.079638194 | I14: =-D14/D$6 -> 0 | J14: =-E14/E$6 -> 0.045658522 | Q14: =B14 -> 36556.54 | R14: =C14 -> 177818.79 | S14: =D14 -> 0 | T14: =SUM(Q14:S14) -> 214375.33 | U14: =T14*2 -> 428750.66 | V14: Estimated Fair Market Rent NNN (30%?) | Y14: =Y13*0.35 -> -23244.9 | Z14: =Y14-X14 -> -23244.9 | AA14: =Z14*3.5 -> -81357.15 | AB14: Per AI NNN is usually 25-50% of rent | AC14: =Q14*2 -> 73113.08 | AD14: =R14*2 -> 355637.58 | AE14: =O14 -> 0 | AF14: =SUM(AC14:AE14) -> 428750.66
A15: 8. Admin | B15: 40430.47 | C15: 340312.03 | D15: 19495.37 | E15: 400237.87 | G15: =-B15/B$6 -> 0.026950162 | H15: =-C15/C$6 -> 0.15241266 | I15: =-D15/D$6 -> 0.020262073 | J15: =-E15/E$6 -> 0.085244276 | Q15: =B15 -> 40430.47 | R15: =C15 -> 340312.03 | S15: =D15 -> 19495.37 | T15: =SUM(Q15:S15) -> 400237.87 | U15: =T15*2 -> 800475.74 | V15: Add back 1 owner salary | W15: 0 | X15: =W15*2 -> 0 | Y15: 100000 | Z15: =Y15-X15 -> 100000 | AA15: =Z15*3.5 -> 350000 | AC15: =Q15*2 -> 80860.94 | AD15: =R15*2 -> 680624.06 | AE15: =O15 -> 0 | AF15: =SUM(AC15:AE15) -> 761485
A16: 8. Admin IT | B16: 971.64 | C16: 12346.79 | D16: 825.31 | E16: 14143.74 | G16: =-B16/B$6 -> 0.00064767626 | H16: =-C16/C$6 -> 0.0055296522 | I16: =-D16/D$6 -> 0.00085776734 | J16: =-E16/E$6 -> 0.0030123908 | Q16: =B16 -> 971.64 | R16: =C16 -> 12346.79 | S16: =D16 -> 825.31 | T16: =SUM(Q16:S16) -> 14143.74 | U16: =T16*2 -> 28287.48 | V16: Deduct Gain on Sale of Assets | AC16: =Q16*2 -> 1943.28 | AD16: =R16*2 -> 24693.58 | AE16: =O16 -> 0 | AF16: =SUM(AC16:AE16) -> 26636.86
A17: 8a. Frt Income | B17: -186087.68 | C17: -145148.52 | E17: -331236.2 | F17: how does this tie if Fordyce not in TB? | G17: =-B17/B$6 -> -0.12404242 | H17: =-C17/C$6 -> -0.065006437 | I17: =-D17/D$6 -> 0 | J17: =-E17/E$6 -> -0.070548022 | Q17: =B17 -> -186087.68 | R17: =C17 -> -145148.52 | S17: =D17 -> 0 | T17: =SUM(Q17:S17) -> -331236.2 | U17: =T17*2 -> -662472.4 | V17: Deduct EXCESS Purchase Discounts | AC17: =Q17*2 -> -372175.36 | AD17: =R17*2 -> -290297.04 | AE17: =O17 -> 0 | AF17: =SUM(AC17:AE17) -> -662472.4
A18: 8b. Frt Exp | B18: 145827.64 | C18: 125457.9 | E18: 271285.54 | G18: =-B18/B$6 -> 0.097205859 | H18: =-C18/C$6 -> 0.056187766 | I18: =-D18/D$6 -> 0 | J18: =-E18/E$6 -> 0.057779489 | Q18: =B18 -> 145827.64 | R18: =C18 -> 125457.9 | S18: =D18 -> 0 | T18: =SUM(Q18:S18) -> 271285.54 | U18: =T18*2 -> 542571.08 | V18: Deduct Other Income④ | AC18: =Q18*2 -> 291655.28 | AD18: =R18*2 -> 250915.8 | AE18: =O18 -> 0 | AF18: =SUM(AC18:AE18) -> 542571.08
A19: 9. Scrap & Misc Inc | B19: -2555.07 | C19: -56104.61 | D19: -21843 | E19: -80502.68 | G19: =-B19/B$6 -> -0.0017031598 | H19: =-C19/C$6 -> -0.025127096 | I19: =-D19/D$6 -> -0.02270203 | J19: =-E19/E$6 -> -0.017145786 | Q19: =B19 -> -2555.07 | R19: =C19 -> -56104.61 | S19: =D19 -> -21843 | T19: =SUM(Q19:S19) -> -80502.68 | U19: =T19*2 -> -161005.36 | V19: Pixelle Abnormal Sales Q1 | Y19: =N6 -> -91884.67 | Z19: =Y19-X19 -> -91884.67 | AA19: =Z19*3.5 -> -321596.35 | AB19: HCF ran 6 days (abnormal) to help Pixelle catch up from Mill closer (5/6)= .83%=Adjust out of Sales $91,885 | AC19: =Q19*2 -> -5110.14 | AD19: =R19*2 -> -112209.22 | AE19: =O19 -> 0 | AF19: =SUM(AC19:AE19) -> -117319.36
A20: 91. Other Inc/Exp | B20: 4.33 | C20: -132001.55 | E20: -131997.22 | G20: =-B20/B$6 -> 2.8862935e-06 | H20: =-C20/C$6 -> -0.059118415 | I20: =-D20/D$6 -> 0 | J20: =-E20/E$6 -> -0.0281133 | Q20: =B20 -> 4.33 | R20: 0 | S20: =D20 -> 0 | T20: =SUM(Q20:S20) -> 4.33 | V20: Pixelle Abnormal Sales Duplicated in HY2 2026 Forecast | Y20: =Y19 -> -91884.67 | Z20: =Y20-X20 -> -91884.67 | AA20: =Z20*3.5 -> -321596.35 | AB20: Due the same for Jul-Dec since the P&L was annaulized for the second half year | AC20: =Q20*2 -> 8.66 | AD20: =R20*2 -> 0 | AE20: =O20 -> 0 | AF20: =SUM(AC20:AE20) -> 8.66
A21: 99. Elim | B21: 0 | C21: 0 | D21: 0 | E21: 0 | G21: =-B21/B$6 -> 0 | H21: =-C21/C$6 -> 0 | I21: =-D21/D$6 -> 0 | J21: =-E21/E$6 -> 0 | Q21: =B21 -> 0 | R21: =C21 -> 0 | T21: =SUM(Q21:S21) -> 0 | V21: DLabor Adjustment for Sales Diff | Y21: ='[4]Pixelle P&L'!$D$29 -> 10185.941 | Z21: =Y21-X21 -> 10185.941 | AA21: =Z21*3.5 -> 35650.792 | AC21: =Q21*2 -> 0 | AD21: =R21*2 -> 0 | AF21: =SUM(AC21:AE21) -> 0
A22: Grand Total | B22: 13058.86 | C22: 49695.92 | D22: -530582.91 | E22: -467828.13 | F22: ='[3]2-T5Y IS (Cont.)'!$D$70 -> 467828 | G22: =-B22/B$6 -> 0.0087047813 | H22: =-C22/C$6 -> 0.02225689 | I22: =-D22/D$6 -> -0.55144939 | J22: =-E22/E$6 -> -0.099639922 | Q22: =SUM(Q6:Q21) -> 13058.86 | R22: =SUM(R6:R21) -> 181697.47 | S22: =SUM(S6:S21) -> -438698.24 | T22: =SUM(T6:T21) -> -243941.91 | U22: =SUM(U6:U21) -> -487892.48 | V22: DLabor Adjustment for Sales Diff Dupl in HY2 2026 Forecast | Y22: =Y21 -> 10185.941 | Z22: =Y22-X22 -> 10185.941 | AA22: =Z22*3.5 -> 35650.792 | AC22: =SUM(AC6:AC21) -> 26117.72 | AD22: =SUM(AD6:AD21) -> 363394.94 | AE22: =SUM(AE6:AE21) -> -438698.24 | AF22: =SUM(AF6:AF21) -> -243941.91
A23: 26 Annualized (minus debt forgive) | B23: =-B22*2 -> -26117.72 | C23: =-(C22-C20)*2 -> -363394.94 | D23: =-D22*2 -> 1061165.8 | E23: =-(E22-E20)*2 -> 671661.82 | F23: =(F22+C20)*2 -> 671652.9 | L23: Total Adj | N23: =N6+N12 -> -132969.67 | Q23: =-Q22*2 -> -26117.72 | R23: =-R22*2 -> -363394.94 | S23: =-S22*2 -> 877396.48 | T23: =-T22*2 -> 487883.82 | U23: =-U22*2 -> 975784.96 | V23: Adjusted EBITDA | W23: =SUM(W9:W22) -> 460302.27 | X23: =SUM(X9:X22) -> 920604.54 | Y23: =SUM(Y9:Y22) -> 767548.18 | Z23: =Y23-X23 -> -153056.36 | AA23: =SUM(AA10:AA22) -> -535697.26 | AC23: =-AC22*2 -> -52235.44 | AD23: =-AD22*2 -> -726789.88 | AE23: =-AE22*2 -> 877396.48 | AF23: =-AF22*2 -> 487883.82
A24: 2025 | B24: =[2]Pivot!B$22 -> -188567.02 | C24: =[2]Pivot!C$22 -> 507482.26 | D24: =[2]Pivot!D$22 -> -393948.69 | E24: =[2]Pivot!E$22 -> -75033.45 | F24: =E22-C20 -> -335826.58 | Q24: Difference | T24: =T23-E23 -> -183778 | V24: Valuation 3.5x | X24: =3.5*X23 -> 3222115.9 | Y24: =3.5*Y23 -> 2686418.6 | Z24: =Z23*3.5 -> -535697.26 | AC24: Difference | AF24: =AF23-P23 -> -183778
F25: =F22+C20 -> 335826.45 | L25: =551308+410852 -> 962160
A26: Estimated Jun2026 Full Yr to Full Yr 2025 | F26: =F25*2 -> 671652.9 | G26: 2026 % Change toi 2025 | L26: =L25*2 -> 1924320 | Q26: Pixelle Sales Adjusted by 100k Q1 & 100k HY2 = 200k | W26: 0 | X26: =W26*2 -> 0 | Y26: =X26 -> 0 | Z26: =Y26-X26 -> 0
A27: =A6 -> 1. Sales | B27: =B6*2 -> -3000387.9 | C27: =C6*2 -> -4465666.1 | D27: =D6*2 -> -1924321.3 | E27: =E6*2 -> -9390375.3 | G27: =B27/[2]Pivot!B5-1 -> -0.11822123 | H27: =C27/[2]Pivot!C5-1 -> 0.048125645 | I27: =D27/[2]Pivot!D5-1 -> 1.2114667 | J27: =E27/[2]Pivot!E5-1 -> 0.10042202 | Q27: essentially no cost reductions 2025&2026 cost same | W27: 0 | X27: =W27*2 -> 0 | Y27: =X27 -> 0 | Z27: =Y27-X27 -> 0
A28: =A7 -> 2. Variable cost Labor | B28: =B7*2 -> 686376.24 | C28: =C7*2 -> 996513.02 | D28: =D7*2 -> 631506.16 | E28: =E7*2 -> 2314395.4 | G28: =G7-[2]Pivot!F6 -> 0.027699236 | H28: =H7-[2]Pivot!G6 -> -0.00066119334 | I28: =I7-[2]Pivot!H6 -> -0.017588737 | J28: =J7-[2]Pivot!I6 -> 0.019288972 | L28: $12,000 is for a premium we paid employees to work Saturdays | Q28: 41k Pixelle credit x 2 = 82k full year adjsuted
A29: =A8 -> 2. Variable cost Mat | B29: =B8*2 -> 1711702.2 | C29: =C8*2 -> 2286821.6 | D29: =D8*2 -> 44376.14 | E29: =E8*2 -> 4042899.9 | G29: =G8-[2]Pivot!F7 -> 0.028061849 | H29: =H8-[2]Pivot!G7 -> 0.0057809979 | I29: =I8-[2]Pivot!H7 -> -0.0042176288 | J29: =J8-[2]Pivot!I7 -> -0.041329144 | Q29: Need to understand what issues were and what are extra costs | U29: HCF Acquistion | X29: 2026 HY1 | Z29: After
A30: =A9 -> 2a. Variable cost Mat | B30: =B9*2 -> 0 | C30: =C9*2 -> -39214.26 | D30: =D9*2 -> 0 | E30: =E9*2 -> -39214.26 | G30: =G9-[2]Pivot!F8 -> 0 | H30: =H9-[2]Pivot!G8 -> 0.0035708313 | I30: =I9-[2]Pivot!H8 -> 0 | J30: =J9-[2]Pivot!I8 -> 0.0019912278 | Q30: or are they not producing as much and sales would be higher | U30: SYNERGIES | X30: Before | Y30: 2026 Est | Z30: Acqusition | AB30: Adjusmt
A31: =A10 -> 2a. Variable cost Mat Out/Env | B31: =B10*2 -> 0 | C31: =C10*2 -> 23416.34 | D31: =D10*2 -> 0 | E31: =E10*2 -> 23416.34 | G31: =G10-[2]Pivot!F9 -> -0.00015188439 | H31: =H10-[2]Pivot!G9 -> -0.0016654386 | I31: =I10-[2]Pivot!H9 -> 0 | J31: =J10-[2]Pivot!I9 -> -0.001016514
A32: =A11 -> 8c. Frt Exp | B32: =B11*2 -> 11465.6 | C32: =C11*2 -> 15603.26 | D32: =D11*2 -> 0 | E32: =E11*2 -> 27068.86 | G32: =G11-[2]Pivot!F10 -> -0.0010742856 | H32: =H11-[2]Pivot!G10 -> 4.2578791e-05 | I32: =I11-[2]Pivot!H10 -> -0.00010336076 | J32: =J11-[2]Pivot!I10 -> -0.00080330678 | U32: TOTAL SYNERGIES
A33: =A12 -> 3. Mfg IDL | B33: =B12*2 -> 174246.02 | C33: =C12*2 -> 230557 | D33: =D12*2 -> 24828.72 | E33: =E12*2 -> 429631.74 | G33: =G12-[2]Pivot!F11 -> 0.006868519 | H33: =H12-[2]Pivot!G11 -> -0.013437409 | I33: =I12-[2]Pivot!H11 -> -0.10173113 | J33: =J12-[2]Pivot!I11 -> -0.018841589 | U33: RENT | Y33: =SUM(Y34:Y36) -> 126000 | Z33: =SUM(Z34:Z36) -> 192414 | AB33: =SUM(AB34:AB36) -> 66414
A34: =A13 -> 4. Mfg OVHD | B34: =B13*2 -> 372419.78 | C34: =C13*2 -> 405999.28 | D34: =D13*2 -> 165489.14 | E34: =E13*2 -> 943908.2 | G34: =G13-[2]Pivot!F13 -> 0.010265792 | H34: =H13-[2]Pivot!G13 -> 0.005674589 | I34: =I13-[2]Pivot!H13 -> -0.074265473 | J34: =J13-[2]Pivot!I13 -> -0.0037834038 | U34: Rent | V34: Hillsboro | X34: 0 | Z34: 151914 | AB34: 151914
A35: =A14 -> 7. Selling | B35: =B14*2 -> 73113.08 | C35: =C14*2 -> 355637.58 | D35: =D14*2 -> 0 | E35: =E14*2 -> 428750.66 | G35: =G14-[2]Pivot!F14 -> 0.002703289 | H35: =H14-[2]Pivot!G14 -> -0.009789405 | I35: =I14-[2]Pivot!H14 -> 0 | J35: =J14-[2]Pivot!I14 -> -0.0076300312 | U35: Rent | V35: Angola | X35: 48000 | Y35: 96000 | Z35: 0 | AB35: -96000
A36: =A15 -> 8. Admin | B36: =B15*2 -> 80860.94 | C36: =C15*2 -> 680624.06 | D36: =D15*2 -> 38990.74 | E36: =E15*2 -> 800475.74 | G36: =G15-[2]Pivot!F15 -> -0.00065113526 | H36: =H15-[2]Pivot!G15 -> -0.03125465 | I36: =I15-[2]Pivot!H15 -> -0.017910397 | J36: =J15-[2]Pivot!I15 -> -0.021356514 | U36: Rent | V36: Fordyce | X36: 15000 | Y36: 30000 | Z36: 40500 | AB36: 10500
A37: =A16 -> 8. Admin IT | B37: =B16*2 -> 1943.28 | C37: =C16*2 -> 24693.58 | D37: =D16*2 -> 1650.62 | E37: =E16*2 -> 28287.48 | G37: =G16-[2]Pivot!F16 -> -0.00016828979 | H37: =H16-[2]Pivot!G16 -> 0.00081743291 | I37: =I16-[2]Pivot!H16 -> -0.00083706638 | J37: =J16-[2]Pivot!I16 -> 0.00016146245
A38: =A17 -> 8a. Frt Income | B38: =B17*2 -> -372175.36 | C38: =C17*2 -> -290297.04 | D38: =D17*2 -> 0 | E38: =E17*2 -> -662472.4 | G38: =G17-[2]Pivot!F17 -> -0.033929055 | H38: =H17-[2]Pivot!G17 -> 0.00080304336 | I38: =I17-[2]Pivot!H17 -> 0 | J38: =J17-[2]Pivot!I17 -> -0.0017581263
A39: =A18 -> 8b. Frt Exp | B39: =B18*2 -> 291655.28 | C39: =C18*2 -> 250915.8 | D39: =D18*2 -> 0 | E39: =E18*2 -> 542571.08 | G39: =G18-[2]Pivot!F18 -> 0.024880993 | H39: =H18-[2]Pivot!G18 -> 0.0037073921 | I39: =I18-[2]Pivot!H18 -> 0 | J39: =J18-[2]Pivot!I18 -> 0.002737681
A40: =A19 -> 9. Scrap & Misc Inc | B40: =B19*2 -> -5110.14 | C40: =C19*2 -> -112209.22 | D40: =D19*2 -> -43686 | E40: =E19*2 -> -161005.36 | F40: 12k sale of asset? | G40: =G19-[2]Pivot!F19 -> -0.00038598201 | H40: =H19-[2]Pivot!G19 -> 0.0021395681 | I40: =I19-[2]Pivot!H19 -> -0.01774947 | J40: =J19-[2]Pivot!I19 -> -0.0025016967
...

Sheet 26 EBITDA ADJ
A2: TYPE | B2: IS
A3: HCF FINANCIALS HY1 2026 | L3: Adjustment Calcs | N3: Pixelle | O3: =N3 -> Pixelle | Q3: 2026 6Months | X3: Orignal | Y3: Adjusted | AB3: 2026 12Months
A4: Sum of NET_CHANGE | B4: Column Labels | N4: Adjustment | O4: Adj 2026 HY1 | S4: Adjusted | T4: 2026 Adj 5Days | V4: Adjusted EBITDA | W4: 2026 6Mo | X4: Annualized | Y4: Annualized | Z4: Diff | AD4: Adjusted | AE4: 2026 Adj 5Days
A5: Row Labels | B5: Angola | C5: Hillsboro | D5: Pixelle | E5: Grand Total | F5: Original | G5: =B5 -> Angola | H5: =C5 -> Hillsboro | I5: =D5 -> Pixelle | J5: Total | L5: Adjust 6days vs 5 days | N5: Avg/Day | O5: 5Days Sls | Q5: =B5 -> Angola | R5: =C5 -> Hillsboro | S5: =D5 -> Pixelle | T5: =E5 -> Grand Total | W5: Original | AB5: =M5 -> 0 | AC5: =N5 -> Avg/Day | AD5: =O5 -> 5Days Sls | AE5: =P5 -> 0
A6: 1. Sales | B6: -1500193.9 | C6: -2232833 | D6: -962160.67 | E6: -4695187.6 | G6: % of Sales Totals | L6: Sales if 5Days | N6: =D6+O6 -> -91884.67 | O6: =435138*2 -> 870276 | Q6: =B6 -> -1500193.9 | R6: =C6 -> -2232833 | S6: =-O6 -> -870276 | T6: =SUM(Q6:S6) -> -4603303 | U6: =T6*2 -> -9206605.9 | V6: Net Profit | W6: =F22 -> 467828 | X6: =W6*2 -> 935656 | AB6: =Q6*2 -> -3000387.9 | AC6: =R6*2 -> -4465666.1 | AD6: 1800000 | AE6: =SUM(AB6:AD6) -> -5666053.9
A7: 2. Variable cost Labor | B7: 343188.12 | C7: 498256.51 | D7: 315753.08 | E7: 1157197.7 | G7: =-B7/B$6 -> 0.2287625 | H7: =-C7/C$6 -> 0.22314992 | I7: =-D7/D$6 -> 0.32817084 | J7: =-E7/E$6 -> 0.24646464 | N7: =5/6 -> 0.83333333 | O7: =N7*551308 -> 459423.33 | Q7: =B7 -> 343188.12 | R7: =C7 -> 498256.51 | S7: =D7 -> 315753.08 | T7: =SUM(Q7:S7) -> 1157197.7 | U7: =T7*2 -> 2314395.4 | V7: Deduct Debt Forgiveness | W7: =-'[3]2-T5Y IS (Cont.)'!$D$66 -> -133786 | X7: =W7*2 -> -267572 | AB7: =Q7*2 -> 686376.24 | AC7: =R7*2 -> 996513.02 | AD7: =O7 -> 459423.33 | AE7: =SUM(AB7:AD7) -> 2142312.6
A8: 2. Variable cost Mat | B8: 855851.1 | C8: 1143410.8 | D8: 22188.07 | E8: 2021450 | G8: =-B8/B$6 -> 0.57049364 | H8: =-C8/C$6 -> 0.5120897 | I8: =-D8/D$6 -> 0.02306067 | J8: =-E8/E$6 -> 0.43053657 | O8: 410852 | Q8: =B8 -> 855851.1 | R8: =C8 -> 1143410.8 | S8: =D8 -> 22188.07 | T8: =SUM(Q8:S8) -> 2021450 | U8: =T8*2 -> 4042899.9 | V8: Net Profit after Debt Adj | W8: =W6+W7 -> 334042 | X8: =W8*2 -> 668084 | Y8: =T23 -> 487883.82 | Z8: =Y8-X8 -> -180200.18 | AB8: =Q8*2 -> 1711702.2 | AC8: =R8*2 -> 2286821.6 | AD8: =O8 -> 410852 | AE8: =SUM(AB8:AD8) -> 4409375.8
A9: 2a. Variable cost Mat | C9: -19607.13 | E9: -19607.13 | G9: =-B9/B$6 -> 0 | H9: =-C9/C$6 -> -0.0087812791 | I9: =-D9/D$6 -> 0 | J9: =-E9/E$6 -> -0.0041760056 | O9: =AVERAGE(O7:O9) -> 0 | Q9: =B9 -> 0 | R9: =C9 -> -19607.13 | S9: =D9 -> 0 | T9: =SUM(Q9:S9) -> -19607.13 | U9: =T9*2 -> -39214.26 | V9: Add back Interest Expense/Inc | W9: ='SORTED B VS P'!N288+'SORTED B VS P'!M292 -> 1784.75 | X9: =W9*2 -> 3569.5 | Y9: =X9 -> 3569.5 | Z9: =Y9-X9 -> 0 | AB9: =Q9*2 -> 0 | AC9: =R9*2 -> -39214.26 | AD9: =O9 -> 0 | AE9: =SUM(AB9:AD9) -> -19607.13
A10: 2a. Variable cost Mat Out/Env | C10: 11708.17 | E10: 11708.17 | G10: =-B10/B$6 -> 0 | H10: =-C10/C$6 -> 0.0052436388 | I10: =-D10/D$6 -> 0 | J10: =-E10/E$6 -> 0.0024936533 | Q10: =B10 -> 0 | R10: =C10 -> 11708.17 | S10: =D10 -> 0 | T10: =SUM(Q10:S10) -> 11708.17 | U10: =T10*2 -> 23416.34 | V10: Add back Depreciation | W10: =('SORTED B VS P'!N195+'SORTED B VS P'!N196+'SORTED B VS P'!N197+'SORTED B VS P'!N198+'SORTED B VS P'!N199+'SORTED B VS P'!N200+'SORTED B VS P'!N201+'SORTED B VS P'!N202++'SORTED B VS P'!N203+'SORTED B VS P'!N204) -> 106590.78 | X10: =W10*2 -> 213181.56 | Y10: =X10 -> 213181.56 | Z10: =Y10-X10 -> 0 | AB10: =Q10*2 -> 0 | AC10: =R10*2 -> 23416.34 | AD10: =O10 -> 0 | AE10: =SUM(AB10:AD10) -> 23416.34
A11: 8c. Frt Exp | B11: 5732.8 | C11: 7801.63 | E11: 13534.43 | G11: =-B11/B$6 -> 0.0038213726 | H11: =-C11/C$6 -> 0.0034940499 | I11: =-D11/D$6 -> 0 | J11: =-E11/E$6 -> 0.0028826175 | Q11: =B11 -> 5732.8 | R11: =C11 -> 7801.63 | S11: =D11 -> 0 | T11: =SUM(Q11:S11) -> 13534.43 | U11: =T11*2 -> 27068.86 | V11: Estimated Fair Market Rent | W11: =-90000/2 -> -45000 | X11: =W11*2 -> -90000 | Y11: =-AA33 -> -66414 | Z11: =Y11-X11 -> 23586 | AB11: =Q11*2 -> 11465.6 | AC11: =R11*2 -> 15603.26 | AD11: =O11 -> 0 | AE11: =SUM(AB11:AD11) -> 27068.86
A12: 3. Mfg IDL | B12: 87123.01 | C12: 115278.5 | D12: 12414.36 | E12: 214815.87 | G12: =-B12/B$6 -> 0.058074498 | H12: =-C12/C$6 -> 0.051628805 | I12: =-D12/D$6 -> 0.012902585 | J12: =-E12/E$6 -> 0.04575235 | L12: CREDIT PIXELLE | N12: -41085 | O12: =D12-N12 -> 53499.36 | Q12: =B12 -> 87123.01 | R12: =C12 -> 115278.5 | S12: =D12 -> 12414.36 | T12: =SUM(Q12:S12) -> 214815.87 | U12: =T12*2 -> 429631.74 | V12: Add back Bank Charges② | W12: ='SORTED B VS P'!N212 -> 17884.74 | X12: =W12*2 -> 35769.48 | Y12: =X12 -> 35769.48 | Z12: =Y12-X12 -> 0 | AB12: =Q12*2 -> 174246.02 | AC12: =R12*2 -> 230557 | AE12: =SUM(AB12:AD12) -> 404803.02
A13: 4. Mfg OVHD | B13: 186209.89 | C13: 202999.64 | D13: 82744.57 | E13: 471954.1 | G13: =-B13/B$6 -> 0.12412388 | H13: =-C13/C$6 -> 0.090915728 | I13: =-D13/D$6 -> 0.085998703 | J13: =-E13/E$6 -> 0.10051869 | Q13: =B13 -> 186209.89 | R13: =C13 -> 202999.64 | S13: =D13 -> 82744.57 | T13: =SUM(Q13:S13) -> 471954.1 | U13: =T13*2 -> 943908.2 | V13: Add back Bad Debt③ | W13: ='SORTED B VS P'!N209 -> 0 | X13: =W13*2 -> 0 | Y13: =X13 -> 0 | Z13: =Y13-X13 -> 0 | AB13: =Q13*2 -> 372419.78 | AC13: =R13*2 -> 405999.28 | AD13: =O13 -> 0 | AE13: =SUM(AB13:AD13) -> 778419.06
A14: 7. Selling | B14: 36556.54 | C14: 177818.79 | E14: 214375.33 | G14: =-B14/B$6 -> 0.024367876 | H14: =-C14/C$6 -> 0.079638194 | I14: =-D14/D$6 -> 0 | J14: =-E14/E$6 -> 0.045658522 | Q14: =B14 -> 36556.54 | R14: =C14 -> 177818.79 | S14: =D14 -> 0 | T14: =SUM(Q14:S14) -> 214375.33 | U14: =T14*2 -> 428750.66 | V14: Deduct Gain on Sale of Assets | W14: 0 | X14: =W14*2 -> 0 | Y14: =X14 -> 0 | Z14: =Y14-X14 -> 0 | AB14: =Q14*2 -> 73113.08 | AC14: =R14*2 -> 355637.58 | AD14: =O14 -> 0 | AE14: =SUM(AB14:AD14) -> 428750.66
A15: 8. Admin | B15: 40430.47 | C15: 340312.03 | D15: 19495.37 | E15: 400237.87 | G15: =-B15/B$6 -> 0.026950162 | H15: =-C15/C$6 -> 0.15241266 | I15: =-D15/D$6 -> 0.020262073 | J15: =-E15/E$6 -> 0.085244276 | Q15: =B15 -> 40430.47 | R15: =C15 -> 340312.03 | S15: =D15 -> 19495.37 | T15: =SUM(Q15:S15) -> 400237.87 | U15: =T15*2 -> 800475.74 | V15: Deduct EXCESS Purchase Discounts | W15: 0 | X15: =W15*2 -> 0 | Y15: =X15 -> 0 | Z15: =Y15-X15 -> 0 | AB15: =Q15*2 -> 80860.94 | AC15: =R15*2 -> 680624.06 | AD15: =O15 -> 0 | AE15: =SUM(AB15:AD15) -> 761485
A16: 8. Admin IT | B16: 971.64 | C16: 12346.79 | D16: 825.31 | E16: 14143.74 | G16: =-B16/B$6 -> 0.00064767626 | H16: =-C16/C$6 -> 0.0055296522 | I16: =-D16/D$6 -> 0.00085776734 | J16: =-E16/E$6 -> 0.0030123908 | Q16: =B16 -> 971.64 | R16: =C16 -> 12346.79 | S16: =D16 -> 825.31 | T16: =SUM(Q16:S16) -> 14143.74 | U16: =T16*2 -> 28287.48 | V16: Deduct Other Income④ | W16: 0 | X16: =W16*2 -> 0 | Y16: =X16 -> 0 | Z16: =Y16-X16 -> 0 | AB16: =Q16*2 -> 1943.28 | AC16: =R16*2 -> 24693.58 | AD16: =O16 -> 0 | AE16: =SUM(AB16:AD16) -> 26636.86
A17: 8a. Frt Income | B17: -186087.68 | C17: -145148.52 | E17: -331236.2 | F17: how does this tie if Fordyce not in TB? | G17: =-B17/B$6 -> -0.12404242 | H17: =-C17/C$6 -> -0.065006437 | I17: =-D17/D$6 -> 0 | J17: =-E17/E$6 -> -0.070548022 | Q17: =B17 -> -186087.68 | R17: =C17 -> -145148.52 | S17: =D17 -> 0 | T17: =SUM(Q17:S17) -> -331236.2 | U17: =T17*2 -> -662472.4 | V17: Add back Est. Owners' Perqs | W17: 50000 | X17: =W17*2 -> 100000 | Y17: =X17 -> 100000 | Z17: =Y17-X17 -> 0 | AB17: =Q17*2 -> -372175.36 | AC17: =R17*2 -> -290297.04 | AD17: =O17 -> 0 | AE17: =SUM(AB17:AD17) -> -662472.4
A18: 8b. Frt Exp | B18: 145827.64 | C18: 125457.9 | E18: 271285.54 | G18: =-B18/B$6 -> 0.097205859 | H18: =-C18/C$6 -> 0.056187766 | I18: =-D18/D$6 -> 0 | J18: =-E18/E$6 -> 0.057779489 | Q18: =B18 -> 145827.64 | R18: =C18 -> 125457.9 | S18: =D18 -> 0 | T18: =SUM(Q18:S18) -> 271285.54 | U18: =T18*2 -> 542571.08 | V18: Estimated Fair Market Rent NNN | X18: =W18*2 -> 0 | Y18: =X18 -> 0 | Z18: =Y18-X18 -> 0 | AB18: =Q18*2 -> 291655.28 | AC18: =R18*2 -> 250915.8 | AD18: =O18 -> 0 | AE18: =SUM(AB18:AD18) -> 542571.08
A19: 9. Scrap & Misc Inc | B19: -2555.07 | C19: -56104.61 | D19: -21843 | E19: -80502.68 | G19: =-B19/B$6 -> -0.0017031598 | H19: =-C19/C$6 -> -0.025127096 | I19: =-D19/D$6 -> -0.02270203 | J19: =-E19/E$6 -> -0.017145786 | Q19: =B19 -> -2555.07 | R19: =C19 -> -56104.61 | S19: =D19 -> -21843 | T19: =SUM(Q19:S19) -> -80502.68 | U19: =T19*2 -> -161005.36 | V19: Pixelle Abnormal Sales Q1 | X19: =W19*2 -> 0 | Y19: =X19 -> 0 | Z19: =Y19-X19 -> 0 | AB19: =Q19*2 -> -5110.14 | AC19: =R19*2 -> -112209.22 | AD19: =O19 -> 0 | AE19: =SUM(AB19:AD19) -> -117319.36
A20: 91. Other Inc/Exp | B20: 4.33 | C20: -132001.55 | E20: -131997.22 | G20: =-B20/B$6 -> 2.8862935e-06 | H20: =-C20/C$6 -> -0.059118415 | I20: =-D20/D$6 -> 0 | J20: =-E20/E$6 -> -0.0281133 | Q20: =B20 -> 4.33 | R20: 0 | S20: =D20 -> 0 | T20: =SUM(Q20:S20) -> 4.33 | X20: =W20*2 -> 0 | Y20: =X20 -> 0 | Z20: =Y20-X20 -> 0 | AB20: =Q20*2 -> 8.66 | AC20: =R20*2 -> 0 | AD20: =O20 -> 0 | AE20: =SUM(AB20:AD20) -> 8.66
A21: 99. Elim | B21: 0 | C21: 0 | D21: 0 | E21: 0 | G21: =-B21/B$6 -> 0 | H21: =-C21/C$6 -> 0 | I21: =-D21/D$6 -> 0 | J21: =-E21/E$6 -> 0 | Q21: =B21 -> 0 | R21: =C21 -> 0 | T21: =SUM(Q21:S21) -> 0 | X21: =W21*2 -> 0 | Y21: =X21 -> 0 | Z21: =Y21-X21 -> 0 | AB21: =Q21*2 -> 0 | AC21: =R21*2 -> 0 | AE21: =SUM(AB21:AD21) -> 0
A22: Grand Total | B22: 13058.86 | C22: 49695.92 | D22: -530582.91 | E22: -467828.13 | F22: ='[3]2-T5Y IS (Cont.)'!$D$70 -> 467828 | G22: =-B22/B$6 -> 0.0087047813 | H22: =-C22/C$6 -> 0.02225689 | I22: =-D22/D$6 -> -0.55144939 | J22: =-E22/E$6 -> -0.099639922 | Q22: =SUM(Q6:Q21) -> 13058.86 | R22: =SUM(R6:R21) -> 181697.47 | S22: =SUM(S6:S21) -> -438698.24 | T22: =SUM(T6:T21) -> -243941.91 | U22: =SUM(U6:U21) -> -487892.48 | X22: =W22*2 -> 0 | Y22: =X22 -> 0 | Z22: =Y22-X22 -> 0 | AB22: =SUM(AB6:AB21) -> 26117.72 | AC22: =SUM(AC6:AC21) -> 363394.94 | AD22: =SUM(AD6:AD21) -> -438698.24 | AE22: =SUM(AE6:AE21) -> -243941.91
A23: 26 Annualized (minus debt forgive) | B23: =-B22*2 -> -26117.72 | C23: =-(C22-C20)*2 -> -363394.94 | D23: =-D22*2 -> 1061165.8 | E23: =-(E22-E20)*2 -> 671661.82 | F23: =(F22+C20)*2 -> 671652.9 | L23: Total Adj | N23: =N6+N12 -> -132969.67 | Q23: =-Q22*2 -> -26117.72 | R23: =-R22*2 -> -363394.94 | S23: =-S22*2 -> 877396.48 | T23: =-T22*2 -> 487883.82 | U23: =-U22*2 -> 975784.96 | V23: Adjusted EBITDA | W23: =SUM(W8:W22) -> 465302.27 | X23: =SUM(X8:X22) -> 930604.54 | Y23: =SUM(Y8:Y22) -> 773990.36 | Z23: =Y23-X23 -> -156614.18 | AB23: =-AB22*2 -> -52235.44 | AC23: =-AC22*2 -> -726789.88 | AD23: =-AD22*2 -> 877396.48 | AE23: =-AE22*2 -> 487883.82
A24: 2025 | B24: =[2]Pivot!B$22 -> -188567.02 | C24: =[2]Pivot!C$22 -> 507482.26 | D24: =[2]Pivot!D$22 -> -393948.69 | E24: =[2]Pivot!E$22 -> -75033.45 | F24: =E22-C20 -> -335826.58 | Q24: Difference | T24: =T23-E23 -> -183778 | V24: Valuation 3.5x | X24: =3.5*X23 -> 3257115.9 | Y24: =3.5*Y23 -> 2708966.3 | Z24: =Y24-X24 -> -548149.63 | AB24: Difference | AE24: =AE23-P23 -> -183778
V25: Red-RENT Need to validate still
A26: Estimated Jun2026 Full Yr to Full Yr 2025 | G26: 2026 % Change toi 2025 | Q26: Pixelle Sales Adjusted by 100k Q1 & 100k HY2 = 200k
A27: =A6 -> 1. Sales | B27: =B6*2 -> -3000387.9 | C27: =C6*2 -> -4465666.1 | D27: =D6*2 -> -1924321.3 | E27: =E6*2 -> -9390375.3 | G27: =B27/[2]Pivot!B5-1 -> -0.11822123 | H27: =C27/[2]Pivot!C5-1 -> 0.048125645 | I27: =D27/[2]Pivot!D5-1 -> 1.2114667 | J27: =E27/[2]Pivot!E5-1 -> 0.10042202 | Q27: essentially no cost reductions 2025&2026 cost same
A28: =A7 -> 2. Variable cost Labor | B28: =B7*2 -> 686376.24 | C28: =C7*2 -> 996513.02 | D28: =D7*2 -> 631506.16 | E28: =E7*2 -> 2314395.4 | G28: =G7-[2]Pivot!F6 -> 0.027699236 | H28: =H7-[2]Pivot!G6 -> -0.00066119334 | I28: =I7-[2]Pivot!H6 -> -0.017588737 | J28: =J7-[2]Pivot!I6 -> 0.019288972 | L28: $12,000 is for a premium we paid employees to work Saturdays | Q28: 41k Pixelle credit x 2 = 82k full year adjsuted
A29: =A8 -> 2. Variable cost Mat | B29: =B8*2 -> 1711702.2 | C29: =C8*2 -> 2286821.6 | D29: =D8*2 -> 44376.14 | E29: =E8*2 -> 4042899.9 | G29: =G8-[2]Pivot!F7 -> 0.028061849 | H29: =H8-[2]Pivot!G7 -> 0.0057809979 | I29: =I8-[2]Pivot!H7 -> -0.0042176288 | J29: =J8-[2]Pivot!I7 -> -0.041329144 | Q29: Need to understand what issues were and what are extra costs | U29: HCF Acquistion | X29: 2026 HY1 | Z29: After
A30: =A9 -> 2a. Variable cost Mat | B30: =B9*2 -> 0 | C30: =C9*2 -> -39214.26 | D30: =D9*2 -> 0 | E30: =E9*2 -> -39214.26 | G30: =G9-[2]Pivot!F8 -> 0 | H30: =H9-[2]Pivot!G8 -> 0.0035708313 | I30: =I9-[2]Pivot!H8 -> 0 | J30: =J9-[2]Pivot!I8 -> 0.0019912278 | Q30: or are they not producing as much and sales would be higher | U30: SYNERGIES | X30: Before | Y30: 2026 Est | Z30: Acqusition | AA30: Adjusmt
A31: =A10 -> 2a. Variable cost Mat Out/Env | B31: =B10*2 -> 0 | C31: =C10*2 -> 23416.34 | D31: =D10*2 -> 0 | E31: =E10*2 -> 23416.34 | G31: =G10-[2]Pivot!F9 -> -0.00015188439 | H31: =H10-[2]Pivot!G9 -> -0.0016654386 | I31: =I10-[2]Pivot!H9 -> 0 | J31: =J10-[2]Pivot!I9 -> -0.001016514
A32: =A11 -> 8c. Frt Exp | B32: =B11*2 -> 11465.6 | C32: =C11*2 -> 15603.26 | D32: =D11*2 -> 0 | E32: =E11*2 -> 27068.86 | G32: =G11-[2]Pivot!F10 -> -0.0010742856 | H32: =H11-[2]Pivot!G10 -> 4.2578791e-05 | I32: =I11-[2]Pivot!H10 -> -0.00010336076 | J32: =J11-[2]Pivot!I10 -> -0.00080330678 | U32: TOTAL SYNERGIES
A33: =A12 -> 3. Mfg IDL | B33: =B12*2 -> 174246.02 | C33: =C12*2 -> 230557 | D33: =D12*2 -> 24828.72 | E33: =E12*2 -> 429631.74 | G33: =G12-[2]Pivot!F11 -> 0.006868519 | H33: =H12-[2]Pivot!G11 -> -0.013437409 | I33: =I12-[2]Pivot!H11 -> -0.10173113 | J33: =J12-[2]Pivot!I11 -> -0.018841589 | U33: RENT | Y33: =SUM(Y34:Y36) -> 126000 | Z33: =SUM(Z34:Z36) -> 192414 | AA33: =SUM(AA34:AA36) -> 66414
A34: =A13 -> 4. Mfg OVHD | B34: =B13*2 -> 372419.78 | C34: =C13*2 -> 405999.28 | D34: =D13*2 -> 165489.14 | E34: =E13*2 -> 943908.2 | G34: =G13-[2]Pivot!F13 -> 0.010265792 | H34: =H13-[2]Pivot!G13 -> 0.005674589 | I34: =I13-[2]Pivot!H13 -> -0.074265473 | J34: =J13-[2]Pivot!I13 -> -0.0037834038 | U34: Rent | V34: Hillsboro | X34: 0 | Z34: 151914 | AA34: 151914
A35: =A14 -> 7. Selling | B35: =B14*2 -> 73113.08 | C35: =C14*2 -> 355637.58 | D35: =D14*2 -> 0 | E35: =E14*2 -> 428750.66 | G35: =G14-[2]Pivot!F14 -> 0.002703289 | H35: =H14-[2]Pivot!G14 -> -0.009789405 | I35: =I14-[2]Pivot!H14 -> 0 | J35: =J14-[2]Pivot!I14 -> -0.0076300312 | U35: Rent | V35: Angola | X35: 48000 | Y35: 96000 | Z35: 0 | AA35: -96000
A36: =A15 -> 8. Admin | B36: =B15*2 -> 80860.94 | C36: =C15*2 -> 680624.06 | D36: =D15*2 -> 38990.74 | E36: =E15*2 -> 800475.74 | G36: =G15-[2]Pivot!F15 -> -0.00065113526 | H36: =H15-[2]Pivot!G15 -> -0.03125465 | I36: =I15-[2]Pivot!H15 -> -0.017910397 | J36: =J15-[2]Pivot!I15 -> -0.021356514 | U36: Rent | V36: Fordyce | X36: 15000 | Y36: 30000 | Z36: 40500 | AA36: 10500
A37: =A16 -> 8. Admin IT | B37: =B16*2 -> 1943.28 | C37: =C16*2 -> 24693.58 | D37: =D16*2 -> 1650.62 | E37: =E16*2 -> 28287.48 | G37: =G16-[2]Pivot!F16 -> -0.00016828979 | H37: =H16-[2]Pivot!G16 -> 0.00081743291 | I37: =I16-[2]Pivot!H16 -> -0.00083706638 | J37: =J16-[2]Pivot!I16 -> 0.00016146245
A38: =A17 -> 8a. Frt Income | B38: =B17*2 -> -372175.36 | C38: =C17*2 -> -290297.04 | D38: =D17*2 -> 0 | E38: =E17*2 -> -662472.4 | G38: =G17-[2]Pivot!F17 -> -0.033929055 | H38: =H17-[2]Pivot!G17 -> 0.00080304336 | I38: =I17-[2]Pivot!H17 -> 0 | J38: =J17-[2]Pivot!I17 -> -0.0017581263
A39: =A18 -> 8b. Frt Exp | B39: =B18*2 -> 291655.28 | C39: =C18*2 -> 250915.8 | D39: =D18*2 -> 0 | E39: =E18*2 -> 542571.08 | G39: =G18-[2]Pivot!F18 -> 0.024880993 | H39: =H18-[2]Pivot!G18 -> 0.0037073921 | I39: =I18-[2]Pivot!H18 -> 0 | J39: =J18-[2]Pivot!I18 -> 0.002737681
A40: =A19 -> 9. Scrap & Misc Inc | B40: =B19*2 -> -5110.14 | C40: =C19*2 -> -112209.22 | D40: =D19*2 -> -43686 | E40: =E19*2 -> -161005.36 | F40: 12k sale of asset? | G40: =G19-[2]Pivot!F19 -> -0.00038598201 | H40: =H19-[2]Pivot!G19 -> 0.0021395681 | I40: =I19-[2]Pivot!H19 -> -0.01774947 | J40: =J19-[2]Pivot!I19 -> -0.0025016967
A41: =A20 -> 91. Other Inc/Exp | B41: =B20*2 -> 8.66 | C41: 0 | D41: =D20*2 -> 0 | E41: 0 | G41: =G20-[2]Pivot!F20 -> 3.3682703e-06 | H41: 0 | I41: =I20-[2]Pivot!H20 -> 0 | J41: =J20-[2]Pivot!I20 -> -0.029842116
...

Sheet Pivot
A1: TYPE | B1: IS | K1: TYPE | L1: IS
S2: Half YR | Y2: Full YR
A3: Sum of NET_CHANGE | B3: Column Labels | K3: Sum of NET_CHANGE | L3: Column Labels | S3: Current w/ Allocated Corp 100% to Hillsboro | Y3: BEFORE Acquire | AA3: AFTER Acquire | AG3: BEFORE | AI3: AFTER Acquire
A4: Row Labels | B4: Angola | C4: Hillsboro | D4: Pixelle | E4: Grand Total | F4: =B4 -> Angola | G4: =C4 -> Hillsboro | H4: =D4 -> Pixelle | I4: Total | K4: Row Labels | L4: Angola | M4: Hillsboro | N4: Pixelle | O4: Corp | P4: Grand Total | Q4: Comments | S4: Hills/Ang | T4: =N4 -> Pixelle | U4: Total | V4: =S4 -> Hills/Ang | W4: =T4 -> Pixelle | Y4: Hillsboro | Z4: Synergies | AA4: Hillsboro | AB4: =T4 -> Pixelle | AC4: TOTAL | AE4: Pixelle Higher | AG4: Full Yr No Pix | AH4: =Z4 -> Synergies | AI4: Hillsboro
A5: 1. Sales | B5: -1500193.9 | C5: -2232833 | D5: -962160.67 | E5: -4695187.6 | F5: % of Sales Totals | K5: 1. Sales | L5: -1500193.9 | M5: -2232833 | N5: -962160.67 | O5: 0 | P5: -4695187.6 | S5: =M5+L5 -> -3733027 | T5: =N5 -> -962160.67 | U5: =SUM(S5:T5) -> -4695187.6 | X5: =K5 -> 1. Sales | Y5: =S5*2 -> -7466053.9 | AA5: =Y5+Z5 -> -7466053.9 | AB5: =-450000*2*2 -> -1800000 | AC5: =AA5+AB5 -> -9266053.9 | AE5: =U5*2 -> -9390375.3 | AG5: =-(L5+M5)*2 -> 7466053.9 | AI5: =AG5+AH5 -> 7466053.9
A6: 2. Variable cost Labor | B6: 343188.12 | C6: 498256.51 | D6: 315753.08 | E6: 1157197.7 | F6: =-B6/B$5 -> 0.2287625 | G6: =-C6/C$5 -> 0.22314992 | H6: =-D6/D$5 -> 0.32817084 | I6: =-E6/E$5 -> 0.24646464 | K6: 2. Variable cost Labor | L6: 343188.12 | M6: 498256.51 | N6: 315753.08 | O6: 0 | P6: 1157197.7 | S6: =M6+L6 -> 841444.63 | T6: =N6 -> 315753.08 | U6: =SUM(S6:T6) -> 1157197.7 | V6: =-S6/S$5 -> 0.22540545 | W6: =-T6/T$5 -> 0.32817084 | X6: =K6 -> 2. Variable cost Labor | Y6: =S6*2 -> 1682889.3 | AA6: =Y6+Z6 -> 1682889.3 | AB6: =(T6-U36)*2 -> 611134.28 | AC6: =AA6+AB6 -> 2294023.5 | AE6: =AC6+20000 -> 2314023.5 | AG6: =(L6+M6+O6)*2 -> 1682889.3 | AI6: =AG6+AH6 -> 1682889.3
A7: 2. Variable cost Mat | B7: 855851.1 | C7: 1143410.8 | D7: 22188.07 | E7: 2021450 | F7: =-B7/B$5 -> 0.57049364 | G7: =-C7/C$5 -> 0.5120897 | H7: =-D7/D$5 -> 0.02306067 | I7: =-E7/E$5 -> 0.43053657 | K7: 2. Variable cost Mat | L7: 855851.1 | M7: 1143410.8 | N7: 22188.07 | P7: 2021450 | S7: =M7+L7 -> 1999261.9 | T7: =N7 -> 22188.07 | U7: =SUM(S7:T7) -> 2021450 | V7: =-S7/S$5 -> 0.53556053 | W7: =-T7/T$5 -> 0.02306067 | X7: =K7 -> 2. Variable cost Mat | Y7: =S7*2 -> 3998523.8 | Z7: =Synergies!H44 -> -243478.01 | AA7: =Y7+Z7 -> 3755045.8 | AB7: =T7*2 -> 44376.14 | AC7: =AA7+AB7 -> 3799421.9 | AE7: =AC7 -> 3799421.9 | AG7: =(L7+M7+O7)*2 -> 3998523.8 | AH7: =Synergies!H44 -> -243478.01 | AI7: =AG7+AH7 -> 3755045.8 | AJ7: Paper Synergies
A8: 2a. Variable cost Mat | C8: -19607.13 | E8: -19607.13 | F8: =-B8/B$5 -> 0 | G8: =-C8/C$5 -> -0.0087812791 | H8: =-D8/D$5 -> 0 | I8: =-E8/E$5 -> -0.0041760056 | K8: 2a. Variable cost Mat | O8: -19607.13 | P8: -19607.13 | Q8: ALL Purch Discts | S8: =O8 -> -19607.13 | T8: =N8 -> 0 | U8: =SUM(S8:T8) -> -19607.13 | V8: =-S8/S$5 -> -0.0052523409 | W8: =-T8/T$5 -> 0 | X8: =K8 -> 2a. Variable cost Mat | Y8: =S8*2 -> -39214.26 | AA8: =Y8+Z8 -> -39214.26 | AB8: =T8*2 -> 0 | AC8: =AA8+AB8 -> -39214.26 | AE8: =AC8 -> -39214.26 | AG8: =(L8+M8+O8)*2 -> -39214.26 | AI8: =AG8+AH8 -> -39214.26
A9: 2a. Variable cost Mat Out/Env | C9: 11708.17 | E9: 11708.17 | F9: =-B9/B$5 -> 0 | G9: =-C9/C$5 -> 0.0052436388 | H9: =-D9/D$5 -> 0 | I9: =-E9/E$5 -> 0.0024936533 | K9: 8c. Frt Exp | L9: 5732.8 | M9: 7767.41 | O9: 34.22 | P9: 13534.43 | S9: =M9+L9+O9 -> 13534.43 | T9: =N9 -> 0 | U9: =SUM(S9:T9) -> 13534.43 | V9: =-S9/S$5 -> 0.0036255913 | W9: =-T9/T$5 -> 0 | X9: =K9 -> 8c. Frt Exp | Y9: =S9*2 -> 27068.86 | AA9: =Y9+Z9 -> 27068.86 | AB9: =T9*2 -> 0 | AC9: =AA9+AB9 -> 27068.86 | AE9: =AC9 -> 27068.86 | AG9: =(L9+M9+O9)*2 -> 27068.86 | AI9: =AG9+AH9 -> 27068.86
A10: 8c. Frt Exp | B10: 5732.8 | C10: 7801.63 | E10: 13534.43 | F10: =-B10/B$5 -> 0.0038213726 | G10: =-C10/C$5 -> 0.0034940499 | H10: =-D10/D$5 -> 0 | I10: =-E10/E$5 -> 0.0028826175 | K10: 3. Mfg IDL | L10: 87123.01 | M10: 66748.99 | N10: 12414.36 | O10: 48529.51 | P10: 214815.87 | Q10: Super Sal - Who? | S10: =M10+L10+O10 -> 202401.51 | T10: =N10 -> 12414.36 | U10: =SUM(S10:T10) -> 214815.87 | V10: =-S10/S$5 -> 0.05421914 | W10: =-T10/T$5 -> 0.012902585 | X10: =K10 -> 3. Mfg IDL | Y10: =S10*2 -> 404803.02 | Z10: =-S51-S52 -> -82160 | AA10: =Y10+Z10 -> 322643.02 | AB10: =T10*2 -> 24828.72 | AC10: =AA10+AB10 -> 347471.74 | AE10: =AC10 -> 347471.74 | AG10: =(L10+M10+O10)*2 -> 404803.02 | AH10: =-S51-S52 -> -82160 | AI10: =AG10+AH10 -> 322643.02 | AJ10: IDL Synergies
A11: 3. Mfg IDL | B11: 87123.01 | C11: 115278.5 | D11: 12414.36 | E11: 214815.87 | F11: =-B11/B$5 -> 0.058074498 | G11: =-C11/C$5 -> 0.051628805 | H11: =-D11/D$5 -> 0.012902585 | I11: =-E11/E$5 -> 0.04575235 | K11: 4. Mfg OVHD | L11: 186209.89 | M11: 196237.06 | N11: 82744.57 | O11: 6762.58 | P11: 471954.1 | S11: =M11+L11+O11 -> 389209.53 | T11: =N11 -> 82744.57 | U11: =SUM(S11:T11) -> 471954.1 | V11: =-S11/S$5 -> 0.10426111 | W11: =-T11/T$5 -> 0.085998703 | X11: =K11 -> 4. Mfg OVHD | Y11: =S11*2 -> 778419.06 | Z11: =-S50-S47-S45 -> -208158.76 | AA11: =Y11+Z11 -> 570260.3 | AB11: =T11*2 -> 165489.14 | AC11: =AA11+AB11 -> 735749.44 | AE11: =AC11 -> 735749.44 | AG11: =(L11+M11+O11)*2 -> 778419.06 | AH11: =-S50-S47-S45 -> -208158.76 | AI11: =AG11+AH11 -> 570260.3 | AJ11: OHD Synergies
A12: 4. Mfg OVHD | B12: 186209.89 | C12: 202999.64 | D12: 82744.57 | E12: 471954.1 | F12: =-B12/B$5 -> 0.12412388 | G12: =-C12/C$5 -> 0.090915728 | H12: =-D12/D$5 -> 0.085998703 | I12: =-E12/E$5 -> 0.10051869 | K12: 7. Selling | L12: 36556.54 | M12: 91.2 | O12: 177727.59 | P12: 214375.33 | Q12: Repairs | S12: =M12+L12+O12 -> 214375.33 | T12: =N12 -> 0 | U12: =SUM(S12:T12) -> 214375.33 | V12: =-S12/S$5 -> 0.057426676 | W12: =-T12/T$5 -> 0 | X12: =K12 -> 7. Selling | Y12: =S12*2 -> 428750.66 | AA12: =Y12+Z12 -> 428750.66 | AB12: =T12*2 -> 0 | AC12: =AA12+AB12 -> 428750.66 | AE12: =AC12 -> 428750.66 | AG12: =(L12+M12+O12)*2 -> 428750.66 | AI12: =AG12+AH12 -> 428750.66
A13: 7. Selling | B13: 36556.54 | C13: 177818.79 | E13: 214375.33 | F13: =-B13/B$5 -> 0.024367876 | G13: =-C13/C$5 -> 0.079638194 | H13: =-D13/D$5 -> 0 | I13: =-E13/E$5 -> 0.045658522 | K13: 8. Admin | L13: 40430.47 | M13: 88731 | N13: 19495.37 | O13: 251581.03 | P13: 400237.87 | S13: =M13+L13+(O13) -> 380742.5 | T13: =N13 -> 19495.37 | U13: =SUM(S13:T13) -> 400237.87 | V13: =-S13/S$5 -> 0.10199297 | W13: =-T13/T$5 -> 0.020262073 | X13: =K13 -> 8. Admin | Y13: =S13*2 -> 761485 | Z13: =-S48-S49-S46 -> -116142.92 | AA13: =Y13+Z13 -> 645342.08 | AB13: =T13*2 -> 38990.74 | AC13: =AA13+AB13 -> 684332.82 | AE13: =AC13 -> 684332.82 | AG13: =(L13+M13+O13)*2 -> 761485 | AH13: =-S48-S49-S46 -> -116142.92 | AI13: =AG13+AH13 -> 645342.08 | AJ13: ADMIN Synergies
A14: 8. Admin | B14: 40430.47 | C14: 340312.03 | D14: 19495.37 | E14: 400237.87 | F14: =-B14/B$5 -> 0.026950162 | G14: =-C14/C$5 -> 0.15241266 | H14: =-D14/D$5 -> 0.020262073 | I14: =-E14/E$5 -> 0.085244276 | K14: 8. Admin IT | L14: 971.64 | N14: 825.31 | O14: 12346.79 | P14: 14143.74 | S14: =M14+L14+O14 -> 13318.43 | T14: =N14 -> 825.31 | U14: =SUM(S14:T14) -> 14143.74 | V14: =-S14/S$5 -> 0.0035677294 | W14: =-T14/T$5 -> 0.00085776734 | X14: =K14 -> 8. Admin IT | Y14: =S14*2 -> 26636.86 | AA14: =Y14+Z14 -> 26636.86 | AB14: =T14*2 -> 1650.62 | AC14: =AA14+AB14 -> 28287.48 | AE14: =AC14 -> 28287.48 | AG14: =(L14+M14+O14)*2 -> 26636.86 | AI14: =AG14+AH14 -> 26636.86
A15: 8. Admin IT | B15: 971.64 | C15: 12346.79 | D15: 825.31 | E15: 14143.74 | F15: =-B15/B$5 -> 0.00064767626 | G15: =-C15/C$5 -> 0.0055296522 | H15: =-D15/D$5 -> 0.00085776734 | I15: =-E15/E$5 -> 0.0030123908 | K15: 8a. Frt Income | L15: -186087.68 | M15: -145148.52 | P15: -331236.2 | S15: =M15+L15 -> -331236.2 | T15: =N15 -> 0 | U15: =SUM(S15:T15) -> -331236.2 | V15: =-S15/S$5 -> -0.088731264 | W15: =-T15/T$5 -> 0 | X15: =K15 -> 8a. Frt Income | Y15: =S15*2 -> -662472.4 | AA15: =Y15+Z15 -> -662472.4 | AB15: =T15*2 -> 0 | AC15: =AA15+AB15 -> -662472.4 | AE15: =AC15 -> -662472.4 | AG15: =(L15+M15+O15)*2 -> -662472.4 | AI15: =AG15+AH15 -> -662472.4
A16: 8a. Frt Income | B16: -186087.68 | C16: -145148.52 | E16: -331236.2 | F16: =-B16/B$5 -> -0.12404242 | G16: =-C16/C$5 -> -0.065006437 | H16: =-D16/D$5 -> 0 | I16: =-E16/E$5 -> -0.070548022 | K16: 8b. Frt Exp | L16: 145827.64 | M16: 125457.9 | P16: 271285.54 | S16: =M16+L16 -> 271285.54 | T16: =N16 -> 0 | U16: =SUM(S16:T16) -> 271285.54 | V16: =-S16/S$5 -> 0.072671733 | W16: =-T16/T$5 -> 0 | X16: =K16 -> 8b. Frt Exp | Y16: =S16*2 -> 542571.08 | AA16: =Y16+Z16 -> 542571.08 | AB16: =T16*2 -> 0 | AC16: =AA16+AB16 -> 542571.08 | AE16: =AC16 -> 542571.08 | AG16: =(L16+M16+O16)*2 -> 542571.08 | AI16: =AG16+AH16 -> 542571.08
A17: 8b. Frt Exp | B17: 145827.64 | C17: 125457.9 | E17: 271285.54 | F17: =-B17/B$5 -> 0.097205859 | G17: =-C17/C$5 -> 0.056187766 | H17: =-D17/D$5 -> 0 | I17: =-E17/E$5 -> 0.057779489 | K17: 9. Scrap & Misc Inc | L17: -2555.07 | M17: -53579.61 | N17: -21843 | O17: -2525 | P17: -80502.68 | S17: =M17+L17+O17 -> -58659.68 | T17: =N17+O17 -> -24368 | U17: =SUM(S17:T17) -> -83027.68 | V17: =-S17/S$5 -> -0.015713704 | W17: =-T17/T$5 -> -0.025326331 | X17: =K17 -> 9. Scrap & Misc Inc | Y17: =S17*2 -> -117319.36 | AA17: =Y17+Z17 -> -117319.36 | AB17: =T17*2 -> -48736 | AC17: =AA17+AB17 -> -166055.36 | AE17: =AC17 -> -166055.36 | AG17: =(L17+M17+O17)*2 -> -117319.36 | AI17: =AG17+AH17 -> -117319.36
A18: 9. Scrap & Misc Inc | B18: -2555.07 | C18: -56104.61 | D18: -21843 | E18: -80502.68 | F18: =-B18/B$5 -> -0.0017031598 | G18: =-C18/C$5 -> -0.025127096 | H18: =-D18/D$5 -> -0.02270203 | I18: =-E18/E$5 -> -0.017145786 | K18: 91. Other Inc/Exp | L18: 4.33 | O18: -132001.55 | P18: -131997.22 | Q18: Mostly Pix | U18: =SUM(S18:T18) -> 0 | V18: =-S18/S$5 -> 0 | W18: =-T18/T$5 -> 0 | X18: =K18 -> 91. Other Inc/Exp | Y18: =S18*2 -> 0 | AA18: =Y18+Z18 -> 0 | AB18: =T18*2 -> 0 | AC18: =AA18+AB18 -> 0 | AE18: =AC18 -> 0 | AG18: 0 | AI18: =AG18+AH18 -> 0
A19: 91. Other Inc/Exp | B19: 4.33 | C19: -132001.55 | E19: -131997.22 | F19: =-B19/B$5 -> 2.8862935e-06 | G19: =-C19/C$5 -> -0.059118415 | H19: =-D19/D$5 -> 0 | I19: =-E19/E$5 -> -0.0281133 | K19: 99. Elim | L19: 0 | M19: 0 | N19: 0 | P19: 0 | S19: =M19+L19 -> 0 | T19: =N19 -> 0 | U19: =SUM(S19:T19) -> 0 | V19: =-S19/S$5 -> 0 | W19: =-T19/T$5 -> 0 | X19: =K19 -> 99. Elim | Y19: =S19*2 -> 0 | AA19: =Y19+Z19 -> 0 | AB19: =T19*2 -> 0 | AC19: =AA19+AB19 -> 0 | AE19: =AC19 -> 0 | AG19: =(L19+M19+O19)*2 -> 0 | AI19: =AG19+AH19 -> 0
A20: 99. Elim | B20: 0 | C20: 0 | D20: 0 | E20: 0 | F20: =-B20/B$5 -> 0 | G20: =-C20/C$5 -> 0 | H20: =-D20/D$5 -> 0 | I20: =-E20/E$5 -> 0 | K20: 2a. Variable cost Mat Out/Env | M20: 11708.17 | P20: 11708.17 | S20: =M20+L20 -> 11708.17 | T20: =N20 -> 0 | U20: =SUM(S20:T20) -> 11708.17 | V20: =-S20/S$5 -> 0.0031363743 | W20: =-T20/T$5 -> 0 | X20: =K20 -> 2a. Variable cost Mat Out/Env | Y20: =S20*2 -> 23416.34 | AA20: =Y20+Z20 -> 23416.34 | AB20: =T20*2 -> 0 | AC20: =AA20+AB20 -> 23416.34 | AE20: =AC20 -> 23416.34 | AG20: =(L20+M20+O20)*2 -> 23416.34 | AI20: =AG20+AH20 -> 23416.34
