Workbook

Sheet Summary
A1: HCF vs. Wise - Avery Price List Comparison
A2: Highland: "Avery Price List (Excel).xlsx" (Price Update List as of 9/1/2026)
A3: Wise: Avery price list PDF (cxp_PriceListDownloaderPdf.pdf, generated 10/5/2026)
A5: Coverage | B5: Items | C5: % of Wise list
A6: Items on Highland list | B6: 37
A7: Items on Wise list | B7: 150
A8: On both lists (matched by Spec) | B8: =COUNTA('Price Comparison'!$A$5:$A$24) -> 20 | C8: =B8/B7 -> 0.13333333
A9: Highland only | B9: 17
A10: Wise only | B10: 130 | C10: =B10/B7 -> 0.86666667
A12: Who is cheaper? (matched items) | B12: Items | C12: % of matched
A13: Wise price is lower | B13: =COUNTIF('Price Comparison'!$J$5:$J$24,"Wise") -> 12 | C13: =B13/$B$8 -> 0.6
A14: Highland price is lower | B14: =COUNTIF('Price Comparison'!$J$5:$J$24,"Highland") -> 5 | C14: =B14/$B$8 -> 0.25
A15: Same price | B15: =COUNTIF('Price Comparison'!$J$5:$J$24,"Same") -> 3 | C15: =B15/$B$8 -> 0.15
A17: Size of the gap (Highland minus Wise) | B17: Diff ($) | C17: Diff (%)
A18: Average (all matched items) | B18: =AVERAGE('Price Comparison'!$H$5:$H$24) -> 0.0168 | C18: =AVERAGE('Price Comparison'!$I$5:$I$24) -> 0.035369864
A19: Median (all matched items) | B19: =MEDIAN('Price Comparison'!$H$5:$H$24) -> 0.0055 | C19: =MEDIAN('Price Comparison'!$I$5:$I$24) -> 0.013961526
A20: Average where Wise is lower | B20: =AVERAGEIF('Price Comparison'!$H$5:$H$24,">0") -> 0.070416667 | C20: =AVERAGEIF('Price Comparison'!$I$5:$I$24,">0") -> 0.092638952
A21: Average where Highland is lower | B21: =AVERAGEIF('Price Comparison'!$H$5:$H$24,"<0") -> -0.1018 | C21: =AVERAGEIF('Price Comparison'!$I$5:$I$24,"<0") -> -0.08085403
A22: Largest Highland premium | B22: =MAX('Price Comparison'!$H$5:$H$24) -> 0.154 | C22: =MAX('Price Comparison'!$I$5:$I$24) -> 0.24773414
A23: Largest Highland discount | B23: =MIN('Price Comparison'!$H$5:$H$24) -> -0.302 | C23: =MIN('Price Comparison'!$I$5:$I$24) -> -0.18159952
A25: Top 5 where Highland pays MORE than Wise
A26: Spec / Product | C26: Highland | D26: Wise | E26: Diff ($) | F26: Diff (%)
A27: ='Price Comparison'!A5&" "&'Price Comparison'!B5 -> 53872 TT FSC/S2550/40#SCK | C27: ='Price Comparison'!F5 -> 0.413 | D27: ='Price Comparison'!G5 -> 0.331 | E27: ='Price Comparison'!H5 -> 0.082 | F27: ='Price Comparison'!I5 -> 0.24773414
A28: ='Price Comparison'!A6&" "&'Price Comparison'!B6 -> B5661 TT1C FSC PB/S2550/40#SCK | C28: ='Price Comparison'!F6 -> 0.892 | D28: ='Price Comparison'!G6 -> 0.738 | E28: ='Price Comparison'!H6 -> 0.154 | F28: ='Price Comparison'!I6 -> 0.20867209
A29: ='Price Comparison'!A7&" "&'Price Comparison'!B7 -> C2621 2.3 MIL WH BOPP TC2000/S6650/50# SCK | C29: ='Price Comparison'!F7 -> 1.102 | D29: ='Price Comparison'!G7 -> 0.95 | E29: ='Price Comparison'!H7 -> 0.152 | F29: ='Price Comparison'!I7 -> 0.16
A30: ='Price Comparison'!A8&" "&'Price Comparison'!B8 -> B7699 TT2C FSC/LP1000/40#SCK | C30: ='Price Comparison'!F8 -> 1.131 | D30: ='Price Comparison'!G8 -> 0.977 | E30: ='Price Comparison'!H8 -> 0.154 | F30: ='Price Comparison'!I8 -> 0.15762538
A31: ='Price Comparison'!A9&" "&'Price Comparison'!B9 -> 77921 2M CL PET TC/S8025/50#SCK | C31: ='Price Comparison'!F9 -> 1.726 | D31: ='Price Comparison'!G9 -> 1.597 | E31: ='Price Comparison'!H9 -> 0.129 | F31: ='Price Comparison'!I9 -> 0.080776456
A33: Top 5 where Highland pays LESS than Wise
A34: Spec / Product | C34: Highland | D34: Wise | E34: Diff ($) | F34: Diff (%)
A35: ='Price Comparison'!A24&" "&'Price Comparison'!B24 -> 72825 2M WH PET TC/S333/50#SCK ABC | C35: ='Price Comparison'!F24 -> 1.361 | D35: ='Price Comparison'!G24 -> 1.663 | E35: ='Price Comparison'!H24 -> -0.302 | F35: ='Price Comparison'!I24 -> -0.18159952
A36: ='Price Comparison'!A23&" "&'Price Comparison'!B23 -> 75570 3.0M SYN PAPER/S333/50#SCK | C36: ='Price Comparison'!F23 -> 0.96 | D36: ='Price Comparison'!G23 -> 1.132 | E36: ='Price Comparison'!H23 -> -0.172 | F36: ='Price Comparison'!I23 -> -0.15194346
A37: ='Price Comparison'!A22&" "&'Price Comparison'!B22 -> 53057 54# SG LASER FSC/S2501/53#LF | C37: ='Price Comparison'!F22 -> 0.442 | D37: ='Price Comparison'!G22 -> 0.454 | E37: ='Price Comparison'!H22 -> -0.012 | F37: ='Price Comparison'!I22 -> -0.026431718
A38: ='Price Comparison'!A21&" "&'Price Comparison'!B21 -> 18559 60# ARCHIVAL SG FSC/R5195/41#LF | C38: ='Price Comparison'!F21 -> 0.492 | D38: ='Price Comparison'!G21 -> 0.505 | E38: ='Price Comparison'!H21 -> -0.013 | F38: ='Price Comparison'!I21 -> -0.025742574
A39: ='Price Comparison'!A20&" "&'Price Comparison'!B20 -> 18327 TT1C FSC/R5195/40#SCK | C39: ='Price Comparison'!F20 -> 0.529 | D39: ='Price Comparison'!G20 -> 0.539 | E39: ='Price Comparison'!H20 -> -0.01 | F39: ='Price Comparison'!I20 -> -0.018552876
A41: Notes
A42: - Items are matched on Spec number; product names agree on all 20 matches. Details are on the Price Comparison tab.
A43: - Diff = Highland price minus Wise price. % is Diff divided by the Wise price. Red = Highland pays more, green = Highland pays less.
A44: - Averages are simple (unweighted) because no purchase volumes are available.
A45: - Prices are Avery quoted USD per MSI (per 1,000 sq in), except the Wise-only IL- items, which are per EA.
A46: - The Highland sheet is dated 9/1/2026 and the Wise PDF 10/5/2026, so some Wise effective dates are later.
...

Sheet Price Comparison
A1: Highland Computer Forms vs. Wise Business Forms - Avery Price Comparison (items on both lists)
A2: Diff = Highland minus Wise. Positive (red) = Highland pays more; negative (green) = Highland pays less. USD per unit of measure.
A4: Spec | B4: Product | C4: UOM | D4: Highland Eff. Date | E4: Wise Eff. Date | F4: Highland Price | G4: Wise Price | H4: Diff ($) | I4: Diff (% of Wise) | J4: Lower Price
A5: 53872 | B5: TT FSC/S2550/40#SCK | C5: MSI | D5: 46146 | E5: 46146 | F5: 0.413 | G5: 0.331 | H5: =F5-G5 -> 0.082 | I5: =H5/G5 -> 0.24773414 | J5: =IF(ROUND(H5,5)=0,"Same",IF(H5>0,"Wise","Highland")) -> Wise
A6: B5661 | B6: TT1C FSC PB/S2550/40#SCK | C6: MSI | D6: 46146 | E6: 46146 | F6: 0.892 | G6: 0.738 | H6: =F6-G6 -> 0.154 | I6: =H6/G6 -> 0.20867209 | J6: =IF(ROUND(H6,5)=0,"Same",IF(H6>0,"Wise","Highland")) -> Wise
A7: C2621 | B7: 2.3 MIL WH BOPP TC2000/S6650/50# SCK | C7: MSI | D7: 46146 | E7: 46261 | F7: 1.102 | G7: 0.95 | H7: =F7-G7 -> 0.152 | I7: =H7/G7 -> 0.16 | J7: =IF(ROUND(H7,5)=0,"Same",IF(H7>0,"Wise","Highland")) -> Wise
A8: B7699 | B8: TT2C FSC/LP1000/40#SCK | C8: MSI | D8: 46146 | E8: 46203 | F8: 1.131 | G8: 0.977 | H8: =F8-G8 -> 0.154 | I8: =H8/G8 -> 0.15762538 | J8: =IF(ROUND(H8,5)=0,"Same",IF(H8>0,"Wise","Highland")) -> Wise
A9: 77921 | B9: 2M CL PET TC/S8025/50#SCK | C9: MSI | D9: 46146 | E9: 46146 | F9: 1.726 | G9: 1.597 | H9: =F9-G9 -> 0.129 | I9: =H9/G9 -> 0.080776456 | J9: =IF(ROUND(H9,5)=0,"Same",IF(H9>0,"Wise","Highland")) -> Wise
A10: 77609 | B10: 3MIL MATTE WH BOPP TC/AT20/40#SCK | C10: MSI | D10: 46146 | E10: 46146 | F10: 0.846 | G10: 0.787 | H10: =F10-G10 -> 0.059 | I10: =H10/G10 -> 0.074968234 | J10: =IF(ROUND(H10,5)=0,"Same",IF(H10>0,"Wise","Highland")) -> Wise
A11: C2331 | B11: DT 300LD PF FSC/S2550/40#SCK | C11: MSI | D11: 46146 | E11: 46146 | F11: 0.463 | G11: 0.437 | H11: =F11-G11 -> 0.026 | I11: =H11/G11 -> 0.059496568 | J11: =IF(ROUND(H11,5)=0,"Same",IF(H11>0,"Wise","Highland")) -> Wise
A12: 18884 | B12: LCJ300 FSC/S9010N/46#LF | C12: MSI | D12: 46146 | E12: 46146 | F12: 0.431 | G12: 0.408 | H12: =F12-G12 -> 0.023 | I12: =H12/G12 -> 0.056372549 | J12: =IF(ROUND(H12,5)=0,"Same",IF(H12>0,"Wise","Highland")) -> Wise
A13: 71055 | B13: 2M WH PRT PET/R143/50#SCK | C13: MSI | D13: 46146 | E13: 46146 | F13: 1.851 | G13: 1.8 | H13: =F13-G13 -> 0.051 | I13: =H13/G13 -> 0.028333333 | J13: =IF(ROUND(H13,5)=0,"Same",IF(H13>0,"Wise","Highland")) -> Wise
A14: 54314 | B14: TTC FSC/AT2550/40#CK | C14: MSI | D14: 46146 | E14: 46146 | F14: 0.352 | G14: 0.346 | H14: =F14-G14 -> 0.006 | I14: =H14/G14 -> 0.01734104 | J14: =IF(ROUND(H14,5)=0,"Same",IF(H14>0,"Wise","Highland")) -> Wise
A15: 53753 | B15: 7PT C1S THERMAL TRANSFER FSC | C15: MSI | D15: 46220 | E15: 46220 | F15: 0.382 | G15: 0.378 | H15: =F15-G15 -> 0.004 | I15: =H15/G15 -> 0.010582011 | J15: =IF(ROUND(H15,5)=0,"Same",IF(H15>0,"Wise","Highland")) -> Wise
A16: 18329 | B16: 50# DSX FSC/R5195/50#CK | C16: MSI | D16: 46146 | E16: 46206 | F16: 0.517 | G16: 0.512 | H16: =F16-G16 -> 0.005 | I16: =H16/G16 -> 0.009765625 | J16: =IF(ROUND(H16,5)=0,"Same",IF(H16>0,"Wise","Highland")) -> Wise
... A24: 72825 | B24: 2M WH PET TC/S333/50#SCK ABC | C24: MSI | D24: 46146 | E24: 46146 | F24: 1.361 | G24: 1.663 | H24: =F24-G24 -> -0.302 | I24: =H24/G24 -> -0.18159952 | J24: =IF(ROUND(H24,5)=0,"Same",IF(H24>0,"Wise","Highland")) -> Highland

Sheet Highland Only
A1: On the Highland list but NOT on the Wise list
A3: Spec | B3: Product | C3: UOM | D3: Highland Eff. Date | E3: Highland Price
A4: 15666 | B4: DISSOLVABLE FSC/S2600/40# | C4: MSI | D4: 46140 | E4: 1.663
A5: 19046 | B5: SF 50#DSX FSC/S9010N/45#BK | C5: MSI | D5: 46146 | E5: 0.513
A6: 53110 | B6: DEMANDJET500HG FSC/S2501/40#SCK | C6: MSI | D6: 46146 | E6: 1.209
A7: 53870 | B7: SF TTC FSC/S2550/40#SCK | C7: MSI | D7: 46146 | E7: 0.354
A8: 54247 | B8: DT 200HD RX PF FSC/S2501/40# | C8: MSI | D8: 46146 | E8: 0.629
A9: 54296 | B9: SF 50# DSX FSC/AT2550/50#CK | C9: MSI | D9: 46146 | E9: 0.506
A10: 76656 | B10: 2M WH PET TC/S8015/50#SCK | C10: MSI | D10: 46146 | E10: 1.8
A11: 78401 | B11: 3.0M SYN PAPER/S8001/50#SCK | C11: MSI | D11: 46146 | E11: 0.96
A12: 81628 | B12: TYVEK/S730/50#SCK | C12: MSI | D12: 46146 | E12: 3.556
A13: B4336 | B13: MAT LITHO FSC/AT2550/40# SCK | C13: MSI | D13: 46164 | E13: 0.48
A14: B4338 | B14: 60#GLOSS/AT2550/40# | C14: MSI | D14: 46172 | E14: 0.48
A15: B6003 | B15: 2M VOID PET WH TC/S8015A/50#SCK | C15: MSI | D15: 46146 | E15: 3.438
... A20: C2779 | B20: DT 300LD PF FSC/AT2550/40#SCK | C20: MSI | D20: 46142 | E20: 0.365

Sheet Wise Only
A1: On the Wise list but NOT on the Highland list
A3: Spec | B3: Product | C3: UOM | D3: Wise Eff. Date | E3: Wise Price
A4: 01292 | B4: TT1C FSC 1M PE WELD/TL2/40#SCK | C4: MSI | D4: 46146 | E4: 2.257
A5: 02329 | B5: TT2C FSC/S246/50#SCK | C5: MSI | D5: 46217 | E5: 0.595
A6: 03172 | B6: DT 300HD PF FSC/HMR/40#SCK | C6: MSI | D6: 46146 | E6: 1.178
A7: 03558 | B7: MATTE LITHO FSC/S246/40#SCK | C7: MSI | D7: 46146 | E7: 0.53
A8: 05040 | B8: SGE FSC/HMR/40#SCK | C8: MSI | D8: 46301 | E8: 1.116
A9: 07605 | B9: HG+/S246/50#CK | C9: MSI | D9: 46233 | E9: 0.635
A10: 07944 | B10: LT WT PH LITHO FSC/S727/40#SCK | C10: MSI | D10: 46146 | E10: 1.188
A11: 13014 | B11: SGE FSC/TL2/40#SCK | C11: MSI | D11: 46301 | E11: 1.45
A12: 13605 | B12: TT1C FSC/S246/40#SCK | C12: MSI | D12: 46146 | E12: 0.505
A13: 14188 | B13: TT1C FSC/HMR/40#SCK | C13: MSI | D13: 46146 | E13: 1.051
A14: 14554 | B14: TRANSCODE/TL2/50#SCK | C14: MSI | D14: 46301 | E14: 2.543
A15: 14857 | B15: 2.6M WH BOPP/TL2/40#SCK | C15: MSI | D15: 46146 | E15: 1.141
... A133: C4065 | B133: IL-611306 AD Squarewave WEL M830 RIF Wet | C133: EA | D133: 46204 | E133: 0.0478
