Workbook

Sheet 1-T5Y IS
B2: Financial Information | C2: Highland Computer Forms, Inc.
B3: Date: 07/15/2026 | C3: Hillsboro, Ohio "S"-Corp
C4: Fiscal years ending December 31st
C6: Internal | D6: Adjusted RS | E6: Internal | F6: Adjusted RS | G6: Internal | H6: Adjusted RS | I6: Review | J6: Internal | K6: Internal | L6: Review | M6: Review | N6: Review | O6: Review | P6: Review
B7: INCOME STATEMENT | C7: 6 mo.-'26 | D7: 6 mo.-'26 | E7: Q2-'26 | F7: Q2-'26 | G7: Q1-'26 | H7: Q1-'26 | I7: FY2025 | J7: 6 mo.-'25 | K7: 6 mo.-'24 | L7: FY2024 | M7: FY2023 | N7: FY2022 | O7: FY2021 | P7: FY2020
B8: Sales
B9: HCF Sales, Net | C9: ='2024&2023'!C3 -> 4695188 | D9: =+F9+H9 -> 4695187 | E9: =C9-G9 -> 2315210 | F9: =4695187-H9 -> 2315209 | G9: ='2024&2023'!D3 -> 2379978 | H9: 2379978 | I9: ='2024&2023'!E3 -> 8533432 | J9: ='2024&2023'!F3 -> 4406436 | K9: ='2024&2023'!G3 -> 4464702 | L9: ='2024&2023'!H3 -> 8855077 | M9: ='2024&2023'!I3 -> 10655460
B10: G. Fordyce Sales, Net | I10: ='2024&2023'!E4 -> 347072 | L10: ='2024&2023'!H4 -> 370068 | M10: ='2024&2023'!I4 -> 264960
B11: Scrap Paper & Rebates | C11: ='2024&2023'!C5 -> 80502 | D11: =+F11+H11 -> 80502 | E11: =C11-G11 -> 50798 | F11: =63892+16610-29704 -> 50798 | G11: ='2024&2023'!D5 -> 29704 | H11: =27819+1885 -> 29704 | I11: ='2024&2023'!E5 -> 125545 | J11: ='2024&2023'!F5 -> 72205 | K11: ='2024&2023'!G5 -> 72457 | L11: ='2024&2023'!H5 -> 126021 | M11: ='2024&2023'!I5 -> 206685
B12: Total Sales, Net | C12: =SUM(C9:C11) -> 4775690 | D12: =SUM(D9:D11) -> 4775689 | E12: =SUM(E9:E11) -> 2366008 | F12: =SUM(F9:F11) -> 2366007 | G12: =SUM(G9:G11) -> 2409682 | H12: =SUM(H9:H11) -> 2409682 | I12: =SUM(I9:I11) -> 9006049 | J12: =SUM(J9:J11) -> 4478641 | ... M12: =SUM(M9:M11) -> 11127105 | N12: ='2024&2023'!J3 -> 11681336 | O12: ='2024&2023'!K3 -> 10246051 | P12: ='2024&2023'!L3 -> 9810201
B14: Cost of Goods Sold
B15: Materials
B16: Beginning Inventories (HCF) | C16: ='2024&2023'!C7 -> 203836 | D16: 1239901 | E16: 255947 | F16: 1202624 | G16: ='2024&2023'!D7 -> 203836 | H16: 1239901 | I16: ='2024&2023'!E7 -> 1021535 | J16: ='2024&2023'!F7 -> 226313 | K16: ='2024&2023'!G7 -> 313473 | L16: ='2024&2023'!H7 -> 1051427 | M16: ='2024&2023'!I7 -> 1733922 | N16: ='2024&2023'!J7 -> 1107863 | O16: ='2024&2023'!K7 -> 683140 | P16: ='2024&2023'!L7 -> 683140
B17: Beginning Inventories (G. Fordyce) | I17: ='2024&2023'!E8 -> 0 | L17: ='2024&2023'!H8 -> 45134 | M17: ='2024&2023'!I8 -> 0
B18: Paper | C18: ='2024&2023'!C10 -> 1555246 | D18: =+F18+H18 -> 1457822.2 | E18: =C18-G18 -> 779277 | F18: =779277+96081.2-104117 -> 771241.2 | G18: ='2024&2023'!D10 -> 775969 | H18: =775969-14910-37201-37277 -> 686581 | I18: ='2024&2023'!E10 -> 3408695 | J18: ='2024&2023'!F10 -> 1725419 | K18: ='2024&2023'!G10 -> 1808752 | L18: ='2024&2023'!H10 -> 3692358 | M18: ='2024&2023'!I10 -> 3982914 | N18: ='2024&2023'!J10 -> 5780557 | O18: ='2024&2023'!K10 -> 4920814 | P18: ='2024&2023'!L10 -> 4390895
B19: Supplies (HCF) | C19: ='2024&2023'!C37 -> 204362 | D19: =+F19+H19 -> 167191 | E19: =C19-G19 -> 103681 | F19: =100404+66787-H19 -> 81381 | G19: ='2024&2023'!D37 -> 100681 | H19: =44922+40888 -> 85810 | I19: ='2024&2023'!E15 -> 308812 | J19: ='2024&2023'!F37 -> 182646 | K19: ='2024&2023'!G37 -> 196587 | L19: ='2024&2023'!H15 -> 327826 | M19: ='2024&2023'!I15 -> 329822 | N19: ='2024&2023'!J15 -> 381473 | O19: ='2024&2023'!K15 -> 359935 | P19: ='2024&2023'!L15 -> 309092
B20: Supplies (G. Fordyce) | D20: =+F20+H20 -> 0 | E20: =C20-G20 -> 0 | I20: ='2024&2023'!E16+'2024&2023'!E38 -> 12632 | L20: ='2024&2023'!H16+'2024&2023'!H38 -> 2364 | M20: ='2024&2023'!I16+'2024&2023'!I38 -> 50791
B21: Buyouts & Outside Purchases (HCF) | C21: ='2024&2023'!C17 -> 0 | D21: =+F21+H21 -> 37171 | E21: =C21-G21 -> 0 | F21: =37171-H21 -> 22300 | G21: ='2024&2023'!D17 -> 0 | H21: =14871+0 -> 14871 | I21: ='2024&2023'!E17 -> 48537 | J21: ='2024&2023'!F17 -> 516 | K21: ='2024&2023'!G17 -> 0 | L21: ='2024&2023'!H17 -> 69427 | M21: ='2024&2023'!I17 -> 91234 | N21: ='2024&2023'!J17 -> 104261 | O21: ='2024&2023'!K17 -> 112637 | P21: ='2024&2023'!L17 -> 163690
B22: Buyouts & Outside Purchases (G. Fordyce) | C22: ='2024&2023'!C18 -> 0 | D22: =+F22+H22 -> 0 | E22: =C22-G22 -> 0 | G22: ='2024&2023'!D18 -> 0 | I22: ='2024&2023'!E18 -> 186902 | J22: ='2024&2023'!F18 -> 0 | K22: ='2024&2023'!G18 -> 0 | L22: ='2024&2023'!H18 -> 207091 | M22: ='2024&2023'!I18 -> 166233
B23: Cartons | C23: ='2024&2023'!C23 -> 76707 | D23: =+F23+H23 -> 76707 | E23: =C23-G23 -> 37188 | F23: =76707-39519 -> 37188 | G23: ='2024&2023'!D23 -> 39519 | H23: 39519 | I23: ='2024&2023'!E23 -> 160443 | J23: ='2024&2023'!F23 -> 86112 | K23: ='2024&2023'!G23 -> 91936 | L23: ='2024&2023'!H23 -> 180668 | M23: ='2024&2023'!I23 -> 225574 | N23: ='2024&2023'!J23 -> 267861 | O23: ='2024&2023'!K23 -> 205064 | P23: ='2024&2023'!L23 -> 195649
B24: Ink | C24: ='2024&2023'!C31 -> 39332 | D24: =+F24+H24 -> 39332 | E24: =C24-G24 -> 18262 | F24: =39332-21070 -> 18262 | G24: ='2024&2023'!D31 -> 21070 | H24: 21070 | I24: ='2024&2023'!E31 -> 64635 | J24: ='2024&2023'!F31 -> 33175 | K24: ='2024&2023'!G31 -> 34202 | L24: ='2024&2023'!H31 -> 94918 | M24: ='2024&2023'!I31 -> 94148 | N24: ='2024&2023'!J31 -> 116856 | O24: ='2024&2023'!K31 -> 125195 | P24: ='2024&2023'!L31 -> 131612
B25: Envelopes | C25: ='2024&2023'!C33 -> 11708 | D25: =+F25+H25 -> 11708 | E25: =C25-G25 -> 6157 | F25: =11708-5551 -> 6157 | G25: ='2024&2023'!D33 -> 5551 | H25: 5551 | I25: ='2024&2023'!E33 -> 29437 | J25: ='2024&2023'!F33 -> 17665 | K25: ='2024&2023'!G33 -> 18433 | L25: ='2024&2023'!H33 -> 31056 | M25: ='2024&2023'!I33 -> 33531 | N25: ='2024&2023'!J33 -> 40827 | O25: ='2024&2023'!K33 -> 44298 | P25: ='2024&2023'!L33 -> 39991
B26: Carbon Products | C26: ='2024&2023'!C34 -> 1184 | D26: =+F26+H26 -> 1184 | E26: =C26-G26 -> 38 | F26: =1184-1146 -> 38 | G26: ='2024&2023'!D34 -> 1146 | H26: 1146 | I26: ='2024&2023'!E34 -> 1375 | J26: ='2024&2023'!F34 -> 884 | K26: ='2024&2023'!G34 -> 4565 | L26: ='2024&2023'!H34 -> 6961 | M26: ='2024&2023'!I34 -> 6603 | N26: ='2024&2023'!J34 -> 10241 | O26: ='2024&2023'!K34 -> 2163 | P26: ='2024&2023'!L34 -> 2741
B27: Copy Paper | C27: ='2024&2023'!C36 -> 0 | D27: =+F27+H27 -> 0 | E27: =C27-G27 -> 0 | G27: ='2024&2023'!D36 -> 0 | I27: ='2024&2023'!E36 -> 0 | J27: ='2024&2023'!F36 -> 0 | K27: ='2024&2023'!G36 -> 2773 | L27: ='2024&2023'!H36 -> 2773 | M27: ='2024&2023'!I36 -> 0 | N27: ='2024&2023'!J36 -> 92 | O27: ='2024&2023'!K36 -> 135 | P27: ='2024&2023'!L36 -> 967
B28: Inventory Obsolescence | C28: 0 | D28: =+F28+H28 -> 0 | E28: =C28-G28 -> 0 | G28: 0 | I28: ='2024&2023'!E40 -> 46829 | J28: 0 | K28: 0 | L28: 0 | M28: 0 | N28: 0 | O28: 0 | P28: 0
B29: Less Purchase Discounts (HCF) | C29: ='2024&2023'!C43 -> -19607 | D29: =+F29+H29 -> -60692.72 | E29: =C29-G29 -> -10300 | F29: =-19607+9307-8369.59 -> -18669.59 | G29: ='2024&2023'!D43 -> -9307 | H29: =-9307-32716.13 -> -42023.13 | I29: ='2024&2023'!E43 -> -170697 | J29: ='2024&2023'!F43 -> -31307 | K29: ='2024&2023'!G43 -> -30420 | L29: ='2024&2023'!H43 -> -62386 | M29: ='2024&2023'!I43 -> -84956
B30: Less Purchase Discounts (G. Fordyce) | E30: =C30-G30 -> 0 | I30: ='2024&2023'!E44 -> -183 | L30: ='2024&2023'!H44 -> -246 | M30: ='2024&2023'!I44 -> -210
B31: Less Ending Inventories | C31: ='2024&2023'!C48 -> -159866 | D31: -1098507 | E31: -159866 | F31: -1098507 | G31: ='2024&2023'!D48 -> -255947 | H31: -1202624 | I31: ='2024&2023'!E48 -> -1239901 | J31: ='2024&2023'!F48 -> -225544 | K31: ='2024&2023'!G48 -> -199589 | L31: ='2024&2023'!H48 -> -1021535 | M31: ='2024&2023'!I48 -> -1096561 | N31: ='2024&2023'!J48 -> -1733922 | O31: ='2024&2023'!K48 -> -1107863 | P31: ='2024&2023'!L48 -> -632835
B32: Sub-total Materials | C32: =SUM(C16:C31) -> 1912902 | D32: =SUM(D16:D31) -> 1871816.5 | E32: =SUM(E16:E31) -> 1030384 | F32: =SUM(F16:F31) -> 1022014.6 | G32: =SUM(G16:G31) -> 882518 | H32: =SUM(H16:H31) -> 849801.87 | I32: =SUM(I16:I31) -> 3879051 | J32: =SUM(J16:J31) -> 2015879 | ... P32: =SUM(P16:P31) -> 5284942
B33: % to Total COGS | C33: =IFERROR(C32/C66,"") -> 0.51149779 | D33: =IFERROR(D32/D66,"") -> 0.49583457 | E33: =IFERROR(E32/E66,"") -> 0.51818212 | F33: =IFERROR(F32/F66,"") -> 0.50980246 | G33: =IFERROR(G32/G66,"") -> 0.50390848 | H33: =IFERROR(H32/H66,"") -> 0.48001753 | I33: =IFERROR(I32/I66,"") -> 0.5304548 | J33: =IFERROR(J32/J66,"") -> 0.55732174 | ... P33: =IFERROR(P32/P66,"") -> 0.60078079
B35: Labor
B36: Supervisors' Salaries (HCF) | C36: ='2024&2023'!C19 -> 7443 | D36: =+F36+H36 -> 148405.61 | E36: =C36-G36 -> 16164 | F36: =31420.42+39840.4+28614.88+48529.51-72182 -> 76223.21 | G36: ='2024&2023'!D19 -> -8721 | H36: =23994.88+15525.96+18501.12+14160.44 -> 72182.4 | I36: ='2024&2023'!E19 -> 297193 | J36: ='2024&2023'!F19 -> 4379 | K36: ='2024&2023'!G19 -> 42516 | L36: ='2024&2023'!H19 -> 268102 | M36: ='2024&2023'!I19 -> 280397 | N36: ='2024&2023'!J19 -> 229257 | O36: ='2024&2023'!K19 -> 198693 | P36: ='2024&2023'!L19 -> 209196
B37: Supervisors' Salaries (G. Fordyce) | D37: =+F37+H37 -> 0 | E37: =C37-G37 -> 0 | I37: ='2024&2023'!E20 -> 0 | L37: ='2024&2023'!H20 -> 980 | M37: ='2024&2023'!I20 -> 0
B38: ='2024&2023'!B11 -> Production and Collator Wages (HCF) | C38: ='2024&2023'!C11 -> 686327 | D38: =+F38+H38 -> 588773.55 | E38: =C38-G38 -> 349654 | F38: =195400.87+132082.52+192924.91+11856.83+1885.59+16086.61+13301.93+9474.5+3777.6+4738.4+3327.68+3916.4-290730 -> 298043.84 | G38: ='2024&2023'!D11 -> 336673 | H38: =96603.31+68017.23+95593.65+4546.34+1357.58+9167.59+5231.56+4529.49+1619.2+1624.4+1104.96+1334.4 -> 290729.71 | I38: ='2024&2023'!E11 -> 964599 | J38: ='2024&2023'!F11 -> 550391 | K38: ='2024&2023'!G11 -> 583091 | L38: ='2024&2023'!H11 -> 965420 | M38: ='2024&2023'!I11 -> 1082631 | N38: ='2024&2023'!J11 -> 1144403 | O38: ='2024&2023'!K11 -> 1120001 | P38: ='2024&2023'!L11 -> 1091526
B39: Production and Collator Wages (G. Fordyce) | D39: =+F39+H39 -> 0 | E39: =C39-G39 -> 0 | I39: ='2024&2023'!E12 -> 73530 | L39: ='2024&2023'!H12 -> 84107 | M39: ='2024&2023'!I12 -> 136379
B40: Shipping Wages① | C40: 0 | D40: =+F40+H40 -> 64372.38 | E40: =C40-G40 -> 0 | F40: =15699.76+18393.18+22463.2+57.9+1512.92+1626.65+1324.85+2422+409.2+463.2-32906 -> 31466.86 | G40: 0 | H40: =7971.35+8886.85+11072+683.04+600.54+978.94+2422+136.4+154.4 -> 32905.52 | I40: ='2024&2023'!E30 -> 120598 | J40: 0 | K40: 0 | L40: ='2024&2023'!H30 -> 119383 | M40: ='2024&2023'!I30 -> 93521 | N40: ='2024&2023'!J30 -> 97494 | O40: ='2024&2023'!K30 -> 100963 | P40: ='2024&2023'!L30 -> 91173
B41: ='2024&2023'!B13 -> Indirect Labor | C41: ='2024&2023'!C13 -> 297222 | D41: =+F41+H41 -> 221782.59 | E41: =C41-G41 -> 151940 | F41: =18093.38+26890.05-8500.32+1118.25+210.75+30+1260+448+800+480+672+480+35623.52+54.76+2504.83+939.6+88431.96+3399.18+3773.1+1949.6+15107.15+24574.86+19.54+1999.17+610.4+409.2+403.2-106685 -> 115097.18 | G41: ='2024&2023'!D13 -> 145282 | H41: =8751.67+13287.56-3762.29+267.19+94.5+15+744.44+160+160+224+160+17957.96+54.76+847.43+305.2+41395.52+2270.17+1718.48+559.2+8013.21+12385.73+12.79+456.09+336+136.4+134.4 -> 106685.41 | I41: ='2024&2023'!E13 -> 486589 | J41: ='2024&2023'!F13 -> 324530 | K41: ='2024&2023'!G13 -> 334157 | L41: ='2024&2023'!H13 -> 523378 | M41: ='2024&2023'!I13 -> 608621 | N41: ='2024&2023'!J13 -> 594797 | O41: ='2024&2023'!K13 -> 563755 | P41: ='2024&2023'!L13 -> 573376
B42: ='2024&2023'!B22 -> Payroll Taxes | C42: ='2024&2023'!C22 -> 95499 | D42: =+F42+H42 -> 95499 | E42: =C42-G42 -> 42313 | F42: =95499-53186 -> 42313 | G42: ='2024&2023'!D22 -> 53186 | H42: 53186 | I42: ='2024&2023'!E22 -> 200715 | J42: ='2024&2023'!F22 -> 96885 | K42: ='2024&2023'!G22 -> 101738 | L42: ='2024&2023'!H22 -> 200385 | M42: ='2024&2023'!I22 -> 232730 | N42: ='2024&2023'!J22 -> 238780 | O42: ='2024&2023'!K22 -> 198502 | P42: ='2024&2023'!L22 -> 179936
B43: Health Insurance② | C43: ='2024&2023'!C14 -> 299280 | D43: =+F43+H43 -> 299280 | E43: =C43-G43 -> 185489 | F43: =299280-113791 -> 185489 | G43: ='2024&2023'!D14 -> 113791 | H43: 113791 | I43: ='2024&2023'!E14 -> 436125 | J43: ='2024&2023'!F14 -> 221909 | K43: ='2024&2023'!G14 -> 152082 | L43: ='2024&2023'!H14 -> 383282 | M43: ='2024&2023'!I14 -> 476537 | N43: ='2024&2023'!J14 -> 491729 | O43: ='2024&2023'!K14 -> 393068 | P43: ='2024&2023'!L14 -> 452009
B44: ='2024&2023'!B32 -> Retirement Plan Expenses | C44: ='2024&2023'!C32 -> 23310 | D44: =+F44+H44 -> 23310 | E44: =C44-G44 -> 11098 | F44: =23310-12212 -> 11098 | G44: ='2024&2023'!D32 -> 12212 | H44: 12212 | I44: ='2024&2023'!E32 -> 53604 | J44: ='2024&2023'!F32 -> 25105 | K44: ='2024&2023'!G32 -> 25240 | L44: ='2024&2023'!H32 -> 53479 | M44: ='2024&2023'!I32 -> 52088 | N44: ='2024&2023'!J32 -> 49590 | O44: ='2024&2023'!K32 -> 39566 | P44: ='2024&2023'!L32 -> 36058
...

Sheet 2-T5Y IS (Cont.)
B2: Financial Information | C2: Highland Computer Forms, Inc.
B3: Date: 07/15/2026 | C3: Hillsboro, Ohio "S"-Corp
C4: Fiscal years ending December 31st
C6: Internal | D6: Adjusted RS | E6: Internal | F6: Adjusted RS | G6: Internal | H6: Adjusted -RS | I6: Review | J6: Internal | K6: Internal | L6: Review | M6: Review | N6: Review | O6: Review | P6: Review
B7: INCOME STATEMENT | C7: 6 mo.-'26 | D7: 6 mo.-'26 | E7: Q2-'26 | F7: 6 mo.-'26 | G7: Q1-'26 | H7: Q1-'26 | I7: FY2025 | J7: 6 mo.-'25 | K7: 6-mo.-'24 | L7: FY2024 | M7: FY2023 | N7: FY2022 | O7: FY2021 | P7: FY2020
B8: Gross Profit Margin $ | C8: ='1-T5Y IS'!C68 -> 1035885 | D8: ='1-T5Y IS'!D68 -> 1000606.4 | E8: ='1-T5Y IS'!E68 -> 377548.8 | F8: ='1-T5Y IS'!F68 -> 361280.3 | G8: ='1-T5Y IS'!G68 -> 658336.2 | H8: ='1-T5Y IS'!H68 -> 639326.09 | I8: ='1-T5Y IS'!I68 -> 1693360 | J8: ='1-T5Y IS'!J68 -> 861558 | ... P8: ='1-T5Y IS'!P68 -> 1013411.8
B9: Gross Profit Margin % (to Total Revenue) | C9: ='1-T5Y IS'!C69 -> 0.21690792 | D9: ='1-T5Y IS'!D69 -> 0.20952084 | E9: ='1-T5Y IS'!E69 -> 0.15957207 | F9: ='1-T5Y IS'!F69 -> 0.15269621 | G9: ='1-T5Y IS'!G69 -> 0.2732046 | H9: ='1-T5Y IS'!H69 -> 0.26531554 | I9: ='1-T5Y IS'!I69 -> 0.18802474 | J9: ='1-T5Y IS'!J69 -> 0.19237041 | ... P9: ='1-T5Y IS'!P69 -> 0.10330184
B10: S, G & A Expenses
B11: Selling Expenses
B12: Advertising | C12: ='2024&2023'!C76 -> 1531 | D12: =+F12+H12 -> 1531 | E12: =C12-G12 -> 1016 | F12: =1531-515 -> 1016 | G12: ='2024&2023'!D76 -> 515 | H12: 515 | I12: ='2024&2023'!E76 -> 7823 | J12: ='2024&2023'!F76 -> 3474 | K12: ='2024&2023'!G76 -> 8845 | L12: ='2024&2023'!H76 -> 10995 | M12: ='2024&2023'!I76 -> 12447 | N12: ='2024&2023'!J76 -> 25516 | O12: ='2024&2023'!K76 -> 0 | P12: ='2024&2023'!L76 -> 0
B13: ='2024&2023'!B67 -> Travel and Entertainment (HCF) | C13: ='2024&2023'!C67 -> 10973 | D13: =+F13+H13 -> 10973 | E13: =C13-G13 -> 5765 | F13: =6142+4831-5208 -> 5765 | G13: ='2024&2023'!D67 -> 5208 | H13: =4085+1123 -> 5208 | I13: ='2024&2023'!E67 -> 15274 | J13: ='2024&2023'!F67 -> 4516 | K13: ='2024&2023'!G67 -> 13063 | L13: ='2024&2023'!H67 -> 23822 | M13: ='2024&2023'!I67 -> 41639 | N13: ='2024&2023'!J67 -> 23791 | O13: ='2024&2023'!K67 -> 23622 | P13: ='2024&2023'!L67 -> 7286
B14: ='2024&2023'!B68 -> Travel and Entertainment (G. Fordyce) | C14: ='2024&2023'!C68 -> 0 | D14: =+F14+H14 -> 0 | E14: =C14-G14 -> 0 | G14: ='2024&2023'!D68 -> 0 | I14: ='2024&2023'!E68 -> 3679 | J14: ='2024&2023'!F68 -> 0 | K14: ='2024&2023'!G68 -> 0 | L14: ='2024&2023'!H68 -> 5497 | M14: ='2024&2023'!I68 -> 1611
B15: Salaries - Sales Service | C15: ='2024&2023'!C86 -> 148173 | D15: =+F15+H15 -> 0 | E15: =C15-G15 -> 74047 | G15: ='2024&2023'!D86 -> 74126 | I15: ='2024&2023'!E86 -> 0 | J15: ='2024&2023'!F86 -> 165564 | K15: ='2024&2023'!G86 -> 167528 | L15: 0 | M15: 0 | N15: 0 | O15: 0 | P15: 0
B16: Salaries - Outside Sales | C16: ='2024&2023'!C87 -> 62136 | D16: =+F16+H16 -> 0 | E16: =C16-G16 -> 31434 | G16: ='2024&2023'!D87 -> 30702 | I16: ='2024&2023'!E87 -> 0 | J16: ='2024&2023'!F87 -> 61884 | K16: ='2024&2023'!G87 -> 74441 | L16: 0 | M16: 0 | N16: 0 | O16: 0 | P16: 0 | S16: 1. Do not substract the other income, since this other income is rebates and scrap paper sales. It is indeed arguably a parrt of operational costs and income
B17: ='2024&2023'!B79 -> Selling Expenses | C17: ='2024&2023'!C79 -> 1534 | D17: =+F17+H17 -> 1534 | E17: =C17-G17 -> 982 | F17: =1534-552 -> 982 | G17: ='2024&2023'!D79 -> 552 | H17: 552 | I17: ='2024&2023'!E79 -> 505 | J17: ='2024&2023'!F79 -> 207 | K17: ='2024&2023'!G79 -> 1734 | L17: ='2024&2023'!H79 -> 1753 | M17: ='2024&2023'!I79 -> 10325 | N17: ='2024&2023'!J79 -> 571 | O17: ='2024&2023'!K79 -> 129 | P17: ='2024&2023'!L79 -> 0 | S17: 2. Make sure to correct the depreciation amount.
B18: ='2024&2023'!B84 -> Dues and Subscriptions (HCF) | C18: ='2024&2023'!C84 -> 0 | D18: =+F18+H18 -> 0 | E18: =C18-G18 -> 0 | G18: ='2024&2023'!D84 -> 0 | I18: ='2024&2023'!E84 -> 6 | J18: ='2024&2023'!F84 -> 8 | K18: ='2024&2023'!G84 -> 99 | L18: ='2024&2023'!H84 -> 99 | M18: ='2024&2023'!I84 -> 99 | N18: ='2024&2023'!J84 -> 298 | O18: ='2024&2023'!K84 -> 299 | P18: ='2024&2023'!L84 -> 95 | S18: 3. Make sure to itemize and bake in the G. Fordyce amounts into the financials to match the Reviews
B19: ='2024&2023'!B85 -> Dues and Subscriptions (G. Fordyce) | C19: ='2024&2023'!C85 -> 0 | D19: =+F19+H19 -> 0 | E19: =C19-G19 -> 0 | G19: ='2024&2023'!D85 -> 0 | I19: ='2024&2023'!E85 -> 171 | J19: ='2024&2023'!F85 -> 0 | K19: ='2024&2023'!G85 -> 0 | L19: ='2024&2023'!H85 -> 166 | M19: ='2024&2023'!I85 -> 160
B20: Sub-total Selling Expenses | C20: =SUM(C12:C19) -> 224347 | D20: =SUM(D12:D19) -> 14038 | E20: =SUM(E12:E19) -> 113244 | F20: =SUM(F12:F19) -> 7763 | G20: =SUM(G12:G19) -> 111103 | H20: =SUM(H12:H19) -> 6275 | I20: =SUM(I12:I19) -> 27458 | J20: =SUM(J12:J18) -> 235653 | K20: =SUM(K12:K18) -> 265710 | L20: =SUM(L12:L19) -> 42332 | M20: =SUM(M12:M19) -> 66281 | N20: =SUM(N12:N18) -> 50176 | O20: =SUM(O12:O18) -> 24050 | P20: =SUM(P12:P18) -> 7381 | S20: 4. Make sure to talk about thse self-funded insurance plan.
B22: General & Administrative
B23: ='2024&2023'!B54 -> Office Salaries | C23: ='2024&2023'!C54 -> 0 | D23: =+F23+H23 -> 210305 | E23: =C23-G23 -> 0 | F23: =148173+62136-104827-4 -> 105478 | G23: ='2024&2023'!D54 -> 0 | H23: =74126+30702-1 -> 104827 | I23: ='2024&2023'!E54-244188 -> 438733 | J23: ='2024&2023'!F54 -> 0 | K23: ='2024&2023'!G54 -> 0 | L23: ='2024&2023'!H54-102120 -> 473197 | M23: ='2024&2023'!I54-55340 -> 579472 | N23: ='2024&2023'!J54 -> 775051 | O23: ='2024&2023'!K54 -> 683480 | P23: ='2024&2023'!L54 -> 535262 | Q23: *** pulled out bonus amount fr 25 and 24 and 23
B24: ='2024&2023'!B56 -> Administrative Salaries | C24: ='2024&2023'!C56 -> 65997 | D24: =+F24+H24 -> 65997 | E24: =C24-G24 -> 33478 | F24: =65997-32519 -> 33478 | G24: ='2024&2023'!D56 -> 32519 | H24: 32519 | I24: ='2024&2023'!E56 -> 129211 | J24: ='2024&2023'!F56 -> 63483 | K24: ='2024&2023'!G56 -> 63975 | L24: ='2024&2023'!H56 -> 128935 | M24: ='2024&2023'!I56 -> 127950 | N24: ='2024&2023'!J56 -> 119896 | O24: ='2024&2023'!K56 -> 115656 | P24: ='2024&2023'!L56 -> 119624
B25: Employee Bonus | C25: ='2024&2023'!C73 -> 38088 | D25: =+F25+H25 -> 38088 | E25: =C25-G25 -> 3968 | F25: =38088-H25 -> 3968 | G25: ='2024&2023'!D73 -> 34120 | H25: 34120 | I25: 244188 | J25: ='2024&2023'!F73 -> 59055 | K25: ='2024&2023'!G73 -> 73000 | L25: 102120 | M25: 55340 | N25: 0 | O25: 0 | P25: 0 | Q25: reclassified from office salaries
B26: ='2024&2023'!B63 -> Payroll Taxes | C26: ='2024&2023'!C63 -> 19095 | D26: =+F26+H26 -> 19095 | E26: =C26-G26 -> 8565 | F26: =19095-10530 -> 8565 | G26: ='2024&2023'!D63 -> 10530 | H26: 10530 | I26: ='2024&2023'!E63 -> 41164 | J26: ='2024&2023'!F63 -> 21560 | K26: ='2024&2023'!G63 -> 22732 | L26: ='2024&2023'!H63 -> 43462 | M26: ='2024&2023'!I63 -> 54543 | N26: ='2024&2023'!J63 -> 51840 | O26: ='2024&2023'!K63 -> 48608 | P26: ='2024&2023'!L63 -> 46821
B27: ='2024&2023'!B70 -> Retirement Plan Expenses | C27: ='2024&2023'!C70 -> 10982 | D27: =+F27+H27 -> 10982 | E27: =C27-G27 -> 5091 | F27: =10982-5891 -> 5091 | G27: ='2024&2023'!D70 -> 5891 | H27: 5891 | I27: ='2024&2023'!E70 -> 21536 | J27: ='2024&2023'!F70 -> 11009 | K27: ='2024&2023'!G70 -> 11290 | L27: ='2024&2023'!H70 -> 22199 | M27: ='2024&2023'!I70 -> 23682 | N27: ='2024&2023'!J70 -> 23252 | O27: ='2024&2023'!K70 -> 21563 | P27: ='2024&2023'!L70 -> 19755
B28: Lease (20% of Total - HCF) | C28: =('2024&2023'!C24*0.2)+'2024&2023'!C88 -> 12600 | D28: =+F28+H28 -> 0 | E28: =C28-G28 -> 6300 | G28: =('2024&2023'!D24*0.2)+'2024&2023'!D88 -> 6300 | I28: =('2024&2023'!E24*0.2)+'2024&2023'!E88 -> 24935.4 | J28: =('2024&2023'!F24*0.2)+'2024&2023'!F88 -> 11278 | K28: =('2024&2023'!G24*0.2)+'2024&2023'!G88 -> 31313 | L28: ='2024&2023'!H24*0.2 -> 31395 | M28: ='2024&2023'!I24*0.2 -> 30169.2 | N28: ='2024&2023'!J24*0.2 -> 30251.4 | O28: ='2024&2023'!K24*0.2 -> 29445.8 | P28: ='2024&2023'!L24*0.2 -> 28436
B29: Lease (20% of Total - G. Fordyce) | D29: =+F29+H29 -> 0 | E29: =C29-G29 -> 0 | I29: ='2024&2023'!E25*0.2 -> 1920 | L29: ='2024&2023'!H25*0.2 -> 1920 | M29: ='2024&2023'!I25*0.2 -> 1920
B30: Utilities (20% of Total) | C30: ='2024&2023'!C21*0.2 -> 31421 | D30: =+F30+H30 -> 0 | E30: =C30-G30 -> 15263.8 | G30: ='2024&2023'!D21*0.2 -> 16157.2 | I30: ='2024&2023'!E21*0.2 -> 57973.6 | J30: ='2024&2023'!F21*0.2 -> 26652 | K30: ='2024&2023'!G21*0.2 -> 21759.6 | L30: ='2024&2023'!H21*0.2 -> 47776.4 | M30: ='2024&2023'!I21*0.2 -> 51618.2 | N30: ='2024&2023'!J21*0.2 -> 52677.6 | O30: ='2024&2023'!K21*0.2 -> 50665.4 | P30: ='2024&2023'!L21*0.2 -> 48759.8
B31: ='2024&2023'!B55 -> Insurance | C31: ='2024&2023'!C55+'2024&2023'!C45 -> 98449 | D31: =+F31+H31 -> 98449 | E31: =C31-G31 -> 56031 | F31: =61880+6163+30406-42418 -> 56031 | G31: ='2024&2023'!D55+'2024&2023'!D45 -> 42418 | H31: =24134+3081+15203 -> 42418 | I31: ='2024&2023'!E55+'2024&2023'!E45 -> 160790 | J31: ='2024&2023'!F55+'2024&2023'!F45 -> 85102 | K31: ='2024&2023'!G55+'2024&2023'!G45 -> 54904 | L31: ='2024&2023'!H55 -> 146115 | M31: ='2024&2023'!I55 -> 147445 | N31: ='2024&2023'!J55 -> 144638 | O31: ='2024&2023'!K55 -> 102067 | P31: ='2024&2023'!L55 -> 128258
B32: ='2024&2023'!B57 -> Professional Fees | C32: ='2024&2023'!C57 -> 55949 | D32: =+F32+H32 -> 55949 | E32: =C32-G32 -> 15544 | F32: =55949-40405 -> 15544 | G32: ='2024&2023'!D57 -> 40405 | H32: 40405 | I32: ='2024&2023'!E57 -> 85592 | J32: ='2024&2023'!F57 -> 52728 | K32: ='2024&2023'!G57 -> 67530 | L32: ='2024&2023'!H57 -> 90099 | M32: ='2024&2023'!I57 -> 112984 | N32: ='2024&2023'!J57 -> 120304 | O32: ='2024&2023'!K57 -> 196583 | P32: ='2024&2023'!L57 -> 107547
B33: ='2024&2023'!B58 -> Depreciation (HCF) | C33: ='2024&2023'!C58 -> 31793 | D33: =+F33+H33 -> 31793 | E33: =C33-G33 -> 15897 | F33: =3752+21792+6249-15896 -> 15897 | G33: ='2024&2023'!D58 -> 15896 | H33: =1876+10896+3124 -> 15896 | I33: ='2024&2023'!E58 -> 63962 | J33: ='2024&2023'!F58 -> 35231 | K33: ='2024&2023'!G58 -> 30799 | L33: ='2024&2023'!H58 -> 66605 | M33: ='2024&2023'!I58 -> 57511 | N33: ='2024&2023'!J58 -> 59433 | O33: ='2024&2023'!K58 -> 59486 | P33: ='2024&2023'!L58 -> 59449
B34: ='2024&2023'!B59 -> Depreciation (G. Fordyce) | D34: =+F34+H34 -> 0 | E34: =C34-G34 -> 0 | I34: ='2024&2023'!E59 -> 6505 | L34: ='2024&2023'!H59 -> 6505 | M34: ='2024&2023'!I59 -> 7913
B35: ='2024&2023'!B60 -> Bad Debt Expense | C35: ='2024&2023'!C60 -> 0 | D35: =+F35+H35 -> 0 | E35: =C35-G35 -> 0 | G35: ='2024&2023'!D60 -> 0 | I35: ='2024&2023'!E60 -> 6597 | J35: ='2024&2023'!F60 -> 2198 | K35: ='2024&2023'!G60 -> 1493 | L35: ='2024&2023'!H60 -> 50879 | M35: ='2024&2023'!I60 -> 1704 | N35: ='2024&2023'!J60 -> 57 | O35: ='2024&2023'!K60 -> 5840 | P35: ='2024&2023'!L60 -> 2810
B36: ='2024&2023'!B61 -> General Taxes | C36: ='2024&2023'!C61 -> 24950 | D36: =+F36+H36 -> 24950 | E36: =C36-G36 -> 12692 | F36: =24950-12258 -> 12692 | G36: ='2024&2023'!D61 -> 12258 | H36: 12258 | I36: ='2024&2023'!E61 -> 54835 | J36: ='2024&2023'!F61 -> 29289 | K36: ='2024&2023'!G61 -> 23864 | L36: ='2024&2023'!H61 -> 46939 | M36: ='2024&2023'!I61 -> 57431 | N36: ='2024&2023'!J61 -> 96595 | O36: ='2024&2023'!K61 -> 44146 | P36: ='2024&2023'!L61 -> 49266
B37: ='2024&2023'!B62 -> Caretaking Expenses | C37: ='2024&2023'!C62 -> 15908 | D37: =+F37+H37 -> 24654 | E37: =C37-G37 -> 7950 | F37: =8746+15908-11405 -> 13249 | G37: ='2024&2023'!D62 -> 7958 | H37: =3447+7958 -> 11405 | I37: ='2024&2023'!E62 -> 53893 | J37: ='2024&2023'!F62 -> 18911 | K37: ='2024&2023'!G62 -> 8927 | L37: ='2024&2023'!H62 -> 46071 | M37: ='2024&2023'!I62 -> 63705 | N37: ='2024&2023'!J62 -> 76067 | O37: ='2024&2023'!K62 -> 59648 | P37: ='2024&2023'!L62 -> 54602
B38: ='2024&2023'!B64 -> Bank and Payroll Service Charges (HCF) | C38: ='2024&2023'!C64 -> 25874 | D38: =+F38+H38 -> 25874 | E38: =C38-G38 -> 12309 | F38: =17884+7990-13566 -> 12308 | G38: ='2024&2023'!D64 -> 13565 | H38: =9018+4548 -> 13566 | I38: ='2024&2023'!E64 -> 43303 | J38: ='2024&2023'!F64 -> 20966 | K38: ='2024&2023'!G64 -> 22813 | L38: ='2024&2023'!H64 -> 42997 | M38: ='2024&2023'!I64 -> 39709 | N38: ='2024&2023'!J64 -> 76511 | O38: ='2024&2023'!K64 -> 99314 | P38: ='2024&2023'!L64 -> 109300
B39: ='2024&2023'!B65 -> Bank and Payroll Service Charges (G. Fordyce) | C39: ='2024&2023'!C65 -> 0 | D39: =+F39+H39 -> 0 | E39: =C39-G39 -> 0 | G39: ='2024&2023'!D65 -> 0 | I39: ='2024&2023'!E65 -> 156 | J39: ='2024&2023'!F65 -> 0 | K39: ='2024&2023'!G65 -> 0 | L39: ='2024&2023'!H65 -> 36 | M39: ='2024&2023'!I65 -> 164
B40: ='2024&2023'!B66 -> Office Repairs and Maintenance | C40: ='2024&2023'!C66 -> 13222 | D40: =+F40+H40 -> 13222 | E40: =C40-G40 -> 6611 | F40: =13222-6611 -> 6611 | G40: ='2024&2023'!D66 -> 6611 | H40: 6611 | I40: ='2024&2023'!E66 -> 29691 | J40: ='2024&2023'!F66 -> 12994 | K40: ='2024&2023'!G66 -> 17626 | L40: ='2024&2023'!H66 -> 42669 | M40: ='2024&2023'!I66 -> 23969 | N40: ='2024&2023'!J66 -> 24119 | O40: ='2024&2023'!K66 -> 25649 | P40: ='2024&2023'!L66 -> 24175
B41: ='2024&2023'!B69 -> Telephone and Internet | C41: ='2024&2023'!C69 -> 14143 | D41: =+F41+H41 -> 14143 | E41: =C41-G41 -> 6655 | F41: =4305+9838-7488 -> 6655 | G41: ='2024&2023'!D69 -> 7488 | H41: =2173+5315 -> 7488 | I41: ='2024&2023'!E69 -> 24328 | J41: ='2024&2023'!F69 -> 13541 | K41: ='2024&2023'!G69 -> 15458 | L41: ='2024&2023'!H69 -> 28373 | M41: ='2024&2023'!I69 -> 32412 | N41: ='2024&2023'!J69 -> 33368 | O41: ='2024&2023'!K69 -> 38805 | P41: ='2024&2023'!L69 -> 36491
B42: Office Supplies (HCF) | C42: ='2024&2023'!C71 -> 7095 | D42: =+F42+H42 -> 7095 | E42: =C42-G42 -> 2969 | F42: =7095-4126 -> 2969 | G42: ='2024&2023'!D71 -> 4126 | H42: 4126 | I42: ='2024&2023'!E71 -> 21002 | J42: ='2024&2023'!F71 -> 9564 | K42: ='2024&2023'!G71 -> 11638 | L42: ='2024&2023'!H71 -> 20600 | M42: ='2024&2023'!I71 -> 32828 | N42: ='2024&2023'!J71 -> 33223 | O42: ='2024&2023'!K71 -> 26639 | P42: ='2024&2023'!L71 -> 26432
B43: ='2024&2023'!B72 -> Office Supplies (G. Fordyce) | C43: ='2024&2023'!C72 -> 0 | D43: =+F43+H43 -> 0 | E43: =C43-G43 -> 0 | G43: ='2024&2023'!D72 -> 0 | I43: ='2024&2023'!E72 -> 1339 | J43: ='2024&2023'!F72 -> 0 | K43: ='2024&2023'!G72 -> 0 | L43: ='2024&2023'!H72 -> 1093 | M43: ='2024&2023'!I72 -> 1158
...

Sheet 3-Balance Sheet
B2: Financial Information | C2: Highland Computer Forms, Inc.
B3: Date: 07/15/2026 | C3: Hillsboro, Ohio "S"-Corp
C4: Fiscal years ending December 31st
C6: Internal | D6: Internal | E6: Review | F6: Internal | G6: Review | H6: Internal | I6: Review | J6: Review | K6: Review | L6: Review
B7: BALANCE SHEET | C7: Q2-'26 | D7: Q1-'26 | E7: FY2025 | F7: Q2-'25 | G7: FY2024 | H7: Q2-'24 | I7: FY2023 | J7: FY2022 | K7: FY2021 | L7: FY2020
B8: Current Assets
B9: Cash and Cash Equivalents (HCF) | C9: =739924 -> 739924 | D9: 543005 | E9: 254337 | F9: 739103 | G9: 286933 | H9: 641003 | I9: 519446 | J9: 113938 | K9: 49473 | L9: 175518
B10: Cash and Cash Equivalents (G. Fordyce) | E10: 71723 | G10: 21799 | I10: 87219
B11: Certificates of Deposit | D11: 0 | E11: 312916 | F11: 0 | G11: 300000 | H11: 0 | I11: 0 | J11: 0 | K11: 0 | L11: 0
B12: A/R, Trade
B13: A/R, Trade (HCF) | C13: 779487 | D13: 1010922 | E13: 674696 | F13: 624234 | G13: 600833 | H13: =739879 -> 739879 | I13: 825739 | J13: 1162502 | K13: 1033535 | L13: 838596
B14: A/R, Trade (G. Fordyce) | E14: 14174 | G14: 15236 | I14: 101789
B15: (Less Eliminating Entry) | C15: 0 | D15: 0 | E15: 0 | F15: 0 | G15: -7603 | H15: 0 | I15: -9935 | J15: 13420 | K15: 21353 | L15: =11296+6000 -> 17296
B16: Sub-Total A/P, Trade | C16: =SUM(C13:C15) -> 779487 | D16: =SUM(D13:D15) -> 1010922 | E16: =SUM(E13:E15) -> 688870 | F16: =SUM(F13:F15) -> 624234 | G16: =SUM(G13:G15) -> 608466 | H16: =SUM(H13:H15) -> 739879 | I16: =SUM(I13:I15) -> 917593
B17: A/R, Other
B18: A/R, Other (HCF) | C18: 15 | D18: 44939 | E18: 40085 | F18: 8401 | G18: 8193 | H18: =6459 -> 6459 | I18: 90154
B19: A/R, Other (G. Fordyce) | E19: 0 | G19: 0 | I19: 0
B20: (Less Eliminating Entry) | C20: 0 | D20: 0 | E20: -9206 | F20: 0 | G20: 0 | H20: 0 | I20: 0
B21: Sub-Total A/P, Other | C21: =SUM(C18:C20) -> 15 | D21: =SUM(D18:D20) -> 44939 | E21: =SUM(E18:E20) -> 30879 | F21: =SUM(F18:F20) -> 8401 | G21: =SUM(G18:G20) -> 8193 | H21: =SUM(H18:H20) -> 6459 | I21: =SUM(I18:I20) -> 90154
B22: Inventories (HCF) | C22: 1098507 | D22: 1202624 | E22: 1239901 | F22: 1050542 | G22: 1021535 | H22: =909413 -> 909413 | I22: 1051427 | J22: 1733922 | K22: 1107863 | L22: 632835
B23: Inventories (G. Fordyce) | C23: 0 | D23: 0 | E23: 0 | F23: 0 | G23: 0 | H23: 0 | I23: 45134
B24: Employee Retention Credits Receivable | D24: 0 | E24: 0 | F24: 0 | G24: 0 | H24: 0 | I24: 0 | J24: 1352277 | K24: 1352277 | L24: 0
B25: Prepaid Expenses | C25: 33215 | D25: 18804 | E25: 12631 | F25: 14221 | G25: 5961 | H25: =17236 -> 17236 | I25: 11844 | J25: 5804 | K25: 4863 | L25: 4523
B26: Total Current Assets | C26: =SUM(C9:C11,C16,C21,C22,C25) -> 2651148 | D26: =SUM(D9:D11,D16,D21,D22,D25) -> 2820294 | E26: =SUM(E9:E11,E16,E21,E22,E25) -> 2611257 | F26: =SUM(F9:F11,F16,F21,F22,F25) -> 2436501 | G26: =SUM(G9:G11,G16,G21,G22,G25) -> 2252887 | H26: =SUM(H9:H11,H16,H21,H22,H25) -> 2313990 | I26: =SUM(I9:I11,I16,I21,I22,I25,I23) -> 2722817 | J26: =SUM(J9:J25) -> 4381863 | K26: =SUM(K9:K25) -> 3569364 | L26: =SUM(L9:L25) -> 1668768
B28: Property, Plant and Equipment
B29: Land | C29: 600000 | D29: 600000 | E29: 100000 | F29: 600000 | G29: 100000 | H29: 600000 | I29: 100000 | J29: 100000 | K29: 100000 | L29: 100000
B30: Buildings | E30: 500000 | G30: 500000 | I30: 500000 | J30: 500000 | K30: 500000 | L30: 500000
B31: Leasehold Improvements (HCF) | C31: 1078355 | D31: 1078355 | E31: 1078356 | F31: 1078355 | G31: 1078356 | H31: 1056776 | I31: 1027967 | J31: 1001669 | K31: 1001669 | L31: 1001669
B32: Leasehold Improvements (G. Fordyce) | E32: 65050 | F32: 0 | G32: 65050 | H32: 0 | I32: 65050
B33: Machinery and Equipment | C33: 6811540 | D33: 6811540 | E33: 6801540 | F33: =6777168+188705 -> 6965873 | G33: 6759705 | H33: =6713457+199516 -> 6912973 | I33: 6717643 | J33: 6638006 | K33: 6638006 | L33: 6483888
B34: Vehicles | C34: 149312 | D34: 149312 | E34: 149313 | F34: 149312 | G34: 149313 | H34: 149312 | I34: 149313 | J34: 149313 | K34: 127387 | L34: 324668
B35: Furniture, Fixtures & Office Equip. | C35: =42406+188705 -> 231111 | D35: =42406+188705 -> 231111 | E35: 231112 | F35: 42406 | G35: 231112 | H35: =42406 -> 42406 | I35: 209970 | J35: 209970 | K35: 209970 | L35: 200911
B36: Total Fixed Assets at Cost | C36: =SUM(C29:C35) -> 8870318 | D36: =SUM(D29:D35) -> 8870318 | E36: =SUM(E29:E35) -> 8925371 | F36: =SUM(F29:F35) -> 8835946 | G36: =SUM(G29:G35) -> 8883536 | H36: =SUM(H29:H35) -> 8761467 | I36: =SUM(I29:I35) -> 8769943 | J36: =SUM(J29:J35) -> 8598958 | ... L36: =SUM(L29:L35) -> 8611136
B37: (Less Accumulated Depreciation) | C37: -7467180 | D37: =-7413885 -> -7413885 | E37: =-7339665-20923 -> -7360588 | F37: =-7241132 -> -7241132 | G37: =-7110597-14418 -> -7125015 | H37: =-7007577 -> -7007577 | I37: =-6889114-7913 -> -6897027 | J37: -6639871 | K37: -6381778 | L37: -6310027
B38: Total Net Fixed Assets | C38: =SUM(C36:C37) -> 1403138 | D38: =SUM(D36:D37) -> 1456433 | E38: =SUM(E36:E37) -> 1564783 | F38: =SUM(F36:F37) -> 1594814 | G38: =SUM(G36:G37) -> 1758521 | H38: =SUM(H36:H37) -> 1753890 | I38: =SUM(I36:I37) -> 1872916 | J38: =SUM(J36:J37) -> 1959087 | ... L38: =SUM(L36:L37) -> 2301109
B40: Other Assets
B41: Right-of-use assets, operating | D41: 0 | E41: 0 | F41: 0 | G41: 0 | H41: 0 | I41: 7572 | J41: 22269 | K41: 0 | L41: 0
B42: Cash Value of Life Insurance | D42: 0 | E42: 0 | F42: 0 | G42: 0 | H42: 0 | I42: 0 | J42: 176655 | K42: 168892 | L42: 160874
B43: Deferred Financing Fees, net | D43: 0 | E43: 0 | F43: 0 | G43: 0 | H43: 0 | I43: 0 | J43: 0 | K43: 20806 | L43: 41613
B44: Goodwill | C44: 10000 | D44: 10000 | E44: 10000 | F44: 10000 | G44: 10000 | H44: 10000 | I44: 10000 | J44: 10000 | K44: 10000 | L44: 10000
...

Sheet 4-EBITDA
B2: Financial Information | C2: Highland Computer Forms, Inc.
B3: Date: 07/15/2026 | C3: Hillsboro, Ohio "S"-Corp
C4: Fiscal years ending December 31st
C6: Extrapolation④ | D6: Internal | E6: Internal | F6: Internal | G6: Review | H6: Internal | I6: Internal | J6: Review | K6: Review | L6: Review | M6: Review | N6: Review
B7: "Adjusted" EBITDA CALCULATION | C7: FY2026 | D7: 6 mo.-'26 | E7: Q2-'26 | F7: Q1-'26 | G7: FY2025 | H7: 6 mo.-'25 | I7: 6mo.-'24 | J7: FY2024 | K7: FY2023 | L7: FY2022 | M7: FY2021 | N7: FY2020
B8: Net Revenue | C8: =D8*2 -> 9551380 | D8: ='1-T5Y IS'!C12 -> 4775690 | E8: =D8-F8 -> 2366008 | F8: ='1-T5Y IS'!G12 -> 2409682 | G8: ='1-T5Y IS'!I12 -> 9006049 | H8: ='1-T5Y IS'!J12 -> 4478641 | I8: ='1-T5Y IS'!K12 -> 4537159 | J8: ='1-T5Y IS'!L12 -> 9351166 | K8: ='1-T5Y IS'!M12 -> 11127105 | L8: ='1-T5Y IS'!N12 -> 11681336 | M8: ='1-T5Y IS'!O12 -> 10246051 | N8: ='1-T5Y IS'!P12 -> 9810201
B9: Gross Margin $ | C9: =D9*2 -> 2071770 | D9: ='1-T5Y IS'!C68 -> 1035885 | E9: =D9-F9 -> 377548.8 | F9: ='1-T5Y IS'!G68 -> 658336.2 | G9: ='1-T5Y IS'!I68 -> 1693360 | H9: ='1-T5Y IS'!J68 -> 861558 | I9: ='1-T5Y IS'!K68 -> 699544.6 | J9: ='1-T5Y IS'!L68 -> 1369004.4 | K9: ='1-T5Y IS'!M68 -> 1716019.4 | L9: ='1-T5Y IS'!N68 -> 1934944 | M9: ='1-T5Y IS'!O68 -> 1429017.2 | N9: ='1-T5Y IS'!P68 -> 1013411.8
B10: Gross Margin % | C10: =C9/C8 -> 0.21690792 | D10: ='1-T5Y IS'!C69 -> 0.21690792 | E10: =E9/E8 -> 0.15957207 | F10: ='1-T5Y IS'!G69 -> 0.2732046 | G10: ='1-T5Y IS'!I69 -> 0.18802474 | H10: ='1-T5Y IS'!J69 -> 0.19237041 | I10: ='1-T5Y IS'!K69 -> 0.1541812 | J10: ='1-T5Y IS'!L69 -> 0.14639933 | K10: ='1-T5Y IS'!M69 -> 0.15421975 | L10: ='1-T5Y IS'!N69 -> 0.16564407 | M10: ='1-T5Y IS'!O69 -> 0.13947005 | N10: ='1-T5Y IS'!P69 -> 0.10330184
B11: Net Income (Loss) | C11: =D11*2 -> 935656 | D11: ='2-T5Y IS (Cont.)'!C70 -> 467828 | E11: =D11-F11 -> 192988 | F11: ='2-T5Y IS (Cont.)'!G70 -> 274840 | G11: ='2-T5Y IS (Cont.)'!I70 -> 122299 | H11: ='2-T5Y IS (Cont.)'!J70 -> 138098 | I11: ='2-T5Y IS (Cont.)'!K70 -> -62638 | J11: ='2-T5Y IS (Cont.)'!L70 -> -149387 | K11: ='2-T5Y IS (Cont.)'!M70 -> 99772 | L11: ='2-T5Y IS (Cont.)'!N70 -> 1214423 | M11: ='2-T5Y IS (Cont.)'!O70 -> 2288208 | N11: ='2-T5Y IS (Cont.)'!P70 -> 84468
B13: Add back Interest Expense | C13: =D13*2 -> 3570 | D13: =-'2-T5Y IS (Cont.)'!C61 -> 1785 | E13: =D13-F13 -> -5287 | F13: =-'2-T5Y IS (Cont.)'!G61 -> 7072 | G13: =-'2-T5Y IS (Cont.)'!I61 -> 15331 | H13: =-'2-T5Y IS (Cont.)'!J61 -> 9887 | I13: =-'2-T5Y IS (Cont.)'!K61 -> 9669 | J13: =-'2-T5Y IS (Cont.)'!L61 -> 19142 | K13: =-'2-T5Y IS (Cont.)'!M61 -> 22060 | L13: =-'2-T5Y IS (Cont.)'!N61 -> 121245 | M13: =-'2-T5Y IS (Cont.)'!O61 -> 88472 | N13: =-'2-T5Y IS (Cont.)'!P61 -> 137472
B14: Add back Income Taxes | E14: =D14-F14 -> 0 | J14: 0 | K14: 0 | L14: 1 | M14: 2 | N14: 3
B15: Add back Depreciation | C15: =D15*2 -> 213176 | D15: ='2-T5Y IS (Cont.)'!C33+'1-T5Y IS'!C54 -> 106588 | E15: =D15-F15 -> 53295 | F15: ='2-T5Y IS (Cont.)'!G33+'1-T5Y IS'!G54 -> 53293 | G15: ='2-T5Y IS (Cont.)'!I33+'1-T5Y IS'!I54+'2-T5Y IS (Cont.)'!I34 -> 235573 | H15: ='2-T5Y IS (Cont.)'!J33+'1-T5Y IS'!J54+'2-T5Y IS (Cont.)'!J34 -> 116113 | I15: ='2-T5Y IS (Cont.)'!K33+'1-T5Y IS'!K54+'2-T5Y IS (Cont.)'!K34 -> 115715 | J15: ='2-T5Y IS (Cont.)'!L33+'1-T5Y IS'!L54+'2-T5Y IS (Cont.)'!L34 -> 243966 | K15: ='2-T5Y IS (Cont.)'!M33+'1-T5Y IS'!M54+'2-T5Y IS (Cont.)'!M34 -> 254968 | L15: ='2-T5Y IS (Cont.)'!N33 -> 59433 | M15: ='2-T5Y IS (Cont.)'!O33 -> 59486 | N15: ='2-T5Y IS (Cont.)'!P33 -> 59449
B16: Less Depreciation of Building | C16: 0 | D16: 0 | E16: =D16-F16 -> 0 | F16: 0 | G16: 0 | H16: 0 | I16: 0 | J16: 0 | K16: 0 | L16: 0 | M16: 0 | N16: 0
B17: Estimated Fair Market Rent | C17: 0 | D17: 0 | E17: =D17-F17 -> 0 | F17: 0 | G17: 0 | H17: 0 | I17: 0 | J17: 0 | K17: 0 | L17: 0 | M17: 0 | N17: 0
B18: Add back Bank Charges② | C18: =D18*2 -> 35768 | D18: ='2024&2023'!C119 -> 17884 | E18: =D18-F18 -> 8866 | F18: ='2024&2023'!D119 -> 9018 | G18: ='2024&2023'!E119 -> 0 | H18: ='2024&2023'!F119 -> 13390 | I18: ='2024&2023'!G119 -> 15941 | J18: 0 | K18: 0 | L18: 0 | M18: 0 | N18: 0
B19: Add back Bad Debt③ | C19: 0 | D19: =-'2-T5Y IS (Cont.)'!C63 -> 0 | E19: =D19-F19 -> 0 | F19: =-'2-T5Y IS (Cont.)'!G63 -> 0 | G19: =-'2-T5Y IS (Cont.)'!I63 -> 0 | H19: =-'2-T5Y IS (Cont.)'!J63 -> -576 | I19: =-'2-T5Y IS (Cont.)'!K63 -> 0 | J19: 45648 | K19: 0 | L19: 0 | M19: 0 | N19: 0
B20: Deduct Gain on Sale of Assets | C20: 0 | D20: =-'2-T5Y IS (Cont.)'!C62 -> 0 | E20: =D20-F20 -> 0 | F20: =-'2-T5Y IS (Cont.)'!G62 -> 0 | G20: =-'2-T5Y IS (Cont.)'!I62 -> 0 | H20: =-'2-T5Y IS (Cont.)'!J62 -> 0 | I20: =-'2-T5Y IS (Cont.)'!K62 -> -2666 | J20: =-'2-T5Y IS (Cont.)'!L62 -> -2667 | K20: =-'2-T5Y IS (Cont.)'!M62 -> 0 | L20: =-'2-T5Y IS (Cont.)'!N62 -> 0 | M20: =-'2-T5Y IS (Cont.)'!O62 -> -1500 | N20: =-'2-T5Y IS (Cont.)'!P62 -> 0
B21: Deduct ERC Funds | D21: =-'2-T5Y IS (Cont.)'!C65 -> 0 | E21: =D21-F21 -> 0 | F21: =-'2-T5Y IS (Cont.)'!G65 -> 0 | G21: =-'2-T5Y IS (Cont.)'!I65 -> 0 | H21: =-'2-T5Y IS (Cont.)'!J65 -> 0 | I21: =-'2-T5Y IS (Cont.)'!K65 -> 0 | J21: =-'2-T5Y IS (Cont.)'!L65 -> 0 | K21: =-'2-T5Y IS (Cont.)'!M65 -> 0 | L21: =-'2-T5Y IS (Cont.)'!N65 -> 0 | M21: =-'2-T5Y IS (Cont.)'!O65 -> -1352277 | N21: =-'2-T5Y IS (Cont.)'!P65 -> 0
B22: Deduct PPP Loan Funds | D22: =-'2-T5Y IS (Cont.)'!C67 -> 0 | E22: =D22-F22 -> 0 | F22: =-'2-T5Y IS (Cont.)'!G67 -> 0 | G22: =-'2-T5Y IS (Cont.)'!I67 -> 0 | H22: =-'2-T5Y IS (Cont.)'!J67 -> 0 | I22: =-'2-T5Y IS (Cont.)'!K67 -> 0 | J22: =-'2-T5Y IS (Cont.)'!L67 -> 0 | K22: =-'2-T5Y IS (Cont.)'!M67 -> 0 | L22: =-'2-T5Y IS (Cont.)'!N67 -> -688137 | M22: =-'2-T5Y IS (Cont.)'!O67 -> -862310 | N22: =-'2-T5Y IS (Cont.)'!P67 -> 0
B23: Deduct Purchase Discounts | D23: =-'2-T5Y IS (Cont.)'!C60 -> 0 | E23: =D23-F23 -> 0 | F23: =-'2-T5Y IS (Cont.)'!G60 -> 0 | G23: =-'2-T5Y IS (Cont.)'!I60 -> 0 | H23: =-'2-T5Y IS (Cont.)'!J60 -> 0 | I23: =-'2-T5Y IS (Cont.)'!K60 -> 0 | J23: =-'2-T5Y IS (Cont.)'!L60 -> 0 | K23: =-'2-T5Y IS (Cont.)'!M60 -> 0 | L23: =-'2-T5Y IS (Cont.)'!N60 -> -108616 | M23: =-'2-T5Y IS (Cont.)'!O60 -> -100887 | N23: =-'2-T5Y IS (Cont.)'!P60 -> -49024
B24: Deduct Other Income④ | D24: =-'2-T5Y IS (Cont.)'!C59 -> 0 | E24: =D24-F24 -> 0 | F24: =-'2-T5Y IS (Cont.)'!G59 -> 0 | G24: =-'2-T5Y IS (Cont.)'!I59 -> 0 | H24: =-'2-T5Y IS (Cont.)'!J59 -> 0 | I24: =-'2-T5Y IS (Cont.)'!K59 -> 0 | J24: =-'2-T5Y IS (Cont.)'!L59 -> 0 | K24: =-'2-T5Y IS (Cont.)'!M59 -> 0 | L24: =-'2-T5Y IS (Cont.)'!N59 -> -388325 | M24: =-'2-T5Y IS (Cont.)'!O59 -> -279481 | N24: =-'2-T5Y IS (Cont.)'!P59 -> -591937
B25: Deduct Debt Forgiveness | C25: =D25 -> -133786 | D25: =-'2-T5Y IS (Cont.)'!C66 -> -133786 | E25: =D25-F25 -> -133786 | F25: =-'2-T5Y IS (Cont.)'!G66 -> 0 | G25: =-'2-T5Y IS (Cont.)'!I66 -> 0 | H25: =-'2-T5Y IS (Cont.)'!J66 -> 0 | I25: =-'2-T5Y IS (Cont.)'!K66 -> 0 | J25: =-'2-T5Y IS (Cont.)'!L66 -> 0 | K25: =-'2-T5Y IS (Cont.)'!M66 -> 0
B26: Add back Est. Owners' Perqs | C26: 0 | E26: =D26-F26 -> 0 | H26: 0 | I26: 0 | J26: 0 | K26: 0 | L26: 0 | M26: 0 | N26: 0
B27: ① "Adjusted" EBITDA $ | C27: =SUM(C11:C26) -> 1054384 | D27: =SUM(D11:D26) -> 460299 | E27: =SUM(E11:E26) -> 116076 | F27: =SUM(F11:F26) -> 344223 | G27: =SUM(G11:G26) -> 373203 | H27: =SUM(H11:H26) -> 276912 | I27: =SUM(I11:I26) -> 76021 | J27: =SUM(J11:J26) -> 156702 | ... N27: =SUM(N11:N26) -> -359569
B28: ① "Adjusted" EBITDA % | C28: =IFERROR(C27/C8,"") -> 0.11039075 | D28: =IFERROR(D27/D8,"") -> 0.096383769 | E28: =IFERROR(E27/E8,"") -> 0.049059851 | F28: =IFERROR(F27/F8,"") -> 0.14284997 | G28: =IFERROR(G27/G8,"") -> 0.041439148 | H28: =IFERROR(H27/H8,"") -> 0.06182947 | I28: =IFERROR(I27/I8,"") -> 0.016755199 | J28: =IFERROR(J27/J8,"") -> 0.016757482 | ... N28: =IFERROR(N27/N8,"") -> -0.036652562
B29: ① Pretax Income (Earnings) less Interest, Taxes, Depreciation/Amortization & "unusual" Expenses
B30: ②The internals separate bank charges from payroll charges. The Reviews do not.
B31: ③A large customer filed bankruptcy in 2024. Rare event.
B32: ④Straight-line extrapolation based on 6-mo'-FY'26 figures.

Sheet 5-Working Cap
B1: HCF's Working Capital Computation
C4: 3-mo'-FY'26 | D4: FY2025 | E4: 6-mo'-FY'25 | F4: 6-mo'-FY'24 | G4: FY2024 | H4: FY2023 | I4: FY2022 | J4: FY2021 | K4: FY2020
B5: CASH* | C5: ='3-Balance Sheet'!D9+'3-Balance Sheet'!D11 -> 543005 | D5: ='3-Balance Sheet'!E9+'3-Balance Sheet'!E11 -> 567253 | E5: ='3-Balance Sheet'!F9+'3-Balance Sheet'!F11 -> 739103 | F5: ='3-Balance Sheet'!H9+'3-Balance Sheet'!H11 -> 641003 | G5: ='3-Balance Sheet'!G9+'3-Balance Sheet'!G11 -> 586933 | H5: ='3-Balance Sheet'!I9+'3-Balance Sheet'!I11 -> 519446 | I5: ='3-Balance Sheet'!J9+'3-Balance Sheet'!J11 -> 113938 | J5: ='3-Balance Sheet'!K9+'3-Balance Sheet'!K11 -> 49473 | K5: ='3-Balance Sheet'!L9+'3-Balance Sheet'!L11 -> 175518
B7: A/R | C7: ='3-Balance Sheet'!D13 -> 1010922 | D7: ='3-Balance Sheet'!E13 -> 674696 | E7: ='3-Balance Sheet'!F13 -> 624234 | F7: ='3-Balance Sheet'!H13 -> 739879 | G7: ='3-Balance Sheet'!G13 -> 600833 | H7: ='3-Balance Sheet'!I13 -> 825739 | I7: ='3-Balance Sheet'!J13 -> 1162502 | J7: ='3-Balance Sheet'!K13 -> 1033535 | K7: ='3-Balance Sheet'!L13 -> 838596
B8: INV | C8: ='3-Balance Sheet'!D22 -> 1202624 | D8: ='3-Balance Sheet'!E22 -> 1239901 | E8: ='3-Balance Sheet'!F22 -> 1050542 | F8: ='3-Balance Sheet'!H22 -> 909413 | G8: ='3-Balance Sheet'!G22 -> 1021535 | H8: ='3-Balance Sheet'!I22 -> 1051427 | I8: ='3-Balance Sheet'!J22 -> 1733922 | J8: ='3-Balance Sheet'!K22 -> 1107863 | K8: ='3-Balance Sheet'!L22 -> 632835
B9: A/P | C9: ='3-Balance Sheet'!D58 -> 413053 | D9: ='3-Balance Sheet'!E58 -> 451708 | E9: ='3-Balance Sheet'!F58 -> 219210 | F9: ='3-Balance Sheet'!H58 -> 230561 | G9: ='3-Balance Sheet'!G58 -> 281913 | H9: ='3-Balance Sheet'!I58 -> 284395 | I9: ='3-Balance Sheet'!J58 -> 1181015 | J9: ='3-Balance Sheet'!K58 -> 642630 | K9: ='3-Balance Sheet'!L58 -> 758243
B10: Net | C10: =C7+C8-C9 -> 1800493 | D10: =D7+D8-D9 -> 1462889 | E10: =E7+E8-E9 -> 1455566 | F10: =F7+F8-F9 -> 1418731 | G10: =G7+G8-G9 -> 1340455 | H10: =H7+H8-H9 -> 1592771 | I10: =I7+I8-I9 -> 1715409 | J10: =J7+J8-J9 -> 1498768 | K10: =K7+K8-K9 -> 713188
B11: *Includes $300k in Certificates of Deposit for FY2024 and $313k for FY2025.

Sheet 5-Core NWC of HCF
B2: Financial Information | C2: Highland Computer Forms, Inc.
B3: Date: 7/15/2026 | C3: Hillsboro, Ohio "S"-Corp
C4: Fiscal Year Ends December 31st
C6: Average | D6: Internal | E6: Internal | F6: Internal | G6: Internal | H6: Review | I6: Internal | J6: Review | K6: Internal | L6: Review | M6: Review | N6: Review | O6: Review
C7: Trailing ? | D7: June-'26 | E7: May-'26 | F7: Apr-'26 | G7: Mar-'26 | H7: Dec-'25 | I7: 45838 | J7: Dec-'24 | K7: 45473 | L7: Dec-'23 | M7: Dec-'22 | N7: Dec-'21 | O7: Dec-'20
B8: Working Capital Computation
B10: CASH | D10: =SUM('3-Balance Sheet'!C9:C11) -> 739924 | E10: 0 | F10: 0 | G10: =SUM('3-Balance Sheet'!D9:D11) -> 543005 | H10: =SUM('3-Balance Sheet'!E9:E11) -> 638976 | I10: =SUM('3-Balance Sheet'!F9:F11) -> 739103 | J10: =SUM('3-Balance Sheet'!G9:G11) -> 608732 | K10: =SUM('3-Balance Sheet'!H9:H11) -> 641003 | L10: =SUM('3-Balance Sheet'!I9:I11) -> 606665 | M10: ='3-Balance Sheet'!J9+'3-Balance Sheet'!J11 -> 113938 | N10: ='3-Balance Sheet'!K9+'3-Balance Sheet'!K11 -> 49473 | O10: ='3-Balance Sheet'!L9+'3-Balance Sheet'!L11 -> 175518
B12: Current Assets
B13: Accounts Receivable - Trade | D13: =SUM('3-Balance Sheet'!C13:C15) -> 779487 | E13: 0 | F13: 0 | G13: =SUM('3-Balance Sheet'!D13:D15) -> 1010922 | H13: =SUM('3-Balance Sheet'!E13:E15) -> 688870 | I13: =SUM('3-Balance Sheet'!F13:F15) -> 624234 | J13: =SUM('3-Balance Sheet'!G13:G15) -> 608466 | K13: =SUM('3-Balance Sheet'!H13:H15) -> 739879 | L13: =SUM('3-Balance Sheet'!I13:I15) -> 917593 | M13: ='3-Balance Sheet'!J13 -> 1162502 | N13: ='3-Balance Sheet'!K13 -> 1033535 | O13: ='3-Balance Sheet'!L13 -> 838596
B14: Inventory | D14: =SUM('3-Balance Sheet'!C22:C23) -> 1098507 | E14: 0 | F14: 0 | G14: =SUM('3-Balance Sheet'!D22:D23) -> 1202624 | H14: =SUM('3-Balance Sheet'!E22:E23) -> 1239901 | I14: =SUM('3-Balance Sheet'!F22:F23) -> 1050542 | J14: =SUM('3-Balance Sheet'!G22:G23) -> 1021535 | K14: =SUM('3-Balance Sheet'!H22:H23) -> 909413 | L14: =SUM('3-Balance Sheet'!I22:I23) -> 1096561 | M14: ='3-Balance Sheet'!J22 -> 1733922 | N14: ='3-Balance Sheet'!K22 -> 1107863 | O14: ='3-Balance Sheet'!L22 -> 632835
B15: Total Current Asset Components of Working Capital | D15: =SUM(D13:D14) -> 1877994 | E15: =SUM(E13:E14) -> 0 | F15: =SUM(F13:F14) -> 0 | G15: =SUM(G13:G14) -> 2213546 | H15: =SUM(H13:H14) -> 1928771 | I15: =SUM(I13:I14) -> 1674776 | J15: =SUM(J13:J14) -> 1630001 | K15: =SUM(K13:K14) -> 1649292 | ... O15: =SUM(O13:O14) -> 1471431
B17: Current Liabilities
B18: Accounts Payable - Trade | D18: =SUM('3-Balance Sheet'!C58:C60) -> 310086 | E18: 0 | F18: 0 | G18: =SUM('3-Balance Sheet'!D58:D60) -> 413053 | H18: =SUM('3-Balance Sheet'!E58:E60) -> 451708 | I18: =SUM('3-Balance Sheet'!F58:F60) -> 219210 | J18: =SUM('3-Balance Sheet'!G58:G60) -> 281913 | K18: =SUM('3-Balance Sheet'!H58:H60) -> 230561 | L18: =SUM('3-Balance Sheet'!I58:I60) -> 284395 | M18: ='3-Balance Sheet'!J58 -> 1181015 | N18: ='3-Balance Sheet'!K58 -> 642630 | O18: ='3-Balance Sheet'!L58 -> 758243
B19: Total Current Liability Components of Working Capital | D19: =SUM(D18) -> 310086 | E19: =SUM(E18) -> 0 | F19: =SUM(F18) -> 0 | G19: =SUM(G18) -> 413053 | H19: =SUM(H18) -> 451708 | I19: =SUM(I18) -> 219210 | J19: =SUM(J18) -> 281913 | K19: =SUM(K18) -> 230561 | ... O19: =SUM(O18) -> 758243
B21: Net Working Capital (sans Cash) | D21: =D15-D19 -> 1567908 | E21: =E15-E19 -> 0 | F21: =F15-F19 -> 0 | G21: =G15-G19 -> 1800493 | H21: =H15-H19 -> 1477063 | I21: =I15-I19 -> 1455566 | J21: =J15-J19 -> 1348088 | K21: =K15-K19 -> 1418731 | ... O21: =O15-O19 -> 713188
B22: Average Ratio of "Core" NWC (sans Cash)® | D22: =IFERROR(D15/D19,"") -> 6.056365 | E22: =IFERROR(E15/E19,"") | F22: =IFERROR(F15/F19,"") | G22: =IFERROR(G15/G19,"") -> 5.3589878 | H22: =H15/H19 -> 4.2699509 | I22: =I15/I19 -> 7.6400529 | J22: =J15/J19 -> 5.7819292 | K22: =K15/K19 -> 7.1533867 | L22: =L15/L19 -> 7.0822412 | M22: =M15/M19 -> 2.4524871 | N22: =N15/N19 -> 3.3322409 | O22: =O15/O19 -> 1.9405797
C23: Trailing ? | D23: =D7 -> June-'26 | E23: =E7 -> May-'26 | F23: =F7 -> Apr-'26 | G23: =G7 -> Mar-'26 | H23: =H7 -> Dec-'25 | I23: 45838 | J23: =J7 -> Dec-'24 | K23: =K7 -> 45473 | L23: =L7 -> Dec-'23 | M23: June-'24 | N23: Mar-'24 | O23: Dec-'23
C24: Average

Sheet Mfg. Costs
B2: FY2024 | C2: Total | D2: Hillsboro #1 | E2: Hillsboro #2 | F2: Angola | G2: ALLOCATED | H2: Agg | O2: 1271667 | Q2: 601238
Q3: 475329
B4: COGS - Manufactured | Q4: 148011
Q5: =SUM(Q2:Q4) -> 1224578 | R5: =O2-Q5 -> 47089
B6: Direct Materials
A7: Materials | B7: Paper | C7: =SUM(D7:F7) -> 3635090 | D7: 1914909 | E7: -382 | F7: 1720563 | H7: =SUM(D7:F7) -> 3635090 | O7: 4651591 | P7: 4592992
A8: Materials | B8: Carbon | C8: =SUM(D8:F8) -> 6960 | D8: 5661 | E8: 0 | F8: 1299 | H8: =SUM(D8:F8) -> 6960 | O8: 4050352 | P8: 59870
A9: Materials | B9: Cartons | C9: =SUM(D9:F9) -> 180668 | D9: 95916 | F9: 84752 | H9: =SUM(D9:F9) -> 180668 | O9: =O7-O8 -> 601239 | P9: =SUM(P7:P8) -> 4652862 | Q9: =O7-P9 -> -1271
A10: Materials | B10: Ink | C10: =SUM(D10:F10) -> 94917 | D10: 76717 | E10: 1873 | F10: 16327 | H10: =SUM(D10:F10) -> 94917
A11: Materials | B11: Materials + Supplies | C11: =SUM(D11:F11) -> 206347 | D11: 138195 | E11: 4832 | F11: 63320 | H11: =SUM(D11:F11) -> 206347 | R11: 530396
A12: Materials | B12: Label Material | C12: =SUM(D12:F12) -> 121477 | E12: 0 | F12: 121477 | H12: =SUM(D12:F12) -> 121477 | O12: 4076396 | R12: 320852
A13: Materials | B13: Integrated Material | C13: =SUM(D13:F13) -> 69426 | D13: 69426 | E13: 0 | F13: 0 | H13: =SUM(D13:F13) -> 69426 | O13: 3347128 | R13: 136816
A14: Plant Overhead | B14: Plates + Comp Charges | C14: =SUM(D14:F14) -> 134079 | D14: 105961 | E14: 0 | F14: 28118 | H14: =SUM(D14:F14) -> 134079 | O14: 389727 | R14: =SUM(R11:R13) -> 988064
B15: Total Direct Materials | C15: =SUM(D15:F15) -> 4448964 | D15: =SUM(D7:D14) -> 2406785 | E15: =SUM(E7:E14) -> 6323 | F15: =SUM(F7:F14) -> 2035856 | H15: =SUM(D15:F15) -> 4448964 | O15: 172398 | R15: -34148
O16: -59870 | R16: =R14+R15 -> 953916
B17: Labor | O17: -54667 | P17: 537739 | R17: -1110653
A18: Labor | B18: Direct Labor Wages | C18: =SUM(D18:F18) -> 1171096 | D18: 723248 | E18: 139496 | F18: 308352 | H18: =SUM(D18:F18) -> 1171096 | O18: 276 | P18: -382 | R18: =SUM(R16:R17) -> -156737
A19: Labor | B19: Indirect Labor Wages | C19: =SUM(D19:F19) -> 638970 | D19: 236265 | E19: 82781 | F19: 319924 | H19: =SUM(D19:F19) -> 638970 | P19: =P17+P18 -> 537357
A20: Labor | B20: Supervisor's Salaries | C20: =SUM(D20:F20) -> -32017 | D20: 0 | E20: -32017 | F20: 0 | H20: =SUM(D20:F20) -> -32017 | O20: =SUM(O12:O18) -> 7871388
B21: Total Labor | C21: =SUM(D21:F21) -> 1778049 | D21: =SUM(D18:D20) -> 959513 | E21: =SUM(E18:E20) -> 190260 | F21: =SUM(F18:F20) -> 628276 | H21: =SUM(D21:F21) -> 1778049
O22: 7709431
B23: Factory Overhead | O23: =O22-O20 -> -161957 | Q23: 133332 | R23: 15954
A24: Plant Overhead | B24: Depreciation Equipment | C24: =SUM(D24:F24) -> 166470 | D24: 96101 | E24: 3757 | F24: 66612 | H24: =SUM(D24:F24) -> 166470 | Q24: 117147 | R24: 131716
A25: Plant Overhead | B25: Depreciation Trucks | C25: =SUM(D25:F25) -> 4385 | D25: 4385 | E25: 0 | F25: 0 | H25: =SUM(D25:F25) -> 4385 | O25: =-1-(O23/O20) -> -0.97942459 | Q25: 34059
A26: Labor | B26: Caretaking-Production | C26: =SUM(D26:F26) -> 29974 | D26: 19408 | E26: 3472 | F26: 7094 | H26: =SUM(D26:F26) -> 29974 | Q26: 15954
B27: Equipment Leasing | C27: =SUM(D27:F27) -> 0 | D27: 0 | E27: 0 | F27: 0 | H27: =SUM(D27:F27) -> 0 | Q27: 1011807
A28: Labor | B28: Insurance - Prod Health | C28: =SUM(D28:F28) -> 355893 | D28: 183496 | E28: 63575 | F28: 108822 | H28: =SUM(D28:F28) -> 355893
A29: Labor | B29: Taxes - Prod Payroll | C29: =SUM(D29:F29) -> 177233 | D29: 77804 | E29: 23956 | F29: 75473 | H29: =SUM(D29:F29) -> 177233
A30: Labor | B30: 401k Match - Prod | C30: =SUM(D30:F30) -> 44374 | D30: 15905 | E30: 11410 | F30: 17059 | H30: =SUM(D30:F30) -> 44374 | Q30: =SUM(Q23:Q29) -> 1312299
A31: Plant Overhead | B31: Insurance - General | C31: =SUM(D31:F31) -> 53729 | D31: 27996 | E31: 3167 | F31: 22566 | H31: =SUM(D31:F31) -> 53729
A32: Plant Overhead | B32: Taxes - General | C32: =SUM(D32:F32) -> 44005 | D32: 10274 | E32: 6807 | F32: 26924 | H32: =SUM(D32:F32) -> 44005 | Q32: 1405438
A33: Plant Overhead | B33: Training & Education | C33: =SUM(D33:F33) -> 315 | D33: 315 | E33: 0 | F33: 0 | H33: =SUM(D33:F33) -> 315 | Q33: =Q32-Q30 -> 93139
A34: Plant Overhead | B34: Rent | C34: =SUM(D34:F34) -> 126000 | D34: 0 | E34: 30000 | F34: 96000 | H34: =SUM(D34:F34) -> 126000
A35: Plant Overhead | B35: Repairs + Maintenance | C35: =SUM(D35:F35) -> 137971 | D35: 67316 | E35: 22352 | F35: 48303 | H35: =SUM(D35:F35) -> 137971 | Q35: =Q33/Q32 -> 0.066270444
A36: Plant Overhead | B36: Truck Expenses | C36: =SUM(D36:F36) -> 2960 | D36: 2960 | E36: 0 | F36: 0 | H36: =SUM(D36:F36) -> 2960
A37: Plant Overhead | B37: Utilities | C37: =SUM(D37:F37) -> 238879 | D37: 110041 | E37: 24643 | F37: 104195 | H37: =SUM(D37:F37) -> 238879
A38: Freight | B38: Freight in Price Expenses | C38: =SUM(D38:F38) -> 83397 | D38: 68402 | E38: 0 | F38: 14995 | H38: =SUM(D38:F38) -> 83397
B39: Total Factory Overhead | C39: =SUM(D39:F39) -> 1465585 | D39: =SUM(D24:D38) -> 684403 | E39: =SUM(E24:E38) -> 193139 | F39: =SUM(F24:F38) -> 588043 | H39: =SUM(D39:F39) -> 1465585
B41: Total Mfg Cost | C41: =SUM(D41:F41) -> 7692598 | D41: =D15+D21+D39 -> 4050701 | E41: =E15+E21+E39 -> 389722 | F41: =F15+F21+F39 -> 3252175 | G41: 172398 | H41: =SUM(D41:F41) -> 7692598
B43: PRODUCTION | C43: =SUM(D43:F43) -> 8916843 | D43: 4651591 | E43: 537739 | F43: 3727513 | H43: =SUM(D43:F43) -> 8916843
...

Sheet P&L Assistant
C4: Total | D4: Hillsboro #1 | E4: Hillsboro #2 | F4: Angola | G4: Total
B5: Sales | C5: =SUM(D5:F5) -> 9008622 | D5: 4669840 | E5: 537398 | F5: 3801384 | G5: =SUM(D5:F5) -> 9008622
B6: Freight Charged to Customer | C6: =SUM(D6:F6) -> 673988 | D6: 339450 | E6: 0 | F6: 334538 | G6: =SUM(D6:F6) -> 673988 | I6: =-F6 -> -334538
B7: Less Sales Discount | C7: =SUM(D7:F7) -> -153544 | D7: -76847 | E7: 0 | F7: -76697 | G7: =SUM(D7:F7) -> -153544
B8: Net Sales | C8: =SUM(D8:F8) -> 9529066 | D8: =SUM(D5:D7) -> 4932443 | E8: =SUM(E5:E7) -> 537398 | F8: =SUM(F5:F7) -> 4059225 | G8: =SUM(D8:F8) -> 9529066
B10: Cost of Goods Sold
B12: Beginning Inventory | C12: =SUM(D12:F12) -> 313472 | D12: ='Mfg. Costs'!D47 -> 68571 | E12: ='Mfg. Costs'!E47 -> 0 | F12: ='Mfg. Costs'!F47 -> 244901 | G12: =SUM(D12:F12) -> 313472
B13: Beginning Inventory (Correction to Review)
B15: Paper | C15: =SUM(D15:F15) -> 3635090 | D15: ='Mfg. Costs'!D7 -> 1914909 | E15: ='Mfg. Costs'!E7 -> -382 | F15: ='Mfg. Costs'!F7 -> 1720563 | G15: =SUM(D15:F15) -> 3635090 | I15: Total COGs | J15: =SUM(D44:F44) -> 7692598
B16: Carbon & Cartons | C16: =SUM(D16:F16) -> 187628 | D16: ='Mfg. Costs'!D8+'Mfg. Costs'!D9 -> 101577 | E16: ='Mfg. Costs'!E8+'Mfg. Costs'!E9 -> 0 | F16: ='Mfg. Costs'!F8+'Mfg. Costs'!F9 -> 86051 | G16: =SUM(D16:F16) -> 187628 | I16: Unallocated COGs | J16: 172398
B17: Ink | C17: =SUM(D17:F17) -> 94917 | D17: ='Mfg. Costs'!D10 -> 76717 | E17: ='Mfg. Costs'!E10 -> 1873 | F17: ='Mfg. Costs'!F10 -> 16327 | G17: =SUM(D17:F17) -> 94917 | I17: Grand Total | J17: =SUM(J15:J16) -> 7864996
B18: Materials + Supplies | C18: =SUM(D18:F18) -> 206347 | D18: ='Mfg. Costs'!D11 -> 138195 | E18: ='Mfg. Costs'!E11 -> 4832 | F18: ='Mfg. Costs'!F11 -> 63320 | G18: =SUM(D18:F18) -> 206347
B19: Label Material | C19: =SUM(D19:F19) -> 121477 | D19: ='Mfg. Costs'!D12 -> 0 | E19: ='Mfg. Costs'!E12 -> 0 | F19: ='Mfg. Costs'!F12 -> 121477 | G19: =SUM(D19:F19) -> 121477
B20: Integrated Material | C20: =SUM(D20:F20) -> 69426 | D20: ='Mfg. Costs'!D13 -> 69426 | E20: ='Mfg. Costs'!E13 -> 0 | F20: ='Mfg. Costs'!F13 -> 0 | G20: =SUM(D20:F20) -> 69426 | I20: Mfg. Cost Portion % - H1 | J20: =D44/J15 -> 0.52657126
B21: Envelopes | C21: =SUM(D21:F21) -> 31055 | D21: 31055 | E21: 0 | F21: 0 | G21: =SUM(D21:F21) -> 31055 | I21: Mfg. Cost Portion % - H2 | J21: =E44/J15 -> 0.050661948
B22: Copy Paper | C22: =SUM(D22:F22) -> 2773 | D22: 0 | E22: 0 | F22: 2773 | G22: =SUM(D22:F22) -> 2773 | I22: Mfg. Cost Portion % - A | J22: =F44/J15 -> 0.42276679
B23: Sub-Total Materials | C23: =SUM(C15:C22) -> 4348713 | D23: =SUM(D15:D22) -> 2331879 | E23: =SUM(E15:E22) -> 6323 | F23: =SUM(F15:F22) -> 2010511 | G23: =SUM(D23:F23) -> 4348713
B25: Labor | I25: Unallocated G&A | J25: 1011807
B26: ='Mfg. Costs'!B18 -> Direct Labor Wages | C26: =SUM(D26:F26) -> 1171096 | D26: ='Mfg. Costs'!D18 -> 723248 | E26: ='Mfg. Costs'!E18 -> 139496 | F26: ='Mfg. Costs'!F18 -> 308352 | G26: =SUM(D26:F26) -> 1171096 | I26: Des Moines G&A | J26: =34059+88 -> 34147 | K26: <-Include $88 in Des Moines Freight (not a plant, definitely a G&A item).
B27: ='Mfg. Costs'!B19 -> Indirect Labor Wages | C27: =SUM(D27:F27) -> 638970 | D27: ='Mfg. Costs'!D19 -> 236265 | E27: ='Mfg. Costs'!E19 -> 82781 | F27: ='Mfg. Costs'!F19 -> 319924 | G27: =SUM(D27:F27) -> 638970 | I27: Unallocated Freight | J27: 276
B28: ='Mfg. Costs'!B29 -> Taxes - Prod Payroll | C28: =SUM(D28:F28) -> 177233 | D28: ='Mfg. Costs'!D29 -> 77804 | E28: ='Mfg. Costs'!E29 -> 23956 | F28: ='Mfg. Costs'!F29 -> 75473 | G28: =SUM(D28:F28) -> 177233
B29: ='Mfg. Costs'!B20 -> Supervisor's Salaries | C29: =SUM(D29:F29) -> -32017 | D29: ='Mfg. Costs'!D20 -> 0 | E29: ='Mfg. Costs'!E20 -> -32017 | F29: ='Mfg. Costs'!F20 -> 0 | G29: =SUM(D29:F29) -> -32017
B30: ='Mfg. Costs'!B26 -> Caretaking-Production | C30: =SUM(D30:F30) -> 29974 | D30: ='Mfg. Costs'!D26 -> 19408 | E30: ='Mfg. Costs'!E26 -> 3472 | F30: ='Mfg. Costs'!F26 -> 7094 | G30: =SUM(D30:F30) -> 29974 | I30: Hillsboro #1 Net Profit(loss) | J30: 530386
B31: Benefits (Health Ins. + 401k) | C31: =SUM(D31:F31) -> 400267 | D31: ='Mfg. Costs'!D28+'Mfg. Costs'!D30 -> 199401 | E31: ='Mfg. Costs'!E28+'Mfg. Costs'!E30 -> 74985 | F31: ='Mfg. Costs'!F28+'Mfg. Costs'!F30 -> 125881 | G31: =SUM(D31:F31) -> 400267 | I31: Hillsboro #2 Net Profit(loss) | J31: 136816
B32: Sub-Total Labor | C32: =SUM(C26:C31) -> 2385523 | D32: =SUM(D26:D31) -> 1256126 | E32: =SUM(E26:E31) -> 292673 | F32: =SUM(F26:F31) -> 836724 | G32: =SUM(D32:F32) -> 2385523 | I32: Angola Net Profit(loss) | J32: 320852
I33: Des moines Net Profit(loss) | J33: -34148
B34: Plant Overhead | I34: Allocated Net Profit(loss) | J34: -1110653
B35: Rent | C35: =SUM(D35:F35) -> 126000 | D35: ='Mfg. Costs'!D34 -> 0 | E35: ='Mfg. Costs'!E34 -> 30000 | F35: ='Mfg. Costs'!F34 -> 96000 | G35: =SUM(D35:F35) -> 126000 | I35: Total | J35: =SUM(J30:J34) -> -156747
B36: Utilities | C36: =SUM(D36:F36) -> 238879 | D36: ='Mfg. Costs'!D37 -> 110041 | E36: ='Mfg. Costs'!E37 -> 24643 | F36: ='Mfg. Costs'!F37 -> 104195 | G36: =SUM(D36:F36) -> 238879
B37: Depreciation | C37: =SUM(D37:F37) -> 170855 | D37: ='Mfg. Costs'!D24+'Mfg. Costs'!D25 -> 100486 | E37: ='Mfg. Costs'!E24+'Mfg. Costs'!E25 -> 3757 | F37: ='Mfg. Costs'!F24+'Mfg. Costs'!F25 -> 66612 | G37: =SUM(D37:F37) -> 170855
B38: Repairs & Maintenance | C38: =SUM(D38:F38) -> 137971 | D38: ='Mfg. Costs'!D35 -> 67316 | E38: ='Mfg. Costs'!E35 -> 22352 | F38: ='Mfg. Costs'!F35 -> 48303 | G38: =SUM(D38:F38) -> 137971
B39: Plates & Comp Charges | C39: =SUM(D39:F39) -> 134079 | D39: ='Mfg. Costs'!D14 -> 105961 | E39: ='Mfg. Costs'!E14 -> 0 | F39: ='Mfg. Costs'!F14 -> 28118 | G39: =SUM(D39:F39) -> 134079 | I39: Unallocated Misc. Income | J39: 27919
B40: Misc. Plant Overhead | C40: =SUM(D40:F40) -> 101009 | D40: ='Mfg. Costs'!D31+'Mfg. Costs'!D32+'Mfg. Costs'!D33+'Mfg. Costs'!D36 -> 41545 | E40: ='Mfg. Costs'!E31+'Mfg. Costs'!E32+'Mfg. Costs'!E33+'Mfg. Costs'!E36 -> 9974 | F40: ='Mfg. Costs'!F31+'Mfg. Costs'!F32+'Mfg. Costs'!F33+'Mfg. Costs'!F36 -> 49490 | G40: =SUM(D40:F40) -> 101009 | I40: Unallocated Interst Income | J40: 7
B41: Sub-Total Plant Overhead | C41: =SUM(C35:C40) -> 908793 | D41: =SUM(D35:D40) -> 425349 | E41: =SUM(E35:E40) -> 90726 | F41: =SUM(F35:F40) -> 392718 | G41: =SUM(D41:F41) -> 908793 | I41: Unallocated Interest Expense | J41: -19149
I42: Unallocated Loss of Sale of Property | J42: 2666
B43: Less Ending Inventory | C43: =SUM(D43:F43) -> -226313 | D43: =-'Mfg. Costs'!D48 -> -73583 | E43: =-'Mfg. Costs'!E48 -> 0 | F43: =-'Mfg. Costs'!F48 -> -152730 | G43: =SUM(D43:F43) -> -226313 | I43: Unallocated Purchase Discounts | J43: 62385
B44: Total COGs(per Internals) | C44: =SUM(D44:F44) -> 7692598 | D44: =SUM(D15:D20,D26:D31,D35:D40)+D46 -> 4050701 | E44: =SUM(E15:E20,E26:E31,E35:E40)+E46 -> 389722 | F44: =SUM(F15:F20,F26:F31,F35:F40)+F46 -> 3252175 | G44: =SUM(D44:F44) -> 7692598
B46: Freight In Price Expenses | C46: =SUM(D46:F46) -> 83397 | D46: ='Mfg. Costs'!D38 -> 68402 | E46: ='Mfg. Costs'!E38 -> 0 | F46: ='Mfg. Costs'!F38 -> 14995 | G46: =SUM(D46:F46) -> 83397 | I46: Beginning Inventories (review) | J46: 1051427
B47: Freight Expense | C47: =SUM(D47:F47) -> 540101 | D47: 268916 | E47: 0 | F47: 271185 | G47: =SUM(D47:F47) -> 540101 | I47: Ending Inventories (review) | J47: -1021535
